Workbook

Sheet Summary
A1: CONSOLIDATED PORTFOLIO SUMMARY – ALL MANAGED ACCOUNTS
A2: Built 23.10.2026 from 6 statements. All market values at NSE/BSE close of 22.10.2026 (Prices sheet); statement-reported values kept alongside for reconciliation.
A5: Portfolio | B5: Broker | C5: Holdings as of | D5: Statement price basis | E5: # Holdings | F5: Invested (₹) | G5: Market Value (₹) | H5: Unrealised P&L (₹) | I5: P&L % | J5: Share of Combined MV | K5: Stmt Invested (₹) | L5: Stmt Market Value (₹) | M5: Repricing Impact (₹)
A6: Gautam | B6: HDFC Securities | C6: 23.10.2026 | D6: HDFC statement prices 23.10.2026 | E6: =COUNTIFS(Gautam!$D$7:$D$300,">0",Gautam!$B$7:$B$300,"<>Cash*") -> 31 | F6: =Gautam!E6 -> 5501448 | G6: =Gautam!H6 -> 5225157.3 | H6: =G6-F6 -> -276290.7 | I6: =IF(F6>0,H6/F6,"") -> -0.050221451 | J6: =IF($G$12=0,"",G6/$G$12) -> 0.13848002 | K6: 5501448.5 | L6: 5224564 | M6: =G6-L6 -> 593.3
A7: Manish Shilpa | B7: Axis Direct + HDFC Securities | C7: 23.10.2026 (live, ~11:23 IST) | D7: Live LTP 23.10.2026 ~11:23 IST (equity); MF NAV per Axis statement 23.10.2026 (three demats + MF merged) | E7: =COUNTIFS('Manish Shilpa'!$D$7:$D$300,">0",'Manish Shilpa'!$B$7:$B$300,"<>Cash*") -> 47 | F7: ='Manish Shilpa'!E6 -> 9857778 | G7: ='Manish Shilpa'!H6 -> 11825895 | H7: =G7-F7 -> 1968116.9 | I7: =IF(F7>0,H7/F7,"") -> 0.19965117 | J7: =IF($G$12=0,"",G7/$G$12) -> 0.31341643 | K7: 9857779 | L7: 11636410 | M7: =G7-L7 -> 189484.74
A8: Saloni Mehra | B8: Angel One | C8: 20.10.2026 + trades of 21–22.10.2026 | D8: 20.10.2026 statement prices (only for rows with no trades since) | E8: =COUNTIFS('Saloni Mehra'!$D$7:$D$300,">0",'Saloni Mehra'!$B$7:$B$300,"<>Cash*") -> 25 | F8: ='Saloni Mehra'!E6 -> 11014028 | G8: ='Saloni Mehra'!H6 -> 11167526 | H8: =G8-F8 -> 153497.65 | I8: =IF(F8>0,H8/F8,"") -> 0.013936559 | J8: =IF($G$12=0,"",G8/$G$12) -> 0.29596797 | K8: 11014028 | L8: 3325492 | M8: =G8-L8 -> 7842033.7
A9: Vidushi Malhotra | B9: Zerodha | C9: 04.10.2026 (+ trades of 05.10.2026) | D9: LTP 05.10.2026 | E9: =COUNTIFS('Vidushi Malhotra'!$D$7:$D$300,">0",'Vidushi Malhotra'!$B$7:$B$300,"<>Cash*") -> 12 | F9: ='Vidushi Malhotra'!E6 -> 201361 | G9: ='Vidushi Malhotra'!H6 -> 226299.36 | H9: =G9-F9 -> 24938.363 | I9: =IF(F9>0,H9/F9,"") -> 0.12384902 | J9: =IF($G$12=0,"",G9/$G$12) -> 0.0059975114 | K9: 201361 | L9: 230319 | M9: =G9-L9 -> -4019.6371
A10: Dr Umesh Choudhry | B10: ICICI Direct | C10: 04.10.2026 + trades of 09.10.2026 | D10: NSE live 09.10.2026 ~09:45 IST | E10: =COUNTIFS('Dr Umesh Choudhry'!$D$7:$D$300,">0",'Dr Umesh Choudhry'!$B$7:$B$300,"<>Cash*") -> 20 | F10: ='Dr Umesh Choudhry'!E6 -> 5222229 | G10: ='Dr Umesh Choudhry'!H6 -> 5421322.8 | H10: =G10-F10 -> 199093.76 | I10: =IF(F10>0,H10/F10,"") -> 0.038124288 | J10: =IF($G$12=0,"",G10/$G$12) -> 0.14367891 | K10: 5222229 | L10: 5467267.2 | M10: =G10-L10 -> -45944.47
A11: DA | B11: HDFC Securities + Kotak Securities | C11: Post 12.09.2026 trades (file dated 04.10.2026) | D11: As on statement (date not printed) | E11: =COUNTIFS(DA!$D$7:$D$300,">0",DA!$B$7:$B$300,"<>Cash*") -> 53 | F11: =DA!E6 -> 4364996 | G11: =DA!H6 -> 3866010.7 | H11: =G11-F11 -> -498985.26 | I11: =IF(F11>0,H11/F11,"") -> -0.11431517 | J11: =IF($G$12=0,"",G11/$G$12) -> 0.10245916 | K11: 4364995 | L11: 4141021 | M11: =G11-L11 -> -275010.26
A12: COMBINED (ALL 6) | B12: HDFC Securities + Axis Direct + HDFC Securities + Angel One + Zerodha + ICICI Direct + HDFC Securities + Kotak Securities | E12: ='Side by Side'!E6 -> 88 | F12: =SUM(F6:F11) -> 36161840 | G12: =SUM(G6:G11) -> 37732211 | H12: =SUM(H6:H11) -> 1570370.7 | I12: =IF(F12>0,H12/F12,"") -> 0.043426184 | J12: =SUM(J6:J11) -> 1 | K12: =SUM(K6:K11) -> 36161841 | L12: =SUM(L6:L11) -> 30025073 | M12: =SUM(M6:M11) -> 7707137.3
L13: Statement totals as printed on each statement (inputs).
A15: TOP 10 COMBINED EXPOSURES – weight in each portfolio
A16: Rank | B16: Security | C16: Combined MV (₹) | D16: Combined Weight | E16: Gautam | F16: Manish Shilpa | G16: Saloni Mehra | H16: Vidushi Malhotra | I16: Dr Umesh Choudhry | J16: DA | K16: Held in (# a/cs)
A17: 1 | B17: =INDEX('Side by Side'!$B$7:$B$95,MATCH(C17,'Side by Side'!$I$7:$I$95,0)) -> Bajaj Finance Ltd | C17: =LARGE('Side by Side'!$I$7:$I$95,A17) -> 13148890 | D17: =INDEX('Side by Side'!$L$7:$L$95,MATCH(C17,'Side by Side'!$I$7:$I$95,0)) -> 0.34847918 | E17: =INDEX('Side by Side'!$S$7:$S$95,MATCH(C17,'Side by Side'!$I$7:$I$95,0)) -> 0.34275181 | F17: =INDEX('Side by Side'!$Z$7:$Z$95,MATCH(C17,'Side by Side'!$I$7:$I$95,0)) -> 0.31029191 | G17: =INDEX('Side by Side'!$AG$7:$AG$95,MATCH(C17,'Side by Side'!$I$7:$I$95,0)) -> 0.39759186 | H17: =INDEX('Side by Side'!$AN$7:$AN$95,MATCH(C17,'Side by Side'!$I$7:$I$95,0)) -> 0.50373142 | I17: =INDEX('Side by Side'!$AU$7:$AU$95,MATCH(C17,'Side by Side'!$I$7:$I$95,0)) -> 0.41914959 | J17: =INDEX('Side by Side'!$BB$7:$BB$95,MATCH(C17,'Side by Side'!$I$7:$I$95,0)) -> 0.22297442 | K17: =INDEX('Side by Side'!$E$7:$E$95,MATCH(C17,'Side by Side'!$I$7:$I$95,0)) -> 6
A18: 2 | B18: =INDEX('Side by Side'!$B$7:$B$95,MATCH(C18,'Side by Side'!$I$7:$I$95,0)) -> Titan Company Ltd | C18: =LARGE('Side by Side'!$I$7:$I$95,A18) -> 3027600 | D18: =INDEX('Side by Side'!$L$7:$L$95,MATCH(C18,'Side by Side'!$I$7:$I$95,0)) -> 0.080239136 | E18: =INDEX('Side by Side'!$S$7:$S$95,MATCH(C18,'Side by Side'!$I$7:$I$95,0)) -> 0.039128009 | F18: =INDEX('Side by Side'!$Z$7:$Z$95,MATCH(C18,'Side by Side'!$I$7:$I$95,0)) -> 0.060693081 | G18: =INDEX('Side by Side'!$AG$7:$AG$95,MATCH(C18,'Side by Side'!$I$7:$I$95,0)) -> 0.095043435 | H18: =INDEX('Side by Side'!$AN$7:$AN$95,MATCH(C18,'Side by Side'!$I$7:$I$95,0)) -> 0.17300093 | I18: =INDEX('Side by Side'!$AU$7:$AU$95,MATCH(C18,'Side by Side'!$I$7:$I$95,0)) -> 0.1380106 | J18: =INDEX('Side by Side'!$BB$7:$BB$95,MATCH(C18,'Side by Side'!$I$7:$I$95,0)) -> 0.066386262 | K18: =INDEX('Side by Side'!$E$7:$E$95,MATCH(C18,'Side by Side'!$I$7:$I$95,0)) -> 6
A19: 3 | B19: =INDEX('Side by Side'!$B$7:$B$95,MATCH(C19,'Side by Side'!$I$7:$I$95,0)) -> Nippon India ETF Nifty 50 BeES | C19: =LARGE('Side by Side'!$I$7:$I$95,A19) -> 2864949.7 | D19: =INDEX('Side by Side'!$L$7:$L$95,MATCH(C19,'Side by Side'!$I$7:$I$95,0)) -> 0.075928488 | E19: =INDEX('Side by Side'!$S$7:$S$95,MATCH(C19,'Side by Side'!$I$7:$I$95,0)) -> 0 | F19: =INDEX('Side by Side'!$Z$7:$Z$95,MATCH(C19,'Side by Side'!$I$7:$I$95,0)) -> 0.242239 | G19: =INDEX('Side by Side'!$AG$7:$AG$95,MATCH(C19,'Side by Side'!$I$7:$I$95,0)) -> 0 | H19: =INDEX('Side by Side'!$AN$7:$AN$95,MATCH(C19,'Side by Side'!$I$7:$I$95,0)) -> 0.0011343069 | I19: =INDEX('Side by Side'!$AU$7:$AU$95,MATCH(C19,'Side by Side'!$I$7:$I$95,0)) -> 0 | J19: =INDEX('Side by Side'!$BB$7:$BB$95,MATCH(C19,'Side by Side'!$I$7:$I$95,0)) -> 0 | K19: =INDEX('Side by Side'!$E$7:$E$95,MATCH(C19,'Side by Side'!$I$7:$I$95,0)) -> 2
A20: 4 | B20: =INDEX('Side by Side'!$B$7:$B$95,MATCH(C20,'Side by Side'!$I$7:$I$95,0)) -> HDFC Bank Ltd | C20: =LARGE('Side by Side'!$I$7:$I$95,A20) -> 2484699 | D20: =INDEX('Side by Side'!$L$7:$L$95,MATCH(C20,'Side by Side'!$I$7:$I$95,0)) -> 0.065850873 | E20: =INDEX('Side by Side'!$S$7:$S$95,MATCH(C20,'Side by Side'!$I$7:$I$95,0)) -> 0.059374356 | F20: =INDEX('Side by Side'!$Z$7:$Z$95,MATCH(C20,'Side by Side'!$I$7:$I$95,0)) -> 0.059451962 | G20: =INDEX('Side by Side'!$AG$7:$AG$95,MATCH(C20,'Side by Side'!$I$7:$I$95,0)) -> 0.067680207 | H20: =INDEX('Side by Side'!$AN$7:$AN$95,MATCH(C20,'Side by Side'!$I$7:$I$95,0)) -> 0.064406058 | I20: =INDEX('Side by Side'!$AU$7:$AU$95,MATCH(C20,'Side by Side'!$I$7:$I$95,0)) -> 0.086158982 | J20: =INDEX('Side by Side'!$BB$7:$BB$95,MATCH(C20,'Side by Side'!$I$7:$I$95,0)) -> 0.06050031 | K20: =INDEX('Side by Side'!$E$7:$E$95,MATCH(C20,'Side by Side'!$I$7:$I$95,0)) -> 6
A21: 5 | B21: =INDEX('Side by Side'!$B$7:$B$95,MATCH(C21,'Side by Side'!$I$7:$I$95,0)) -> Poonawalla Fincorp Ltd | C21: =LARGE('Side by Side'!$I$7:$I$95,A21) -> 2331770.4 | D21: =INDEX('Side by Side'!$L$7:$L$95,MATCH(C21,'Side by Side'!$I$7:$I$95,0)) -> 0.061797874 | E21: =INDEX('Side by Side'!$S$7:$S$95,MATCH(C21,'Side by Side'!$I$7:$I$95,0)) -> 0.093687782 | F21: =INDEX('Side by Side'!$Z$7:$Z$95,MATCH(C21,'Side by Side'!$I$7:$I$95,0)) -> 0.050975872 | G21: =INDEX('Side by Side'!$AG$7:$AG$95,MATCH(C21,'Side by Side'!$I$7:$I$95,0)) -> 0.049063165 | H21: =INDEX('Side by Side'!$AN$7:$AN$95,MATCH(C21,'Side by Side'!$I$7:$I$95,0)) -> 0.072616643 | I21: =INDEX('Side by Side'!$AU$7:$AU$95,MATCH(C21,'Side by Side'!$I$7:$I$95,0)) -> 0.061341865 | J21: =INDEX('Side by Side'!$BB$7:$BB$95,MATCH(C21,'Side by Side'!$I$7:$I$95,0)) -> 0.088592718 | K21: =INDEX('Side by Side'!$E$7:$E$95,MATCH(C21,'Side by Side'!$I$7:$I$95,0)) -> 6
A22: 6 | B22: =INDEX('Side by Side'!$B$7:$B$95,MATCH(C22,'Side by Side'!$I$7:$I$95,0)) -> AFCOM Holdings Ltd | C22: =LARGE('Side by Side'!$I$7:$I$95,A22) -> 1645740 | D22: =INDEX('Side by Side'!$L$7:$L$95,MATCH(C22,'Side by Side'!$I$7:$I$95,0)) -> 0.043616315 | E22: =INDEX('Side by Side'!$S$7:$S$95,MATCH(C22,'Side by Side'!$I$7:$I$95,0)) -> 0.031496468 | F22: =INDEX('Side by Side'!$Z$7:$Z$95,MATCH(C22,'Side by Side'!$I$7:$I$95,0)) -> 0.041749229 | G22: =INDEX('Side by Side'!$AG$7:$AG$95,MATCH(C22,'Side by Side'!$I$7:$I$95,0)) -> 0.04421051 | H22: =INDEX('Side by Side'!$AN$7:$AN$95,MATCH(C22,'Side by Side'!$I$7:$I$95,0)) -> 0 | I22: =INDEX('Side by Side'!$AU$7:$AU$95,MATCH(C22,'Side by Side'!$I$7:$I$95,0)) -> 0.060713596 | J22: =INDEX('Side by Side'!$BB$7:$BB$95,MATCH(C22,'Side by Side'!$I$7:$I$95,0)) -> 0.042569463 | K22: =INDEX('Side by Side'!$E$7:$E$95,MATCH(C22,'Side by Side'!$I$7:$I$95,0)) -> 5
A23: 7 | B23: =INDEX('Side by Side'!$B$7:$B$95,MATCH(C23,'Side by Side'!$I$7:$I$95,0)) -> Tata Consultancy Services Ltd | C23: =LARGE('Side by Side'!$I$7:$I$95,A23) -> 1173229.2 | D23: =INDEX('Side by Side'!$L$7:$L$95,MATCH(C23,'Side by Side'!$I$7:$I$95,0)) -> 0.031093572 | E23: =INDEX('Side by Side'!$S$7:$S$95,MATCH(C23,'Side by Side'!$I$7:$I$95,0)) -> 0.044139303 | F23: =INDEX('Side by Side'!$Z$7:$Z$95,MATCH(C23,'Side by Side'!$I$7:$I$95,0)) -> 0.0061475348 | G23: =INDEX('Side by Side'!$AG$7:$AG$95,MATCH(C23,'Side by Side'!$I$7:$I$95,0)) -> 0.068466778 | H23: =INDEX('Side by Side'!$AN$7:$AN$95,MATCH(C23,'Side by Side'!$I$7:$I$95,0)) -> 0 | I23: =INDEX('Side by Side'!$AU$7:$AU$95,MATCH(C23,'Side by Side'!$I$7:$I$95,0)) -> 0.01341003 | J23: =INDEX('Side by Side'!$BB$7:$BB$95,MATCH(C23,'Side by Side'!$I$7:$I$95,0)) -> 0.0084298007 | K23: =INDEX('Side by Side'!$E$7:$E$95,MATCH(C23,'Side by Side'!$I$7:$I$95,0)) -> 5
A24: 8 | B24: =INDEX('Side by Side'!$B$7:$B$95,MATCH(C24,'Side by Side'!$I$7:$I$95,0)) -> LTM Ltd (formerly LTIMindtree) | C24: =LARGE('Side by Side'!$I$7:$I$95,A24) -> 1081322 | D24: =INDEX('Side by Side'!$L$7:$L$95,MATCH(C24,'Side by Side'!$I$7:$I$95,0)) -> 0.028657796 | E24: =INDEX('Side by Side'!$S$7:$S$95,MATCH(C24,'Side by Side'!$I$7:$I$95,0)) -> 0.049077948 | F24: =INDEX('Side by Side'!$Z$7:$Z$95,MATCH(C24,'Side by Side'!$I$7:$I$95,0)) -> 0.023853079 | G24: =INDEX('Side by Side'!$AG$7:$AG$95,MATCH(C24,'Side by Side'!$I$7:$I$95,0)) -> 0.031765497 | H24: =INDEX('Side by Side'!$AN$7:$AN$95,MATCH(C24,'Side by Side'!$I$7:$I$95,0)) -> 0.037772974 | I24: =INDEX('Side by Side'!$AU$7:$AU$95,MATCH(C24,'Side by Side'!$I$7:$I$95,0)) -> 0.029169634 | J24: =INDEX('Side by Side'!$BB$7:$BB$95,MATCH(C24,'Side by Side'!$I$7:$I$95,0)) -> 0.0055276618 | K24: =INDEX('Side by Side'!$E$7:$E$95,MATCH(C24,'Side by Side'!$I$7:$I$95,0)) -> 6
A25: 9 | B25: =INDEX('Side by Side'!$B$7:$B$95,MATCH(C25,'Side by Side'!$I$7:$I$95,0)) -> Bajaj Housing Finance Ltd | C25: =LARGE('Side by Side'!$I$7:$I$95,A25) -> 1075378.5 | D25: =INDEX('Side by Side'!$L$7:$L$95,MATCH(C25,'Side by Side'!$I$7:$I$95,0)) -> 0.028500277 | E25: =INDEX('Side by Side'!$S$7:$S$95,MATCH(C25,'Side by Side'!$I$7:$I$95,0)) -> 0.024809205 | F25: =INDEX('Side by Side'!$Z$7:$Z$95,MATCH(C25,'Side by Side'!$I$7:$I$95,0)) -> 0.025773715 | G25: =INDEX('Side by Side'!$AG$7:$AG$95,MATCH(C25,'Side by Side'!$I$7:$I$95,0)) -> 0.028004162 | H25: =INDEX('Side by Side'!$AN$7:$AN$95,MATCH(C25,'Side by Side'!$I$7:$I$95,0)) -> 0.043320582 | I25: =INDEX('Side by Side'!$AU$7:$AU$95,MATCH(C25,'Side by Side'!$I$7:$I$95,0)) -> 0.032848433 | J25: =INDEX('Side by Side'!$BB$7:$BB$95,MATCH(C25,'Side by Side'!$I$7:$I$95,0)) -> 0.03629753 | K25: =INDEX('Side by Side'!$E$7:$E$95,MATCH(C25,'Side by Side'!$I$7:$I$95,0)) -> 6
A26: 10 | B26: =INDEX('Side by Side'!$B$7:$B$95,MATCH(C26,'Side by Side'!$I$7:$I$95,0)) -> Connplex Cinemas Ltd | C26: =LARGE('Side by Side'!$I$7:$I$95,A26) -> 937000 | D26: =INDEX('Side by Side'!$L$7:$L$95,MATCH(C26,'Side by Side'!$I$7:$I$95,0)) -> 0.024832894 | E26: =INDEX('Side by Side'!$S$7:$S$95,MATCH(C26,'Side by Side'!$I$7:$I$95,0)) -> 0.035864949 | F26: =INDEX('Side by Side'!$Z$7:$Z$95,MATCH(C26,'Side by Side'!$I$7:$I$95,0)) -> 0.015846581 | G26: =INDEX('Side by Side'!$AG$7:$AG$95,MATCH(C26,'Side by Side'!$I$7:$I$95,0)) -> 0.016780799 | H26: =INDEX('Side by Side'!$AN$7:$AN$95,MATCH(C26,'Side by Side'!$I$7:$I$95,0)) -> 0 | I26: =INDEX('Side by Side'!$AU$7:$AU$95,MATCH(C26,'Side by Side'!$I$7:$I$95,0)) -> 0.03456721 | J26: =INDEX('Side by Side'!$BB$7:$BB$95,MATCH(C26,'Side by Side'!$I$7:$I$95,0)) -> 0.04847374 | K26: =INDEX('Side by Side'!$E$7:$E$95,MATCH(C26,'Side by Side'!$I$7:$I$95,0)) -> 5
A29: NOTES & FLAGS
A30: • Pricing: every holding is valued at the NSE/BSE close of 22.10.2026 (Screener.in daily price series), one price per security across all accounts. 'Repricing Impact' = workbook value minus each statement's own market value.
A31: ="• Securities on an exchange close: "&COUNTIF(Prices!$K$6:$K$300,"Close*")&" | on a statement price: "&COUNTIF(Prices!$K$6:$K$300,"No exchange*")&" | held in all 6 accounts: "&COUNTIF('Side by Side'!$E$7:$E$95,6) -> • Securities on an exchange close: 79 | on a statement price: 9 | held in all 6 accounts: 9
A32: • No exchange close for the 4 ETFs (Nifty 50 BeES, Gold BeES, Liquid BeES, HDFC Gold ETF), the Utkarsh SFB rights entitlement, NEPC Agro and PSL Ltd – these stay at statement price (Liquid BeES holds near ₹1,000).
A33: • Names aligned across statements: LTM Ltd = LTIMindtree (DA); Connplex Cinemas = Connplex Smart Theatres (DA); AFCOM = Afcom Holdings.
A34: • Trades blended into holdings and listed on each tab: Vidushi 05.10.2026 (3 buys, ₹9,889); Dr Umesh 09.10.2026 (13 buys, ₹5.01 L, incl. new Eicher Motors and Rategain).
A35: • Dr Umesh holds ₹36,000 uninvested cash at ICICI Direct – row 'Cash – ICICI Direct' at ₹1 per unit, counted in totals but not as a holding.
A36: • Statement invested/market totals reconcile to transcribed rows within ₹2 (rupee rounding on the statements).
A37: • Gautam: NEPC Agro Foods (144 sh) and PSL Ltd (1,000 sh) still have no cost or price on the statement – carried at nil.
A38: • Manish Shilpa: Axis and HDFC CSVs carry short names (e.g. 'Nip. India Nifty', 'C D S L', 'Waaree Renewab.'); aligned to canonical names. 'Nippon ETF Infra' is carried as Nippon India ETF Infra BeES. ETFs have no exchange close and stay on the statement price.
A39: • Gautam refreshed from HDFC statement of 23.10.2026 (31 lines; invested ₹55,01,448 reconciles to ₹55,01,448.50). Changes vs the 05.10 statement are derived: 16 buys and 1 exit (International Gemmological Institute, 80 sh, valued at the 05.10 statement price).
A40: • Vidushi, Dr Umesh and DA have no new statements since 09.10 and are only repriced to the 22.10.2026 close.
A41: • Manish Shilpa is new (23.10.2026): Axis Direct (Shilpa), Axis Direct (Manish), HDFC Securities (Manish) and Manish's Axis mutual fund (UTI Nifty 50 Index Fund – 2 folios, ₹1,99,990 invested) merged into one account. A stock held in more than one demat is one row; the row note lists the split. Statement totals: invested ₹98,57,779, market value ₹1,16,36,410 (equity at live ~11:23 IST prices, MF at statement NAV).
A42: • Saloni Mehra is new (Angel One): 26-holding statement of 20.10.2026 (invested ₹1,10,23,244; market value ₹1,13,95,012) rolled forward with the 15 trades of 21–22.10.2026. Buys add cost including all charges; Kotak Mahindra Bank (1,580 sh, realised ≈ ₹62,288) and LIC Housing Finance (700 sh, realised ≈ ₹-29,271) were sold out; Trent is a new position. Statement invested is now the row sum (no printed total after trades). Rows touched by trades have no statement value, so the account's 'Stmt Market Value' covers untraded rows only.

Sheet Side by Side
A1: SIDE-BY-SIDE HOLDINGS – COMBINED AND BY PORTFOLIO
A2: All values at the common Ref Price (Prices sheet). Sorted by combined market value at build; '-' = not held. Amber price = only a stale statement price available.
F4: COMBINED (ALL 6) | M4: GAUTAM – HDFC Securities | T4: MANISH SHILPA – Axis Direct + HDFC Securities | AA4: SALONI MEHRA – Angel One | AH4: VIDUSHI MALHOTRA – Zerodha | AO4: DR UMESH CHOUDHRY – ICICI Direct | AV4: DA – HDFC Securities + Kotak Securities
A5: # | B5: Security | C5: Ref Price (₹) | D5: Price Basis | E5: Held in (# a/cs) | F5: Qty | G5: Wtd Avg Cost (₹) | H5: Invested (₹) | I5: Mkt Value (₹) | J5: P&L (₹) | K5: P&L % | L5: Weight % | M5: Qty | N5: Wtd Avg Cost (₹) | O5: Invested (₹) | P5: Mkt Value (₹) | Q5: P&L (₹) | R5: P&L % | S5: Weight % | T5: Qty | U5: Wtd Avg Cost (₹) | V5: Invested (₹) | W5: Mkt Value (₹) | X5: P&L (₹) | Y5: P&L % | Z5: Weight % | AA5: Qty | AB5: Wtd Avg Cost (₹) | AC5: Invested (₹) | AD5: Mkt Value (₹) | AE5: P&L (₹) | AF5: P&L % | AG5: Weight % | AH5: Qty | AI5: Wtd Avg Cost (₹) | AJ5: Invested (₹) | AK5: Mkt Value (₹) | AL5: P&L (₹) | AM5: P&L % | AN5: Weight % | AO5: Qty | AP5: Wtd Avg Cost (₹) | AQ5: Invested (₹) | AR5: Mkt Value (₹) | AS5: P&L (₹) | AT5: P&L % | AU5: Weight % | AV5: Qty | AW5: Wtd Avg Cost (₹) | AX5: Invested (₹) | AY5: Mkt Value (₹) | AZ5: P&L (₹) | BA5: P&L % | BB5: Weight %
B6: TOTAL | E6: =COUNTIFS(E7:E95,">0",B7:B95,"<>Cash*") -> 88 | F6: =COUNTIFS(F7:F95,">0",$B7:$B95,"<>Cash*") -> 88 | H6: =SUM(H7:H95) -> 36161840 | I6: =SUM(I7:I95) -> 37732211 | J6: =I6-H6 -> 1570370.7 | K6: =IF(H6>0,J6/H6,"") -> 0.043426184 | L6: =SUM(L7:L95) -> 1 | M6: =COUNTIFS(M7:M95,">0",$B7:$B95,"<>Cash*") -> 31 | O6: =SUM(O7:O95) -> 5501448 | P6: =SUM(P7:P95) -> 5225157.3 | Q6: =P6-O6 -> -276290.7 | R6: =IF(O6>0,Q6/O6,"") -> -0.050221451 | S6: =SUM(S7:S95) -> 1 | T6: =COUNTIFS(T7:T95,">0",$B7:$B95,"<>Cash*") -> 47 | V6: =SUM(V7:V95) -> 9857778 | W6: =SUM(W7:W95) -> 11825895 | X6: =W6-V6 -> 1968116.9 | Y6: =IF(V6>0,X6/V6,"") -> 0.19965117 | Z6: =SUM(Z7:Z95) -> 1 | AA6: =COUNTIFS(AA7:AA95,">0",$B7:$B95,"<>Cash*") -> 25 | AC6: =SUM(AC7:AC95) -> 11014028 | AD6: =SUM(AD7:AD95) -> 11167526 | AE6: =AD6-AC6 -> 153497.65 | AF6: =IF(AC6>0,AE6/AC6,"") -> 0.013936559 | AG6: =SUM(AG7:AG95) -> 1 | AH6: =COUNTIFS(AH7:AH95,">0",$B7:$B95,"<>Cash*") -> 12 | AJ6: =SUM(AJ7:AJ95) -> 201361 | AK6: =SUM(AK7:AK95) -> 226299.36 | AL6: =AK6-AJ6 -> 24938.363 | AM6: =IF(AJ6>0,AL6/AJ6,"") -> 0.12384902 | AN6: =SUM(AN7:AN95) -> 1 | AO6: =COUNTIFS(AO7:AO95,">0",$B7:$B95,"<>Cash*") -> 20 | AQ6: =SUM(AQ7:AQ95) -> 5222229 | AR6: =SUM(AR7:AR95) -> 5421322.8 | AS6: =AR6-AQ6 -> 199093.76 | AT6: =IF(AQ6>0,AS6/AQ6,"") -> 0.038124288 | AU6: =SUM(AU7:AU95) -> 1 | AV6: =COUNTIFS(AV7:AV95,">0",$B7:$B95,"<>Cash*") -> 53 | AX6: =SUM(AX7:AX95) -> 4364996 | AY6: =SUM(AY7:AY95) -> 3866010.7 | AZ6: =AY6-AX6 -> -498985.26 | BA6: =IF(AX6>0,AZ6/AX6,"") -> -0.11431517 | BB6: =SUM(BB7:BB95) -> 1
A7: 1 | B7: Bajaj Finance Ltd | C7: =IFERROR(INDEX(Prices!$C$6:$C$300,MATCH($B7,Prices!$A$6:$A$300,0)),"") -> 942.1 | D7: =IFERROR(INDEX(Prices!$D$6:$D$300,MATCH($B7,Prices!$A$6:$A$300,0)),"") -> Close 22.10.2026 (Screener.in) | E7: =(M7>0)+(T7>0)+(AA7>0)+(AH7>0)+(AO7>0)+(AV7>0) -> 6 | F7: =M7+T7+AA7+AH7+AO7+AV7 -> 13957 | G7: =IF(AND(F7>0,H7>0),H7/F7,"") -> 877.77295 | H7: =O7+V7+AC7+AJ7+AQ7+AX7 -> 12251077 | I7: =P7+W7+AD7+AK7+AR7+AY7 -> 13148890 | J7: =I7-H7 -> 897812.7 | K7: =IF(H7>0,J7/H7,"") -> 0.07328439 | L7: =IF(I$6=0,"",I7/I$6) -> 0.34847918 | M7: =SUMIFS(Gautam!$D$7:$D$300,Gautam!$B$7:$B$300,$B7) -> 1901 | N7: =IF(AND(M7>0,O7>0),O7/M7,"") -> 1005.9332 | O7: =SUMIFS(Gautam!$E$7:$E$300,Gautam!$B$7:$B$300,$B7) -> 1912279 | P7: =SUMIFS(Gautam!$H$7:$H$300,Gautam!$B$7:$B$300,$B7) -> 1790932.1 | Q7: =P7-O7 -> -121346.9 | R7: =IF(O7>0,Q7/O7,"") -> -0.063456692 | S7: =IF(P$6=0,"",P7/P$6) -> 0.34275181 | T7: =SUMIFS('Manish Shilpa'!$D$7:$D$300,'Manish Shilpa'!$B$7:$B$300,$B7) -> 3895 | U7: =IF(AND(T7>0,V7>0),V7/T7,"") -> 747.72503 | V7: =SUMIFS('Manish Shilpa'!$E$7:$E$300,'Manish Shilpa'!$B$7:$B$300,$B7) -> 2912389 | W7: =SUMIFS('Manish Shilpa'!$H$7:$H$300,'Manish Shilpa'!$B$7:$B$300,$B7) -> 3669479.5 | X7: =W7-V7 -> 757090.5 | Y7: =IF(V7>0,X7/V7,"") -> 0.25995514 | Z7: =IF(W$6=0,"",W7/W$6) -> 0.31029191 | AA7: =SUMIFS('Saloni Mehra'!$D$7:$D$300,'Saloni Mehra'!$B$7:$B$300,$B7) -> 4713 | AB7: =IF(AND(AA7>0,AC7>0),AC7/AA7,"") -> 941.87948 | AC7: =SUMIFS('Saloni Mehra'!$E$7:$E$300,'Saloni Mehra'!$B$7:$B$300,$B7) -> 4439078 | AD7: =SUMIFS('Saloni Mehra'!$H$7:$H$300,'Saloni Mehra'!$B$7:$B$300,$B7) -> 4440117.3 | AE7: =AD7-AC7 -> 1039.3 | AF7: =IF(AC7>0,AE7/AC7,"") -> 0.00023412519 | AG7: =IF(AD$6=0,"",AD7/AD$6) -> 0.39759186 | AH7: =SUMIFS('Vidushi Malhotra'!$D$7:$D$300,'Vidushi Malhotra'!$B$7:$B$300,$B7) -> 121 | AI7: =IF(AND(AH7>0,AJ7>0),AJ7/AH7,"") -> 768 | AJ7: =SUMIFS('Vidushi Malhotra'!$E$7:$E$300,'Vidushi Malhotra'!$B$7:$B$300,$B7) -> 92928 | AK7: =SUMIFS('Vidushi Malhotra'!$H$7:$H$300,'Vidushi Malhotra'!$B$7:$B$300,$B7) -> 113994.1 | AL7: =AK7-AJ7 -> 21066.1 | AM7: =IF(AJ7>0,AL7/AJ7,"") -> 0.22669271 | AN7: =IF(AK$6=0,"",AK7/AK$6) -> 0.50373142 | AO7: =SUMIFS('Dr Umesh Choudhry'!$D$7:$D$300,'Dr Umesh Choudhry'!$B$7:$B$300,$B7) -> 2412 | AP7: =IF(AND(AO7>0,AQ7>0),AQ7/AO7,"") -> 800.28441 | AQ7: =SUMIFS('Dr Umesh Choudhry'!$E$7:$E$300,'Dr Umesh Choudhry'!$B$7:$B$300,$B7) -> 1930286 | AR7: =SUMIFS('Dr Umesh Choudhry'!$H$7:$H$300,'Dr Umesh Choudhry'!$B$7:$B$300,$B7) -> 2272345.2 | AS7: =AR7-AQ7 -> 342059.2 | AT7: =IF(AQ7>0,AS7/AQ7,"") -> 0.17720649 | AU7: =IF(AR$6=0,"",AR7/AR$6) -> 0.41914959 | AV7: =SUMIFS(DA!$D$7:$D$300,DA!$B$7:$B$300,$B7) -> 915 | AW7: =IF(AND(AV7>0,AX7>0),AX7/AV7,"") -> 1053.6798 | AX7: =SUMIFS(DA!$E$7:$E$300,DA!$B$7:$B$300,$B7) -> 964117 | AY7: =SUMIFS(DA!$H$7:$H$300,DA!$B$7:$B$300,$B7) -> 862021.5 | AZ7: =AY7-AX7 -> -102095.5 | BA7: =IF(AX7>0,AZ7/AX7,"") -> -0.10589534 | BB7: =IF(AY$6=0,"",AY7/AY$6) -> 0.22297442
A8: 2 | B8: Titan Company Ltd | C8: =IFERROR(INDEX(Prices!$C$6:$C$300,MATCH($B8,Prices!$A$6:$A$300,0)),"") -> 4350 | D8: =IFERROR(INDEX(Prices!$D$6:$D$300,MATCH($B8,Prices!$A$6:$A$300,0)),"") -> Close 22.10.2026 (Screener.in) | E8: =(M8>0)+(T8>0)+(AA8>0)+(AH8>0)+(AO8>0)+(AV8>0) -> 6 | F8: =M8+T8+AA8+AH8+AO8+AV8 -> 696 | G8: =IF(AND(F8>0,H8>0),H8/F8,"") -> 3938.1006 | H8: =O8+V8+AC8+AJ8+AQ8+AX8 -> 2740918 | I8: =P8+W8+AD8+AK8+AR8+AY8 -> 3027600 | J8: =I8-H8 -> 286682 | K8: =IF(H8>0,J8/H8,"") -> 0.10459342 | L8: =IF(I$6=0,"",I8/I$6) -> 0.080239136 | M8: =SUMIFS(Gautam!$D$7:$D$300,Gautam!$B$7:$B$300,$B8) -> 47 | N8: =IF(AND(M8>0,O8>0),O8/M8,"") -> 4763.7872 | O8: =SUMIFS(Gautam!$E$7:$E$300,Gautam!$B$7:$B$300,$B8) -> 223898 | P8: =SUMIFS(Gautam!$H$7:$H$300,Gautam!$B$7:$B$300,$B8) -> 204450 | Q8: =P8-O8 -> -19448 | R8: =IF(O8>0,Q8/O8,"") -> -0.086860981 | S8: =IF(P$6=0,"",P8/P$6) -> 0.039128009 | T8: =SUMIFS('Manish Shilpa'!$D$7:$D$300,'Manish Shilpa'!$B$7:$B$300,$B8) -> 165 | U8: =IF(AND(T8>0,V8>0),V8/T8,"") -> 3421.3939 | V8: =SUMIFS('Manish Shilpa'!$E$7:$E$300,'Manish Shilpa'!$B$7:$B$300,$B8) -> 564530 | W8: =SUMIFS('Manish Shilpa'!$H$7:$H$300,'Manish Shilpa'!$B$7:$B$300,$B8) -> 717750 | X8: =W8-V8 -> 153220 | Y8: =IF(V8>0,X8/V8,"") -> 0.27141162 | Z8: =IF(W$6=0,"",W8/W$6) -> 0.060693081 | AA8: =SUMIFS('Saloni Mehra'!$D$7:$D$300,'Saloni Mehra'!$B$7:$B$300,$B8) -> 244 | AB8: =IF(AND(AA8>0,AC8>0),AC8/AA8,"") -> 4288.8074 | AC8: =SUMIFS('Saloni Mehra'!$E$7:$E$300,'Saloni Mehra'!$B$7:$B$300,$B8) -> 1046469 | AD8: =SUMIFS('Saloni Mehra'!$H$7:$H$300,'Saloni Mehra'!$B$7:$B$300,$B8) -> 1061400 | AE8: =AD8-AC8 -> 14931 | AF8: =IF(AC8>0,AE8/AC8,"") -> 0.014267981 | AG8: =IF(AD$6=0,"",AD8/AD$6) -> 0.095043435 | AH8: =SUMIFS('Vidushi Malhotra'!$D$7:$D$300,'Vidushi Malhotra'!$B$7:$B$300,$B8) -> 9 | AI8: =IF(AND(AH8>0,AJ8>0),AJ8/AH8,"") -> 3160.1111 | AJ8: =SUMIFS('Vidushi Malhotra'!$E$7:$E$300,'Vidushi Malhotra'!$B$7:$B$300,$B8) -> 28441 | AK8: =SUMIFS('Vidushi Malhotra'!$H$7:$H$300,'Vidushi Malhotra'!$B$7:$B$300,$B8) -> 39150 | AL8: =AK8-AJ8 -> 10709 | AM8: =IF(AJ8>0,AL8/AJ8,"") -> 0.37653388 | AN8: =IF(AK$6=0,"",AK8/AK$6) -> 0.17300093 | AO8: =SUMIFS('Dr Umesh Choudhry'!$D$7:$D$300,'Dr Umesh Choudhry'!$B$7:$B$300,$B8) -> 172 | AP8: =IF(AND(AO8>0,AQ8>0),AQ8/AO8,"") -> 3589.9244 | AQ8: =SUMIFS('Dr Umesh Choudhry'!$E$7:$E$300,'Dr Umesh Choudhry'!$B$7:$B$300,$B8) -> 617467 | AR8: =SUMIFS('Dr Umesh Choudhry'!$H$7:$H$300,'Dr Umesh Choudhry'!$B$7:$B$300,$B8) -> 748200 | AS8: =AR8-AQ8 -> 130733 | AT8: =IF(AQ8>0,AS8/AQ8,"") -> 0.21172468 | AU8: =IF(AR$6=0,"",AR8/AR$6) -> 0.1380106 | AV8: =SUMIFS(DA!$D$7:$D$300,DA!$B$7:$B$300,$B8) -> 59 | AW8: =IF(AND(AV8>0,AX8>0),AX8/AV8,"") -> 4408.6949 | AX8: =SUMIFS(DA!$E$7:$E$300,DA!$B$7:$B$300,$B8) -> 260113 | AY8: =SUMIFS(DA!$H$7:$H$300,DA!$B$7:$B$300,$B8) -> 256650 | AZ8: =AY8-AX8 -> -3463 | BA8: =IF(AX8>0,AZ8/AX8,"") -> -0.013313445 | BB8: =IF(AY$6=0,"",AY8/AY$6) -> 0.066386262
A9: 3 | B9: Nippon India ETF Nifty 50 BeES | C9: =IFERROR(INDEX(Prices!$C$6:$C$300,MATCH($B9,Prices!$A$6:$A$300,0)),"") -> 256.69292 | D9: =IFERROR(INDEX(Prices!$D$6:$D$300,MATCH($B9,Prices!$A$6:$A$300,0)),"") -> Manish Shilpa stmt – live 23.10 | E9: =(M9>0)+(T9>0)+(AA9>0)+(AH9>0)+(AO9>0)+(AV9>0) -> 2 | F9: =M9+T9+AA9+AH9+AO9+AV9 -> 11161 | G9: =IF(AND(F9>0,H9>0),H9/F9,"") -> 151.22579 | H9: =O9+V9+AC9+AJ9+AQ9+AX9 -> 1687831 | I9: =P9+W9+AD9+AK9+AR9+AY9 -> 2864949.7 | J9: =I9-H9 -> 1177118.7 | K9: =IF(H9>0,J9/H9,"") -> 0.69741502 | L9: =IF(I$6=0,"",I9/I$6) -> 0.075928488 | M9: =SUMIFS(Gautam!$D$7:$D$300,Gautam!$B$7:$B$300,$B9) -> 0 | N9: =IF(AND(M9>0,O9>0),O9/M9,"") | O9: =SUMIFS(Gautam!$E$7:$E$300,Gautam!$B$7:$B$300,$B9) -> 0 | P9: =SUMIFS(Gautam!$H$7:$H$300,Gautam!$B$7:$B$300,$B9) -> 0 | Q9: =P9-O9 -> 0 | R9: =IF(O9>0,Q9/O9,"") | S9: =IF(P$6=0,"",P9/P$6) -> 0 | T9: =SUMIFS('Manish Shilpa'!$D$7:$D$300,'Manish Shilpa'!$B$7:$B$300,$B9) -> 11160 | U9: =IF(AND(T9>0,V9>0),V9/T9,"") -> 151.21685 | V9: =SUMIFS('Manish Shilpa'!$E$7:$E$300,'Manish Shilpa'!$B$7:$B$300,$B9) -> 1687580 | W9: =SUMIFS('Manish Shilpa'!$H$7:$H$300,'Manish Shilpa'!$B$7:$B$300,$B9) -> 2864693 | X9: =W9-V9 -> 1177113 | Y9: =IF(V9>0,X9/V9,"") -> 0.69751538 | Z9: =IF(W$6=0,"",W9/W$6) -> 0.242239 | AA9: =SUMIFS('Saloni Mehra'!$D$7:$D$300,'Saloni Mehra'!$B$7:$B$300,$B9) -> 0 | AB9: =IF(AND(AA9>0,AC9>0),AC9/AA9,"") | AC9: =SUMIFS('Saloni Mehra'!$E$7:$E$300,'Saloni Mehra'!$B$7:$B$300,$B9) -> 0 | AD9: =SUMIFS('Saloni Mehra'!$H$7:$H$300,'Saloni Mehra'!$B$7:$B$300,$B9) -> 0 | AE9: =AD9-AC9 -> 0 | AF9: =IF(AC9>0,AE9/AC9,"") | AG9: =IF(AD$6=0,"",AD9/AD$6) -> 0 | AH9: =SUMIFS('Vidushi Malhotra'!$D$7:$D$300,'Vidushi Malhotra'!$B$7:$B$300,$B9) -> 1 | AI9: =IF(AND(AH9>0,AJ9>0),AJ9/AH9,"") -> 251 | AJ9: =SUMIFS('Vidushi Malhotra'!$E$7:$E$300,'Vidushi Malhotra'!$B$7:$B$300,$B9) -> 251 | AK9: =SUMIFS('Vidushi Malhotra'!$H$7:$H$300,'Vidushi Malhotra'!$B$7:$B$300,$B9) -> 256.69292 | AL9: =AK9-AJ9 -> 5.6929211 | AM9: =IF(AJ9>0,AL9/AJ9,"") -> 0.022680961 | AN9: =IF(AK$6=0,"",AK9/AK$6) -> 0.0011343069 | AO9: =SUMIFS('Dr Umesh Choudhry'!$D$7:$D$300,'Dr Umesh Choudhry'!$B$7:$B$300,$B9) -> 0 | AP9: =IF(AND(AO9>0,AQ9>0),AQ9/AO9,"") | AQ9: =SUMIFS('Dr Umesh Choudhry'!$E$7:$E$300,'Dr Umesh Choudhry'!$B$7:$B$300,$B9) -> 0 | AR9: =SUMIFS('Dr Umesh Choudhry'!$H$7:$H$300,'Dr Umesh Choudhry'!$B$7:$B$300,$B9) -> 0 | AS9: =AR9-AQ9 -> 0 | AT9: =IF(AQ9>0,AS9/AQ9,"") | AU9: =IF(AR$6=0,"",AR9/AR$6) -> 0 | AV9: =SUMIFS(DA!$D$7:$D$300,DA!$B$7:$B$300,$B9) -> 0 | AW9: =IF(AND(AV9>0,AX9>0),AX9/AV9,"") | AX9: =SUMIFS(DA!$E$7:$E$300,DA!$B$7:$B$300,$B9) -> 0 | AY9: =SUMIFS(DA!$H$7:$H$300,DA!$B$7:$B$300,$B9) -> 0 | AZ9: =AY9-AX9 -> 0 | BA9: =IF(AX9>0,AZ9/AX9,"") | BB9: =IF(AY$6=0,"",AY9/AY$6) -> 0
A10: 4 | B10: HDFC Bank Ltd | C10: =IFERROR(INDEX(Prices!$C$6:$C$300,MATCH($B10,Prices!$A$6:$A$300,0)),"") -> 694.05 | D10: =IFERROR(INDEX(Prices!$D$6:$D$300,MATCH($B10,Prices!$A$6:$A$300,0)),"") -> Close 22.10.2026 (Screener.in) | E10: =(M10>0)+(T10>0)+(AA10>0)+(AH10>0)+(AO10>0)+(AV10>0) -> 6 | F10: =M10+T10+AA10+AH10+AO10+AV10 -> 3580 | G10: =IF(AND(F10>0,H10>0),H10/F10,"") -> 793.61704 | H10: =O10+V10+AC10+AJ10+AQ10+AX10 -> 2841149 | I10: =P10+W10+AD10+AK10+AR10+AY10 -> 2484699 | J10: =I10-H10 -> -356450 | K10: =IF(H10>0,J10/H10,"") -> -0.12545981 | L10: =IF(I$6=0,"",I10/I$6) -> 0.065850873 | M10: =SUMIFS(Gautam!$D$7:$D$300,Gautam!$B$7:$B$300,$B10) -> 447 | N10: =IF(AND(M10>0,O10>0),O10/M10,"") -> 716.1566 | O10: =SUMIFS(Gautam!$E$7:$E$300,Gautam!$B$7:$B$300,$B10) -> 320122 | P10: =SUMIFS(Gautam!$H$7:$H$300,Gautam!$B$7:$B$300,$B10) -> 310240.35 | Q10: =P10-O10 -> -9881.65 | R10: =IF(O10>0,Q10/O10,"") -> -0.030868388 | S10: =IF(P$6=0,"",P10/P$6) -> 0.059374356 | T10: =SUMIFS('Manish Shilpa'!$D$7:$D$300,'Manish Shilpa'!$B$7:$B$300,$B10) -> 1013 | U10: =IF(AND(T10>0,V10>0),V10/T10,"") -> 802.2537 | V10: =SUMIFS('Manish Shilpa'!$E$7:$E$300,'Manish Shilpa'!$B$7:$B$300,$B10) -> 812683 | W10: =SUMIFS('Manish Shilpa'!$H$7:$H$300,'Manish Shilpa'!$B$7:$B$300,$B10) -> 703072.65 | X10: =W10-V10 -> -109610.35 | Y10: =IF(V10>0,X10/V10,"") -> -0.13487467 | Z10: =IF(W$6=0,"",W10/W$6) -> 0.059451962 | AA10: =SUMIFS('Saloni Mehra'!$D$7:$D$300,'Saloni Mehra'!$B$7:$B$300,$B10) -> 1089 | AB10: =IF(AND(AA10>0,AC10>0),AC10/AA10,"") -> 772.60882 | AC10: =SUMIFS('Saloni Mehra'!$E$7:$E$300,'Saloni Mehra'!$B$7:$B$300,$B10) -> 841371 | AD10: =SUMIFS('Saloni Mehra'!$H$7:$H$300,'Saloni Mehra'!$B$7:$B$300,$B10) -> 755820.45 | AE10: =AD10-AC10 -> -85550.55 | AF10: =IF(AC10>0,AE10/AC10,"") -> -0.10167994 | AG10: =IF(AD$6=0,"",AD10/AD$6) -> 0.067680207 | AH10: =SUMIFS('Vidushi Malhotra'!$D$7:$D$300,'Vidushi Malhotra'!$B$7:$B$300,$B10) -> 21 | AI10: =IF(AND(AH10>0,AJ10>0),AJ10/AH10,"") -> 790.38095 | AJ10: =SUMIFS('Vidushi Malhotra'!$E$7:$E$300,'Vidushi Malhotra'!$B$7:$B$300,$B10) -> 16598 | AK10: =SUMIFS('Vidushi Malhotra'!$H$7:$H$300,'Vidushi Malhotra'!$B$7:$B$300,$B10) -> 14575.05 | AL10: =AK10-AJ10 -> -2022.95 | AM10: =IF(AJ10>0,AL10/AJ10,"") -> -0.12187914 | AN10: =IF(AK$6=0,"",AK10/AK$6) -> 0.064406058 | AO10: =SUMIFS('Dr Umesh Choudhry'!$D$7:$D$300,'Dr Umesh Choudhry'!$B$7:$B$300,$B10) -> 673 | AP10: =IF(AND(AO10>0,AQ10>0),AQ10/AO10,"") -> 890.65973 | AQ10: =SUMIFS('Dr Umesh Choudhry'!$E$7:$E$300,'Dr Umesh Choudhry'!$B$7:$B$300,$B10) -> 599414 | AR10: =SUMIFS('Dr Umesh Choudhry'!$H$7:$H$300,'Dr Umesh Choudhry'!$B$7:$B$300,$B10) -> 467095.65 | AS10: =AR10-AQ10 -> -132318.35 | AT10: =IF(AQ10>0,AS10/AQ10,"") -> -0.22074618 | AU10: =IF(AR$6=0,"",AR10/AR$6) -> 0.086158982 | AV10: =SUMIFS(DA!$D$7:$D$300,DA!$B$7:$B$300,$B10) -> 337 | AW10: =IF(AND(AV10>0,AX10>0),AX10/AV10,"") -> 744.69139 | AX10: =SUMIFS(DA!$E$7:$E$300,DA!$B$7:$B$300,$B10) -> 250961 | AY10: =SUMIFS(DA!$H$7:$H$300,DA!$B$7:$B$300,$B10) -> 233894.85 | AZ10: =AY10-AX10 -> -17066.15 | BA10: =IF(AX10>0,AZ10/AX10,"") -> -0.068003196 | BB10: =IF(AY$6=0,"",AY10/AY$6) -> 0.06050031
A11: 5 | B11: Poonawalla Fincorp Ltd | C11: =IFERROR(INDEX(Prices!$C$6:$C$300,MATCH($B11,Prices!$A$6:$A$300,0)),"") -> 432.45 | D11: =IFERROR(INDEX(Prices!$D$6:$D$300,MATCH($B11,Prices!$A$6:$A$300,0)),"") -> Close 22.10.2026 (Screener.in) | E11: =(M11>0)+(T11>0)+(AA11>0)+(AH11>0)+(AO11>0)+(AV11>0) -> 6 | F11: =M11+T11+AA11+AH11+AO11+AV11 -> 5392 | G11: =IF(AND(F11>0,H11>0),H11/F11,"") -> 453.12277 | H11: =O11+V11+AC11+AJ11+AQ11+AX11 -> 2443238 | I11: =P11+W11+AD11+AK11+AR11+AY11 -> 2331770.4 | J11: =I11-H11 -> -111467.6 | K11: =IF(H11>0,J11/H11,"") -> -0.045622899 | L11: =IF(I$6=0,"",I11/I$6) -> 0.061797874 | M11: =SUMIFS(Gautam!$D$7:$D$300,Gautam!$B$7:$B$300,$B11) -> 1132 | N11: =IF(AND(M11>0,O11>0),O11/M11,"") -> 465.69965 | O11: =SUMIFS(Gautam!$E$7:$E$300,Gautam!$B$7:$B$300,$B11) -> 527172 | P11: =SUMIFS(Gautam!$H$7:$H$300,Gautam!$B$7:$B$300,$B11) -> 489533.4 | Q11: =P11-O11 -> -37638.6 | R11: =IF(O11>0,Q11/O11,"") -> -0.071397191 | S11: =IF(P$6=0,"",P11/P$6) -> 0.093687782 | T11: =SUMIFS('Manish Shilpa'!$D$7:$D$300,'Manish Shilpa'!$B$7:$B$300,$B11) -> 1394 | U11: =IF(AND(T11>0,V11>0),V11/T11,"") -> 446.566 | V11: =SUMIFS('Manish Shilpa'!$E$7:$E$300,'Manish Shilpa'!$B$7:$B$300,$B11) -> 622513 | W11: =SUMIFS('Manish Shilpa'!$H$7:$H$300,'Manish Shilpa'!$B$7:$B$300,$B11) -> 602835.3 | X11: =W11-V11 -> -19677.7 | Y11: =IF(V11>0,X11/V11,"") -> -0.031610103 | Z11: =IF(W$6=0,"",W11/W$6) -> 0.050975872 | AA11: =SUMIFS('Saloni Mehra'!$D$7:$D$300,'Saloni Mehra'!$B$7:$B$300,$B11) -> 1267 | AB11: =IF(AND(AA11>0,AC11>0),AC11/AA11,"") -> 436.33623 | AC11: =SUMIFS('Saloni Mehra'!$E$7:$E$300,'Saloni Mehra'!$B$7:$B$300,$B11) -> 552838 | AD11: =SUMIFS('Saloni Mehra'!$H$7:$H$300,'Saloni Mehra'!$B$7:$B$300,$B11) -> 547914.15 | AE11: =AD11-AC11 -> -4923.85 | AF11: =IF(AC11>0,AE11/AC11,"") -> -0.008906497 | AG11: =IF(AD$6=0,"",AD11/AD$6) -> 0.049063165 | AH11: =SUMIFS('Vidushi Malhotra'!$D$7:$D$300,'Vidushi Malhotra'!$B$7:$B$300,$B11) -> 38 | AI11: =IF(AND(AH11>0,AJ11>0),AJ11/AH11,"") -> 452.42105 | AJ11: =SUMIFS('Vidushi Malhotra'!$E$7:$E$300,'Vidushi Malhotra'!$B$7:$B$300,$B11) -> 17192 | AK11: =SUMIFS('Vidushi Malhotra'!$H$7:$H$300,'Vidushi Malhotra'!$B$7:$B$300,$B11) -> 16433.1 | AL11: =AK11-AJ11 -> -758.9 | AM11: =IF(AJ11>0,AL11/AJ11,"") -> -0.044142624 | AN11: =IF(AK$6=0,"",AK11/AK$6) -> 0.072616643 | AO11: =SUMIFS('Dr Umesh Choudhry'!$D$7:$D$300,'Dr Umesh Choudhry'!$B$7:$B$300,$B11) -> 769 | AP11: =IF(AND(AO11>0,AQ11>0),AQ11/AO11,"") -> 451.22237 | AQ11: =SUMIFS('Dr Umesh Choudhry'!$E$7:$E$300,'Dr Umesh Choudhry'!$B$7:$B$300,$B11) -> 346990 | AR11: =SUMIFS('Dr Umesh Choudhry'!$H$7:$H$300,'Dr Umesh Choudhry'!$B$7:$B$300,$B11) -> 332554.05 | AS11: =AR11-AQ11 -> -14435.95 | AT11: =IF(AQ11>0,AS11/AQ11,"") -> -0.04160336 | AU11: =IF(AR$6=0,"",AR11/AR$6) -> 0.061341865 | AV11: =SUMIFS(DA!$D$7:$D$300,DA!$B$7:$B$300,$B11) -> 792 | AW11: =IF(AND(AV11>0,AX11>0),AX11/AV11,"") -> 475.42045 | AX11: =SUMIFS(DA!$E$7:$E$300,DA!$B$7:$B$300,$B11) -> 376533 | AY11: =SUMIFS(DA!$H$7:$H$300,DA!$B$7:$B$300,$B11) -> 342500.4 | AZ11: =AY11-AX11 -> -34032.6 | BA11: =IF(AX11>0,AZ11/AX11,"") -> -0.09038411 | BB11: =IF(AY$6=0,"",AY11/AY$6) -> 0.088592718
A12: 6 | B12: AFCOM Holdings Ltd | C12: =IFERROR(INDEX(Prices!$C$6:$C$300,MATCH($B12,Prices!$A$6:$A$300,0)),"") -> 1371.45 | D12: =IFERROR(INDEX(Prices!$D$6:$D$300,MATCH($B12,Prices!$A$6:$A$300,0)),"") -> Close 22.10.2026 (Screener.in) | E12: =(M12>0)+(T12>0)+(AA12>0)+(AH12>0)+(AO12>0)+(AV12>0) -> 5 | F12: =M12+T12+AA12+AH12+AO12+AV12 -> 1200 | G12: =IF(AND(F12>0,H12>0),H12/F12,"") -> 1079.9858 | H12: =O12+V12+AC12+AJ12+AQ12+AX12 -> 1295983 | I12: =P12+W12+AD12+AK12+AR12+AY12 -> 1645740 | J12: =I12-H12 -> 349757 | K12: =IF(H12>0,J12/H12,"") -> 0.26987777 | L12: =IF(I$6=0,"",I12/I$6) -> 0.043616315 | M12: =SUMIFS(Gautam!$D$7:$D$300,Gautam!$B$7:$B$300,$B12) -> 120 | N12: =IF(AND(M12>0,O12>0),O12/M12,"") -> 1666 | O12: =SUMIFS(Gautam!$E$7:$E$300,Gautam!$B$7:$B$300,$B12) -> 199920 | P12: =SUMIFS(Gautam!$H$7:$H$300,Gautam!$B$7:$B$300,$B12) -> 164574 | Q12: =P12-O12 -> -35346 | R12: =IF(O12>0,Q12/O12,"") -> -0.17680072 | S12: =IF(P$6=0,"",P12/P$6) -> 0.031496468 | T12: =SUMIFS('Manish Shilpa'!$D$7:$D$300,'Manish Shilpa'!$B$7:$B$300,$B12) -> 360 | U12: =IF(AND(T12>0,V12>0),V12/T12,"") -> 1007.5667 | V12: =SUMIFS('Manish Shilpa'!$E$7:$E$300,'Manish Shilpa'!$B$7:$B$300,$B12) -> 362724 | W12: =SUMIFS('Manish Shilpa'!$H$7:$H$300,'Manish Shilpa'!$B$7:$B$300,$B12) -> 493722 | X12: =W12-V12 -> 130998 | Y12: =IF(V12>0,X12/V12,"") -> 0.36115063 | Z12: =IF(W$6=0,"",W12/W$6) -> 0.041749229 | AA12: =SUMIFS('Saloni Mehra'!$D$7:$D$300,'Saloni Mehra'!$B$7:$B$300,$B12) -> 360 | AB12: =IF(AND(AA12>0,AC12>0),AC12/AA12,"") -> 1003 | AC12: =SUMIFS('Saloni Mehra'!$E$7:$E$300,'Saloni Mehra'!$B$7:$B$300,$B12) -> 361080 | AD12: =SUMIFS('Saloni Mehra'!$H$7:$H$300,'Saloni Mehra'!$B$7:$B$300,$B12) -> 493722 | AE12: =AD12-AC12 -> 132642 | AF12: =IF(AC12>0,AE12/AC12,"") -> 0.36734796 | AG12: =IF(AD$6=0,"",AD12/AD$6) -> 0.04421051 | AH12: =SUMIFS('Vidushi Malhotra'!$D$7:$D$300,'Vidushi Malhotra'!$B$7:$B$300,$B12) -> 0 | AI12: =IF(AND(AH12>0,AJ12>0),AJ12/AH12,"") | AJ12: =SUMIFS('Vidushi Malhotra'!$E$7:$E$300,'Vidushi Malhotra'!$B$7:$B$300,$B12) -> 0 | AK12: =SUMIFS('Vidushi Malhotra'!$H$7:$H$300,'Vidushi Malhotra'!$B$7:$B$300,$B12) -> 0 | AL12: =AK12-AJ12 -> 0 | AM12: =IF(AJ12>0,AL12/AJ12,"") | AN12: =IF(AK$6=0,"",AK12/AK$6) -> 0 | AO12: =SUMIFS('Dr Umesh Choudhry'!$D$7:$D$300,'Dr Umesh Choudhry'!$B$7:$B$300,$B12) -> 240 | AP12: =IF(AND(AO12>0,AQ12>0),AQ12/AO12,"") -> 846.57917 | AQ12: =SUMIFS('Dr Umesh Choudhry'!$E$7:$E$300,'Dr Umesh Choudhry'!$B$7:$B$300,$B12) -> 203179 | AR12: =SUMIFS('Dr Umesh Choudhry'!$H$7:$H$300,'Dr Umesh Choudhry'!$B$7:$B$300,$B12) -> 329148 | AS12: =AR12-AQ12 -> 125969 | AT12: =IF(AQ12>0,AS12/AQ12,"") -> 0.61999025 | AU12: =IF(AR$6=0,"",AR12/AR$6) -> 0.060713596 | AV12: =SUMIFS(DA!$D$7:$D$300,DA!$B$7:$B$300,$B12) -> 120 | AW12: =IF(AND(AV12>0,AX12>0),AX12/AV12,"") -> 1409 | AX12: =SUMIFS(DA!$E$7:$E$300,DA!$B$7:$B$300,$B12) -> 169080 | AY12: =SUMIFS(DA!$H$7:$H$300,DA!$B$7:$B$300,$B12) -> 164574 | AZ12: =AY12-AX12 -> -4506 | BA12: =IF(AX12>0,AZ12/AX12,"") -> -0.026650106 | BB12: =IF(AY$6=0,"",AY12/AY$6) -> 0.042569463
A13: 7 | B13: Tata Consultancy Services Ltd | C13: =IFERROR(INDEX(Prices!$C$6:$C$300,MATCH($B13,Prices!$A$6:$A$300,0)),"") -> 2506.9 | D13: =IFERROR(INDEX(Prices!$D$6:$D$300,MATCH($B13,Prices!$A$6:$A$300,0)),"") -> Close 22.10.2026 (Screener.in) | E13: =(M13>0)+(T13>0)+(AA13>0)+(AH13>0)+(AO13>0)+(AV13>0) -> 5 | F13: =M13+T13+AA13+AH13+AO13+AV13 -> 468 | G13: =IF(AND(F13>0,H13>0),H13/F13,"") -> 2396.8868 | H13: =O13+V13+AC13+AJ13+AQ13+AX13 -> 1121743 | I13: =P13+W13+AD13+AK13+AR13+AY13 -> 1173229.2 | J13: =I13-H13 -> 51486.2 | K13: =IF(H13>0,J13/H13,"") -> 0.045898392 | L13: =IF(I$6=0,"",I13/I$6) -> 0.031093572 | M13: =SUMIFS(Gautam!$D$7:$D$300,Gautam!$B$7:$B$300,$B13) -> 92 | N13: =IF(AND(M13>0,O13>0),O13/M13,"") -> 2289 | O13: =SUMIFS(Gautam!$E$7:$E$300,Gautam!$B$7:$B$300,$B13) -> 210588 | P13: =SUMIFS(Gautam!$H$7:$H$300,Gautam!$B$7:$B$300,$B13) -> 230634.8 | Q13: =P13-O13 -> 20046.8 | R13: =IF(O13>0,Q13/O13,"") -> 0.095194408 | S13: =IF(P$6=0,"",P13/P$6) -> 0.044139303 | T13: =SUMIFS('Manish Shilpa'!$D$7:$D$300,'Manish Shilpa'!$B$7:$B$300,$B13) -> 29 | U13: =IF(AND(T13>0,V13>0),V13/T13,"") -> 3379.1034 | V13: =SUMIFS('Manish Shilpa'!$E$7:$E$300,'Manish Shilpa'!$B$7:$B$300,$B13) -> 97994 | W13: =SUMIFS('Manish Shilpa'!$H$7:$H$300,'Manish Shilpa'!$B$7:$B$300,$B13) -> 72700.1 | X13: =W13-V13 -> -25293.9 | Y13: =IF(V13>0,X13/V13,"") -> -0.25811682 | Z13: =IF(W$6=0,"",W13/W$6) -> 0.0061475348 | AA13: =SUMIFS('Saloni Mehra'!$D$7:$D$300,'Saloni Mehra'!$B$7:$B$300,$B13) -> 305 | AB13: =IF(AND(AA13>0,AC13>0),AC13/AA13,"") -> 2162 | AC13: =SUMIFS('Saloni Mehra'!$E$7:$E$300,'Saloni Mehra'!$B$7:$B$300,$B13) -> 659410 | AD13: =SUMIFS('Saloni Mehra'!$H$7:$H$300,'Saloni Mehra'!$B$7:$B$300,$B13) -> 764604.5 | AE13: =AD13-AC13 -> 105194.5 | AF13: =IF(AC13>0,AE13/AC13,"") -> 0.15952821 | AG13: =IF(AD$6=0,"",AD13/AD$6) -> 0.068466778 | AH13: =SUMIFS('Vidushi Malhotra'!$D$7:$D$300,'Vidushi Malhotra'!$B$7:$B$300,$B13) -> 0 | AI13: =IF(AND(AH13>0,AJ13>0),AJ13/AH13,"") | AJ13: =SUMIFS('Vidushi Malhotra'!$E$7:$E$300,'Vidushi Malhotra'!$B$7:$B$300,$B13) -> 0 | AK13: =SUMIFS('Vidushi Malhotra'!$H$7:$H$300,'Vidushi Malhotra'!$B$7:$B$300,$B13) -> 0 | AL13: =AK13-AJ13 -> 0 | AM13: =IF(AJ13>0,AL13/AJ13,"") | AN13: =IF(AK$6=0,"",AK13/AK$6) -> 0 | AO13: =SUMIFS('Dr Umesh Choudhry'!$D$7:$D$300,'Dr Umesh Choudhry'!$B$7:$B$300,$B13) -> 29 | AP13: =IF(AND(AO13>0,AQ13>0),AQ13/AO13,"") -> 4227.6897 | AQ13: =SUMIFS('Dr Umesh Choudhry'!$E$7:$E$300,'Dr Umesh Choudhry'!$B$7:$B$300,$B13) -> 122603 | AR13: =SUMIFS('Dr Umesh Choudhry'!$H$7:$H$300,'Dr Umesh Choudhry'!$B$7:$B$300,$B13) -> 72700.1 | AS13: =AR13-AQ13 -> -49902.9 | AT13: =IF(AQ13>0,AS13/AQ13,"") -> -0.40702838 | AU13: =IF(AR$6=0,"",AR13/AR$6) -> 0.01341003 | AV13: =SUMIFS(DA!$D$7:$D$300,DA!$B$7:$B$300,$B13) -> 13 | AW13: =IF(AND(AV13>0,AX13>0),AX13/AV13,"") -> 2396 | AX13: =SUMIFS(DA!$E$7:$E$300,DA!$B$7:$B$300,$B13) -> 31148 | AY13: =SUMIFS(DA!$H$7:$H$300,DA!$B$7:$B$300,$B13) -> 32589.7 | AZ13: =AY13-AX13 -> 1441.7 | BA13: =IF(AX13>0,AZ13/AX13,"") -> 0.046285476 | BB13: =IF(AY$6=0,"",AY13/AY$6) -> 0.0084298007
A14: 8 | B14: LTM Ltd (formerly LTIMindtree) | C14: =IFERROR(INDEX(Prices!$C$6:$C$300,MATCH($B14,Prices!$A$6:$A$300,0)),"") -> 4274 | D14: =IFERROR(INDEX(Prices!$D$6:$D$300,MATCH($B14,Prices!$A$6:$A$300,0)),"") -> Close 22.10.2026 (Screener.in) | E14: =(M14>0)+(T14>0)+(AA14>0)+(AH14>0)+(AO14>0)+(AV14>0) -> 6 | F14: =M14+T14+AA14+AH14+AO14+AV14 -> 253 | G14: =IF(AND(F14>0,H14>0),H14/F14,"") -> 4727.1265 | H14: =O14+V14+AC14+AJ14+AQ14+AX14 -> 1195963 | I14: =P14+W14+AD14+AK14+AR14+AY14 -> 1081322 | J14: =I14-H14 -> -114641 | K14: =IF(H14>0,J14/H14,"") -> -0.095856644 | L14: =IF(I$6=0,"",I14/I$6) -> 0.028657796 | M14: =SUMIFS(Gautam!$D$7:$D$300,Gautam!$B$7:$B$300,$B14) -> 60 | N14: =IF(AND(M14>0,O14>0),O14/M14,"") -> 4564 | O14: =SUMIFS(Gautam!$E$7:$E$300,Gautam!$B$7:$B$300,$B14) -> 273840 | P14: =SUMIFS(Gautam!$H$7:$H$300,Gautam!$B$7:$B$300,$B14) -> 256440 | Q14: =P14-O14 -> -17400 | R14: =IF(O14>0,Q14/O14,"") -> -0.063540754 | S14: =IF(P$6=0,"",P14/P$6) -> 0.049077948 | T14: =SUMIFS('Manish Shilpa'!$D$7:$D$300,'Manish Shilpa'!$B$7:$B$300,$B14) -> 66 | U14: =IF(AND(T14>0,V14>0),V14/T14,"") -> 5274.803 | V14: =SUMIFS('Manish Shilpa'!$E$7:$E$300,'Manish Shilpa'!$B$7:$B$300,$B14) -> 348137 | W14: =SUMIFS('Manish Shilpa'!$H$7:$H$300,'Manish Shilpa'!$B$7:$B$300,$B14) -> 282084 | X14: =W14-V14 -> -66053 | Y14: =IF(V14>0,X14/V14,"") -> -0.18973278 | Z14: =IF(W$6=0,"",W14/W$6) -> 0.023853079 | AA14: =SUMIFS('Saloni Mehra'!$D$7:$D$300,'Saloni Mehra'!$B$7:$B$300,$B14) -> 83 | AB14: =IF(AND(AA14>0,AC14>0),AC14/AA14,"") -> 3897.9036 | AC14: =SUMIFS('Saloni Mehra'!$E$7:$E$300,'Saloni Mehra'!$B$7:$B$300,$B14) -> 323526 | AD14: =SUMIFS('Saloni Mehra'!$H$7:$H$300,'Saloni Mehra'!$B$7:$B$300,$B14) -> 354742 | AE14: =AD14-AC14 -> 31216 | AF14: =IF(AC14>0,AE14/AC14,"") -> 0.096486836 | AG14: =IF(AD$6=0,"",AD14/AD$6) -> 0.031765497 | AH14: =SUMIFS('Vidushi Malhotra'!$D$7:$D$300,'Vidushi Malhotra'!$B$7:$B$300,$B14) -> 2 | AI14: =IF(AND(AH14>0,AJ14>0),AJ14/AH14,"") -> 5099 | AJ14: =SUMIFS('Vidushi Malhotra'!$E$7:$E$300,'Vidushi Malhotra'!$B$7:$B$300,$B14) -> 10198 | AK14: =SUMIFS('Vidushi Malhotra'!$H$7:$H$300,'Vidushi Malhotra'!$B$7:$B$300,$B14) -> 8548 | AL14: =AK14-AJ14 -> -1650 | AM14: =IF(AJ14>0,AL14/AJ14,"") -> -0.16179643 | AN14: =IF(AK$6=0,"",AK14/AK$6) -> 0.037772974 | AO14: =SUMIFS('Dr Umesh Choudhry'!$D$7:$D$300,'Dr Umesh Choudhry'!$B$7:$B$300,$B14) -> 37 | AP14: =IF(AND(AO14>0,AQ14>0),AQ14/AO14,"") -> 5854.1081 | AQ14: =SUMIFS('Dr Umesh Choudhry'!$E$7:$E$300,'Dr Umesh Choudhry'!$B$7:$B$300,$B14) -> 216602 | AR14: =SUMIFS('Dr Umesh Choudhry'!$H$7:$H$300,'Dr Umesh Choudhry'!$B$7:$B$300,$B14) -> 158138 | AS14: =AR14-AQ14 -> -58464 | AT14: =IF(AQ14>0,AS14/AQ14,"") -> -0.26991441 | AU14: =IF(AR$6=0,"",AR14/AR$6) -> 0.029169634 | AV14: =SUMIFS(DA!$D$7:$D$300,DA!$B$7:$B$300,$B14) -> 5 | AW14: =IF(AND(AV14>0,AX14>0),AX14/AV14,"") -> 4732 | AX14: =SUMIFS(DA!$E$7:$E$300,DA!$B$7:$B$300,$B14) -> 23660 | AY14: =SUMIFS(DA!$H$7:$H$300,DA!$B$7:$B$300,$B14) -> 21370 | AZ14: =AY14-AX14 -> -2290 | BA14: =IF(AX14>0,AZ14/AX14,"") -> -0.096787828 | BB14: =IF(AY$6=0,"",AY14/AY$6) -> 0.0055276618
A15: 9 | B15: Bajaj Housing Finance Ltd | C15: =IFERROR(INDEX(Prices!$C$6:$C$300,MATCH($B15,Prices!$A$6:$A$300,0)),"") -> 81.02 | D15: =IFERROR(INDEX(Prices!$D$6:$D$300,MATCH($B15,Prices!$A$6:$A$300,0)),"") -> Close 22.10.2026 (Screener.in) | E15: =(M15>0)+(T15>0)+(AA15>0)+(AH15>0)+(AO15>0)+(AV15>0) -> 6 | F15: =M15+T15+AA15+AH15+AO15+AV15 -> 13273 | G15: =IF(AND(F15>0,H15>0),H15/F15,"") -> 100.94138 | H15: =O15+V15+AC15+AJ15+AQ15+AX15 -> 1339795 | I15: =P15+W15+AD15+AK15+AR15+AY15 -> 1075378.5 | J15: =I15-H15 -> -264416.54 | K15: =IF(H15>0,J15/H15,"") -> -0.19735597 | L15: =IF(I$6=0,"",I15/I$6) -> 0.028500277 | M15: =SUMIFS(Gautam!$D$7:$D$300,Gautam!$B$7:$B$300,$B15) -> 1600 | N15: =IF(AND(M15>0,O15>0),O15/M15,"") -> 83.08125 | O15: =SUMIFS(Gautam!$E$7:$E$300,Gautam!$B$7:$B$300,$B15) -> 132930 | P15: =SUMIFS(Gautam!$H$7:$H$300,Gautam!$B$7:$B$300,$B15) -> 129632 | Q15: =P15-O15 -> -3298 | R15: =IF(O15>0,Q15/O15,"") -> -0.02481005 | S15: =IF(P$6=0,"",P15/P$6) -> 0.024809205 | T15: =SUMIFS('Manish Shilpa'!$D$7:$D$300,'Manish Shilpa'!$B$7:$B$300,$B15) -> 3762 | U15: =IF(AND(T15>0,V15>0),V15/T15,"") -> 115.01675 | V15: =SUMIFS('Manish Shilpa'!$E$7:$E$300,'Manish Shilpa'!$B$7:$B$300,$B15) -> 432693 | W15: =SUMIFS('Manish Shilpa'!$H$7:$H$300,'Manish Shilpa'!$B$7:$B$300,$B15) -> 304797.24 | X15: =W15-V15 -> -127895.76 | Y15: =IF(V15>0,X15/V15,"") -> -0.29558084 | Z15: =IF(W$6=0,"",W15/W$6) -> 0.025773715 | AA15: =SUMIFS('Saloni Mehra'!$D$7:$D$300,'Saloni Mehra'!$B$7:$B$300,$B15) -> 3860 | AB15: =IF(AND(AA15>0,AC15>0),AC15/AA15,"") -> 85.925389 | AC15: =SUMIFS('Saloni Mehra'!$E$7:$E$300,'Saloni Mehra'!$B$7:$B$300,$B15) -> 331672 | AD15: =SUMIFS('Saloni Mehra'!$H$7:$H$300,'Saloni Mehra'!$B$7:$B$300,$B15) -> 312737.2 | AE15: =AD15-AC15 -> -18934.8 | AF15: =IF(AC15>0,AE15/AC15,"") -> -0.057088931 | AG15: =IF(AD$6=0,"",AD15/AD$6) -> 0.028004162 | AH15: =SUMIFS('Vidushi Malhotra'!$D$7:$D$300,'Vidushi Malhotra'!$B$7:$B$300,$B15) -> 121 | AI15: =IF(AND(AH15>0,AJ15>0),AJ15/AH15,"") -> 115.43802 | AJ15: =SUMIFS('Vidushi Malhotra'!$E$7:$E$300,'Vidushi Malhotra'!$B$7:$B$300,$B15) -> 13968 | AK15: =SUMIFS('Vidushi Malhotra'!$H$7:$H$300,'Vidushi Malhotra'!$B$7:$B$300,$B15) -> 9803.42 | AL15: =AK15-AJ15 -> -4164.58 | AM15: =IF(AJ15>0,AL15/AJ15,"") -> -0.29815149 | AN15: =IF(AK$6=0,"",AK15/AK$6) -> 0.043320582 | AO15: =SUMIFS('Dr Umesh Choudhry'!$D$7:$D$300,'Dr Umesh Choudhry'!$B$7:$B$300,$B15) -> 2198 | AP15: =IF(AND(AO15>0,AQ15>0),AQ15/AO15,"") -> 116.37853 | AQ15: =SUMIFS('Dr Umesh Choudhry'!$E$7:$E$300,'Dr Umesh Choudhry'!$B$7:$B$300,$B15) -> 255800 | AR15: =SUMIFS('Dr Umesh Choudhry'!$H$7:$H$300,'Dr Umesh Choudhry'!$B$7:$B$300,$B15) -> 178081.96 | AS15: =AR15-AQ15 -> -77718.04 | AT15: =IF(AQ15>0,AS15/AQ15,"") -> -0.30382346 | AU15: =IF(AR$6=0,"",AR15/AR$6) -> 0.032848433 | AV15: =SUMIFS(DA!$D$7:$D$300,DA!$B$7:$B$300,$B15) -> 1732 | AW15: =IF(AND(AV15>0,AX15>0),AX15/AV15,"") -> 99.729792 | AX15: =SUMIFS(DA!$E$7:$E$300,DA!$B$7:$B$300,$B15) -> 172732 | AY15: =SUMIFS(DA!$H$7:$H$300,DA!$B$7:$B$300,$B15) -> 140326.64 | AZ15: =AY15-AX15 -> -32405.36 | BA15: =IF(AX15>0,AZ15/AX15,"") -> -0.18760484 | BB15: =IF(AY$6=0,"",AY15/AY$6) -> 0.03629753
A16: 10 | B16: Connplex Cinemas Ltd | C16: =IFERROR(INDEX(Prices!$C$6:$C$300,MATCH($B16,Prices!$A$6:$A$300,0)),"") -> 234.25 | D16: =IFERROR(INDEX(Prices!$D$6:$D$300,MATCH($B16,Prices!$A$6:$A$300,0)),"") -> Close 22.10.2026 (Screener.in) | E16: =(M16>0)+(T16>0)+(AA16>0)+(AH16>0)+(AO16>0)+(AV16>0) -> 5 | F16: =M16+T16+AA16+AH16+AO16+AV16 -> 4000 | G16: =IF(AND(F16>0,H16>0),H16/F16,"") -> 233.36675 | H16: =O16+V16+AC16+AJ16+AQ16+AX16 -> 933467 | I16: =P16+W16+AD16+AK16+AR16+AY16 -> 937000 | J16: =I16-H16 -> 3533 | K16: =IF(H16>0,J16/H16,"") -> 0.0037848151 | L16: =IF(I$6=0,"",I16/I$6) -> 0.024832894 | M16: =SUMIFS(Gautam!$D$7:$D$300,Gautam!$B$7:$B$300,$B16) -> 800 | N16: =IF(AND(M16>0,O16>0),O16/M16,"") -> 264 | O16: =SUMIFS(Gautam!$E$7:$E$300,Gautam!$B$7:$B$300,$B16) -> 211200 | P16: =SUMIFS(Gautam!$H$7:$H$300,Gautam!$B$7:$B$300,$B16) -> 187400 | Q16: =P16-O16 -> -23800 | R16: =IF(O16>0,Q16/O16,"") -> -0.11268939 | S16: =IF(P$6=0,"",P16/P$6) -> 0.035864949 | T16: =SUMIFS('Manish Shilpa'!$D$7:$D$300,'Manish Shilpa'!$B$7:$B$300,$B16) -> 800 | U16: =IF(AND(T16>0,V16>0),V16/T16,"") -> 235.09375 | V16: =SUMIFS('Manish Shilpa'!$E$7:$E$300,'Manish Shilpa'!$B$7:$B$300,$B16) -> 188075 | W16: =SUMIFS('Manish Shilpa'!$H$7:$H$300,'Manish Shilpa'!$B$7:$B$300,$B16) -> 187400 | X16: =W16-V16 -> -675 | Y16: =IF(V16>0,X16/V16,"") -> -0.0035889938 | Z16: =IF(W$6=0,"",W16/W$6) -> 0.015846581 | AA16: =SUMIFS('Saloni Mehra'!$D$7:$D$300,'Saloni Mehra'!$B$7:$B$300,$B16) -> 800 | AB16: =IF(AND(AA16>0,AC16>0),AC16/AA16,"") -> 212.75 | AC16: =SUMIFS('Saloni Mehra'!$E$7:$E$300,'Saloni Mehra'!$B$7:$B$300,$B16) -> 170200 | AD16: =SUMIFS('Saloni Mehra'!$H$7:$H$300,'Saloni Mehra'!$B$7:$B$300,$B16) -> 187400 | AE16: =AD16-AC16 -> 17200 | AF16: =IF(AC16>0,AE16/AC16,"") -> 0.10105758 | AG16: =IF(AD$6=0,"",AD16/AD$6) -> 0.016780799 | AH16: =SUMIFS('Vidushi Malhotra'!$D$7:$D$300,'Vidushi Malhotra'!$B$7:$B$300,$B16) -> 0 | AI16: =IF(AND(AH16>0,AJ16>0),AJ16/AH16,"") | AJ16: =SUMIFS('Vidushi Malhotra'!$E$7:$E$300,'Vidushi Malhotra'!$B$7:$B$300,$B16) -> 0 | AK16: =SUMIFS('Vidushi Malhotra'!$H$7:$H$300,'Vidushi Malhotra'!$B$7:$B$300,$B16) -> 0 | AL16: =AK16-AJ16 -> 0 | AM16: =IF(AJ16>0,AL16/AJ16,"") | AN16: =IF(AK$6=0,"",AK16/AK$6) -> 0 | AO16: =SUMIFS('Dr Umesh Choudhry'!$D$7:$D$300,'Dr Umesh Choudhry'!$B$7:$B$300,$B16) -> 800 | AP16: =IF(AND(AO16>0,AQ16>0),AQ16/AO16,"") -> 229.99 | AQ16: =SUMIFS('Dr Umesh Choudhry'!$E$7:$E$300,'Dr Umesh Choudhry'!$B$7:$B$300,$B16) -> 183992 | AR16: =SUMIFS('Dr Umesh Choudhry'!$H$7:$H$300,'Dr Umesh Choudhry'!$B$7:$B$300,$B16) -> 187400 | AS16: =AR16-AQ16 -> 3408 | AT16: =IF(AQ16>0,AS16/AQ16,"") -> 0.018522544 | AU16: =IF(AR$6=0,"",AR16/AR$6) -> 0.03456721 | AV16: =SUMIFS(DA!$D$7:$D$300,DA!$B$7:$B$300,$B16) -> 800 | AW16: =IF(AND(AV16>0,AX16>0),AX16/AV16,"") -> 225 | AX16: =SUMIFS(DA!$E$7:$E$300,DA!$B$7:$B$300,$B16) -> 180000 | AY16: =SUMIFS(DA!$H$7:$H$300,DA!$B$7:$B$300,$B16) -> 187400 | AZ16: =AY16-AX16 -> 7400 | BA16: =IF(AX16>0,AZ16/AX16,"") -> 0.041111111 | BB16: =IF(AY$6=0,"",AY16/AY$6) -> 0.04847374
A17: 11 | B17: L&T Technology Services Ltd | C17: =IFERROR(INDEX(Prices!$C$6:$C$300,MATCH($B17,Prices!$A$6:$A$300,0)),"") -> 3954.8 | D17: =IFERROR(INDEX(Prices!$D$6:$D$300,MATCH($B17,Prices!$A$6:$A$300,0)),"") -> Close 22.10.2026 (Screener.in) | E17: =(M17>0)+(T17>0)+(AA17>0)+(AH17>0)+(AO17>0)+(AV17>0) -> 6 | F17: =M17+T17+AA17+AH17+AO17+AV17 -> 231 | G17: =IF(AND(F17>0,H17>0),H17/F17,"") -> 3876.0303 | H17: =O17+V17+AC17+AJ17+AQ17+AX17 -> 895363 | I17: =P17+W17+AD17+AK17+AR17+AY17 -> 913558.8 | J17: =I17-H17 -> 18195.8 | K17: =IF(H17>0,J17/H17,"") -> 0.02032226 | L17: =IF(I$6=0,"",I17/I$6) -> 0.024211643 | M17: =SUMIFS(Gautam!$D$7:$D$300,Gautam!$B$7:$B$300,$B17) -> 30 | N17: =IF(AND(M17>0,O17>0),O17/M17,"") -> 3484.3667 | O17: =SUMIFS(Gautam!$E$7:$E$300,Gautam!$B$7:$B$300,$B17) -> 104531 | P17: =SUMIFS(Gautam!$H$7:$H$300,Gautam!$B$7:$B$300,$B17) -> 118644 | Q17: =P17-O17 -> 14113 | R17: =IF(O17>0,Q17/O17,"") -> 0.13501258 | S17: =IF(P$6=0,"",P17/P$6) -> 0.022706302 | T17: =SUMIFS('Manish Shilpa'!$D$7:$D$300,'Manish Shilpa'!$B$7:$B$300,$B17) -> 72 | U17: =IF(AND(T17>0,V17>0),V17/T17,"") -> 4214.8194 | V17: =SUMIFS('Manish Shilpa'!$E$7:$E$300,'Manish Shilpa'!$B$7:$B$300,$B17) -> 303467 | W17: =SUMIFS('Manish Shilpa'!$H$7:$H$300,'Manish Shilpa'!$B$7:$B$300,$B17) -> 284745.6 | X17: =W17-V17 -> -18721.4 | Y17: =IF(V17>0,X17/V17,"") -> -0.061691716 | Z17: =IF(W$6=0,"",W17/W$6) -> 0.024078144 | AA17: =SUMIFS('Saloni Mehra'!$D$7:$D$300,'Saloni Mehra'!$B$7:$B$300,$B17) -> 72 | AB17: =IF(AND(AA17>0,AC17>0),AC17/AA17,"") -> 3415.2083 | AC17: =SUMIFS('Saloni Mehra'!$E$7:$E$300,'Saloni Mehra'!$B$7:$B$300,$B17) -> 245895 | AD17: =SUMIFS('Saloni Mehra'!$H$7:$H$300,'Saloni Mehra'!$B$7:$B$300,$B17) -> 284745.6 | AE17: =AD17-AC17 -> 38850.6 | AF17: =IF(AC17>0,AE17/AC17,"") -> 0.15799671 | AG17: =IF(AD$6=0,"",AD17/AD$6) -> 0.025497645 | AH17: =SUMIFS('Vidushi Malhotra'!$D$7:$D$300,'Vidushi Malhotra'!$B$7:$B$300,$B17) -> 1 | AI17: =IF(AND(AH17>0,AJ17>0),AJ17/AH17,"") -> 4607 | AJ17: =SUMIFS('Vidushi Malhotra'!$E$7:$E$300,'Vidushi Malhotra'!$B$7:$B$300,$B17) -> 4607 | AK17: =SUMIFS('Vidushi Malhotra'!$H$7:$H$300,'Vidushi Malhotra'!$B$7:$B$300,$B17) -> 3954.8 | AL17: =AK17-AJ17 -> -652.2 | AM17: =IF(AJ17>0,AL17/AJ17,"") -> -0.14156718 | AN17: =IF(AK$6=0,"",AK17/AK$6) -> 0.017475966 | AO17: =SUMIFS('Dr Umesh Choudhry'!$D$7:$D$300,'Dr Umesh Choudhry'!$B$7:$B$300,$B17) -> 32 | AP17: =IF(AND(AO17>0,AQ17>0),AQ17/AO17,"") -> 4719.9688 | AQ17: =SUMIFS('Dr Umesh Choudhry'!$E$7:$E$300,'Dr Umesh Choudhry'!$B$7:$B$300,$B17) -> 151039 | AR17: =SUMIFS('Dr Umesh Choudhry'!$H$7:$H$300,'Dr Umesh Choudhry'!$B$7:$B$300,$B17) -> 126553.6 | AS17: =AR17-AQ17 -> -24485.4 | AT17: =IF(AQ17>0,AS17/AQ17,"") -> -0.1621131 | AU17: =IF(AR$6=0,"",AR17/AR$6) -> 0.023343676 | AV17: =SUMIFS(DA!$D$7:$D$300,DA!$B$7:$B$300,$B17) -> 24 | AW17: =IF(AND(AV17>0,AX17>0),AX17/AV17,"") -> 3576 | AX17: =SUMIFS(DA!$E$7:$E$300,DA!$B$7:$B$300,$B17) -> 85824 | AY17: =SUMIFS(DA!$H$7:$H$300,DA!$B$7:$B$300,$B17) -> 94915.2 | AZ17: =AY17-AX17 -> 9091.2 | BA17: =IF(AX17>0,AZ17/AX17,"") -> 0.10592841 | BB17: =IF(AY$6=0,"",AY17/AY$6) -> 0.024551199
A18: 12 | B18: Jubilant FoodWorks Ltd | C18: =IFERROR(INDEX(Prices!$C$6:$C$300,MATCH($B18,Prices!$A$6:$A$300,0)),"") -> 404.9 | D18: =IFERROR(INDEX(Prices!$D$6:$D$300,MATCH($B18,Prices!$A$6:$A$300,0)),"") -> Close 22.10.2026 (Screener.in) | E18: =(M18>0)+(T18>0)+(AA18>0)+(AH18>0)+(AO18>0)+(AV18>0) -> 1 | F18: =M18+T18+AA18+AH18+AO18+AV18 -> 2000 | G18: =IF(AND(F18>0,H18>0),H18/F18,"") -> 422.65 | H18: =O18+V18+AC18+AJ18+AQ18+AX18 -> 845300 | I18: =P18+W18+AD18+AK18+AR18+AY18 -> 809800 | J18: =I18-H18 -> -35500 | K18: =IF(H18>0,J18/H18,"") -> -0.041996924 | L18: =IF(I$6=0,"",I18/I$6) -> 0.021461769 | M18: =SUMIFS(Gautam!$D$7:$D$300,Gautam!$B$7:$B$300,$B18) -> 0 | N18: =IF(AND(M18>0,O18>0),O18/M18,"") | O18: =SUMIFS(Gautam!$E$7:$E$300,Gautam!$B$7:$B$300,$B18) -> 0 | P18: =SUMIFS(Gautam!$H$7:$H$300,Gautam!$B$7:$B$300,$B18) -> 0 | Q18: =P18-O18 -> 0 | R18: =IF(O18>0,Q18/O18,"") | S18: =IF(P$6=0,"",P18/P$6) -> 0 | T18: =SUMIFS('Manish Shilpa'!$D$7:$D$300,'Manish Shilpa'!$B$7:$B$300,$B18) -> 0 | U18: =IF(AND(T18>0,V18>0),V18/T18,"") | V18: =SUMIFS('Manish Shilpa'!$E$7:$E$300,'Manish Shilpa'!$B$7:$B$300,$B18) -> 0 | W18: =SUMIFS('Manish Shilpa'!$H$7:$H$300,'Manish Shilpa'!$B$7:$B$300,$B18) -> 0 | X18: =W18-V18 -> 0 | Y18: =IF(V18>0,X18/V18,"") | Z18: =IF(W$6=0,"",W18/W$6) -> 0 | AA18: =SUMIFS('Saloni Mehra'!$D$7:$D$300,'Saloni Mehra'!$B$7:$B$300,$B18) -> 2000 | AB18: =IF(AND(AA18>0,AC18>0),AC18/AA18,"") -> 422.65 | AC18: =SUMIFS('Saloni Mehra'!$E$7:$E$300,'Saloni Mehra'!$B$7:$B$300,$B18) -> 845300 | AD18: =SUMIFS('Saloni Mehra'!$H$7:$H$300,'Saloni Mehra'!$B$7:$B$300,$B18) -> 809800 | AE18: =AD18-AC18 -> -35500 | AF18: =IF(AC18>0,AE18/AC18,"") -> -0.041996924 | AG18: =IF(AD$6=0,"",AD18/AD$6) -> 0.072513825 | AH18: =SUMIFS('Vidushi Malhotra'!$D$7:$D$300,'Vidushi Malhotra'!$B$7:$B$300,$B18) -> 0 | AI18: =IF(AND(AH18>0,AJ18>0),AJ18/AH18,"") | AJ18: =SUMIFS('Vidushi Malhotra'!$E$7:$E$300,'Vidushi Malhotra'!$B$7:$B$300,$B18) -> 0 | AK18: =SUMIFS('Vidushi Malhotra'!$H$7:$H$300,'Vidushi Malhotra'!$B$7:$B$300,$B18) -> 0 | AL18: =AK18-AJ18 -> 0 | AM18: =IF(AJ18>0,AL18/AJ18,"") | AN18: =IF(AK$6=0,"",AK18/AK$6) -> 0 | AO18: =SUMIFS('Dr Umesh Choudhry'!$D$7:$D$300,'Dr Umesh Choudhry'!$B$7:$B$300,$B18) -> 0 | AP18: =IF(AND(AO18>0,AQ18>0),AQ18/AO18,"") | AQ18: =SUMIFS('Dr Umesh Choudhry'!$E$7:$E$300,'Dr Umesh Choudhry'!$B$7:$B$300,$B18) -> 0 | AR18: =SUMIFS('Dr Umesh Choudhry'!$H$7:$H$300,'Dr Umesh Choudhry'!$B$7:$B$300,$B18) -> 0 | AS18: =AR18-AQ18 -> 0 | AT18: =IF(AQ18>0,AS18/AQ18,"") | AU18: =IF(AR$6=0,"",AR18/AR$6) -> 0 | AV18: =SUMIFS(DA!$D$7:$D$300,DA!$B$7:$B$300,$B18) -> 0 | AW18: =IF(AND(AV18>0,AX18>0),AX18/AV18,"") | AX18: =SUMIFS(DA!$E$7:$E$300,DA!$B$7:$B$300,$B18) -> 0 | AY18: =SUMIFS(DA!$H$7:$H$300,DA!$B$7:$B$300,$B18) -> 0 | AZ18: =AY18-AX18 -> 0 | BA18: =IF(AX18>0,AZ18/AX18,"") | BB18: =IF(AY$6=0,"",AY18/AY$6) -> 0
... A95: 89 | B95: PSL Ltd (formerly PSL Holdings Ltd) | C95: =IFERROR(INDEX(Prices!$C$6:$C$300,MATCH($B95,Prices!$A$6:$A$300,0)),"") | D95: =IFERROR(INDEX(Prices!$D$6:$D$300,MATCH($B95,Prices!$A$6:$A$300,0)),"") -> No price on any statement | E95: =(M95>0)+(T95>0)+(AA95>0)+(AH95>0)+(AO95>0)+(AV95>0) -> 1 | F95: =M95+T95+AA95+AH95+AO95+AV95 -> 1000 | G95: =IF(AND(F95>0,H95>0),H95/F95,"") | H95: =O95+V95+AC95+AJ95+AQ95+AX95 -> 0 | I95: =P95+W95+AD95+AK95+AR95+AY95 -> 0 | J95: =I95-H95 -> 0 | K95: =IF(H95>0,J95/H95,"") | L95: =IF(I$6=0,"",I95/I$6) -> 0 | M95: =SUMIFS(Gautam!$D$7:$D$300,Gautam!$B$7:$B$300,$B95) -> 1000 | N95: =IF(AND(M95>0,O95>0),O95/M95,"") | O95: =SUMIFS(Gautam!$E$7:$E$300,Gautam!$B$7:$B$300,$B95) -> 0 | P95: =SUMIFS(Gautam!$H$7:$H$300,Gautam!$B$7:$B$300,$B95) -> 0 | Q95: =P95-O95 -> 0 | R95: =IF(O95>0,Q95/O95,"") | S95: =IF(P$6=0,"",P95/P$6) -> 0 | T95: =SUMIFS('Manish Shilpa'!$D$7:$D$300,'Manish Shilpa'!$B$7:$B$300,$B95) -> 0 | U95: =IF(AND(T95>0,V95>0),V95/T95,"") | V95: =SUMIFS('Manish Shilpa'!$E$7:$E$300,'Manish Shilpa'!$B$7:$B$300,$B95) -> 0 | W95: =SUMIFS('Manish Shilpa'!$H$7:$H$300,'Manish Shilpa'!$B$7:$B$300,$B95) -> 0 | X95: =W95-V95 -> 0 | Y95: =IF(V95>0,X95/V95,"") | Z95: =IF(W$6=0,"",W95/W$6) -> 0 | AA95: =SUMIFS('Saloni Mehra'!$D$7:$D$300,'Saloni Mehra'!$B$7:$B$300,$B95) -> 0 | AB95: =IF(AND(AA95>0,AC95>0),AC95/AA95,"") | AC95: =SUMIFS('Saloni Mehra'!$E$7:$E$300,'Saloni Mehra'!$B$7:$B$300,$B95) -> 0 | AD95: =SUMIFS('Saloni Mehra'!$H$7:$H$300,'Saloni Mehra'!$B$7:$B$300,$B95) -> 0 | AE95: =AD95-AC95 -> 0 | AF95: =IF(AC95>0,AE95/AC95,"") | AG95: =IF(AD$6=0,"",AD95/AD$6) -> 0 | AH95: =SUMIFS('Vidushi Malhotra'!$D$7:$D$300,'Vidushi Malhotra'!$B$7:$B$300,$B95) -> 0 | AI95: =IF(AND(AH95>0,AJ95>0),AJ95/AH95,"") | AJ95: =SUMIFS('Vidushi Malhotra'!$E$7:$E$300,'Vidushi Malhotra'!$B$7:$B$300,$B95) -> 0 | AK95: =SUMIFS('Vidushi Malhotra'!$H$7:$H$300,'Vidushi Malhotra'!$B$7:$B$300,$B95) -> 0 | AL95: =AK95-AJ95 -> 0 | AM95: =IF(AJ95>0,AL95/AJ95,"") | AN95: =IF(AK$6=0,"",AK95/AK$6) -> 0 | AO95: =SUMIFS('Dr Umesh Choudhry'!$D$7:$D$300,'Dr Umesh Choudhry'!$B$7:$B$300,$B95) -> 0 | AP95: =IF(AND(AO95>0,AQ95>0),AQ95/AO95,"") | AQ95: =SUMIFS('Dr Umesh Choudhry'!$E$7:$E$300,'Dr Umesh Choudhry'!$B$7:$B$300,$B95) -> 0 | AR95: =SUMIFS('Dr Umesh Choudhry'!$H$7:$H$300,'Dr Umesh Choudhry'!$B$7:$B$300,$B95) -> 0 | AS95: =AR95-AQ95 -> 0 | AT95: =IF(AQ95>0,AS95/AQ95,"") | AU95: =IF(AR$6=0,"",AR95/AR$6) -> 0 | AV95: =SUMIFS(DA!$D$7:$D$300,DA!$B$7:$B$300,$B95) -> 0 | AW95: =IF(AND(AV95>0,AX95>0),AX95/AV95,"") | AX95: =SUMIFS(DA!$E$7:$E$300,DA!$B$7:$B$300,$B95) -> 0 | AY95: =SUMIFS(DA!$H$7:$H$300,DA!$B$7:$B$300,$B95) -> 0 | AZ95: =AY95-AX95 -> 0 | BA95: =IF(AX95>0,AZ95/AX95,"") | BB95: =IF(AY$6=0,"",AY95/AY$6) -> 0

Sheet Prices
A1: COMMON PRICE SHEET
A2: One price per security, used to value every portfolio. Without an exchange close, the statement price is used, freshest statement first: Gautam stmt – 23.10 → Manish Shilpa stmt – live 23.10 → Saloni stmt – 20.10 (stale) → Vidushi stmt – LTP 05.10 → Umesh stmt – NSE live 09.10 → DA stmt – older (stale).
A3: Column B holds NSE/BSE closes for 22.10.2026 (Screener.in). TO UPDATE: overwrite the yellow column B and the source text beside it — every portfolio and the combined view revalue. Blank B = statement price.
A5: Security | B5: Override Price (₹) ← type here | C5: Ref Price (₹) (used everywhere) | D5: Price Basis | E5: Gautam stmt (₹) | F5: Manish Shilpa stmt (₹) | G5: Saloni Mehra stmt (₹) | H5: Vidushi Malhotra stmt (₹) | I5: Dr Umesh Choudhry stmt (₹) | J5: DA stmt (₹) | K5: Override source | L5: Prev close 21.10 (₹) | M5: 1-day chg %
