Workbook

Sheet Summary
A1: CONSOLIDATED PORTFOLIO SUMMARY – ALL MANAGED ACCOUNTS
A2: Built 09.10.2026 from 4 statements. All market values at NSE/BSE close of 08.10.2026 (Prices sheet); statement-reported values kept alongside for reconciliation.
A5: Portfolio | B5: Broker | C5: Holdings as of | D5: Statement price basis | E5: # Holdings | F5: Invested (₹) | G5: Market Value (₹) | H5: Unrealised P&L (₹) | I5: P&L % | J5: Share of Combined MV | K5: Stmt Invested (₹) | L5: Stmt Market Value (₹) | M5: Repricing Impact (₹)
A6: Vidushi Malhotra | B6: Zerodha | C6: 04.10.2026 (+ trades of 05.10.2026) | D6: LTP 05.10.2026 | E6: =COUNTIFS('Vidushi Malhotra'!$D$7:$D$300,">0",'Vidushi Malhotra'!$B$7:$B$300,"<>Cash*") -> 12 | F6: ='Vidushi Malhotra'!E6 -> 201361 | G6: ='Vidushi Malhotra'!H6 -> 225002.24 | H6: =G6-F6 -> 23641.24 | I6: =IF(F6>0,H6/F6,"") -> 0.11740724 | J6: =IF($G$10=0,"",G6/$G$10) -> 0.015841766 | K6: 201361 | L6: 230319 | M6: =G6-L6 -> -5316.76
A7: Dr Umesh Choudhry | B7: ICICI Direct | C7: 04.10.2026 + trades of 09.10.2026 | D7: NSE live 09.10.2026 ~09:45 IST | E7: =COUNTIFS('Dr Umesh Choudhry'!$D$7:$D$300,">0",'Dr Umesh Choudhry'!$B$7:$B$300,"<>Cash*") -> 20 | F7: ='Dr Umesh Choudhry'!E6 -> 5222229 | G7: ='Dr Umesh Choudhry'!H6 -> 5427487 | H7: =G7-F7 -> 205257.97 | I7: =IF(F7>0,H7/F7,"") -> 0.039304667 | J7: =IF($G$10=0,"",G7/$G$10) -> 0.38213389 | K7: 5222229 | L7: 5467267.2 | M7: =G7-L7 -> -39780.26
A8: Gautam | B8: HDFC Securities | C8: 05.10.2026 | D8: 05.10.2026 | E8: =COUNTIFS(Gautam!$D$7:$D$300,">0",Gautam!$B$7:$B$300,"<>Cash*") -> 32 | F8: =Gautam!E6 -> 5000486 | G8: =Gautam!H6 -> 4672678.1 | H8: =G8-F8 -> -327807.88 | I8: =IF(F8>0,H8/F8,"") -> -0.065555204 | J8: =IF($G$10=0,"",G8/$G$10) -> 0.32898995 | K8: 5000484.7 | L8: 4762080 | M8: =G8-L8 -> -89401.88
A9: DA | B9: HDFC Securities + Kotak Securities | C9: Post 12.09.2026 trades (file dated 04.10.2026) | D9: As on statement (date not printed) | E9: =COUNTIFS(DA!$D$7:$D$300,">0",DA!$B$7:$B$300,"<>Cash*") -> 53 | F9: =DA!E6 -> 4364996 | G9: =DA!H6 -> 3877935.6 | H9: =G9-F9 -> -487060.36 | I9: =IF(F9>0,H9/F9,"") -> -0.11158323 | J9: =IF($G$10=0,"",G9/$G$10) -> 0.2730344 | K9: 4364995 | L9: 4141021 | M9: =G9-L9 -> -263085.36
A10: COMBINED (ALL 4) | B10: Zerodha + ICICI Direct + HDFC Securities + HDFC Securities + Kotak Securities | E10: ='Side by Side'!E6 -> 66 | F10: =SUM(F6:F9) -> 14789072 | G10: =SUM(G6:G9) -> 14203103 | H10: =SUM(H6:H9) -> -585969.03 | I10: =IF(F10>0,H10/F10,"") -> -0.039621758 | J10: =SUM(J6:J9) -> 1 | K10: =SUM(K6:K9) -> 14789070 | L10: =SUM(L6:L9) -> 14600687 | M10: =SUM(M6:M9) -> -397584.26
L11: Statement totals as printed on each statement (inputs).
A13: TOP 10 COMBINED EXPOSURES – weight in each portfolio
A14: Rank | B14: Security | C14: Combined MV (₹) | D14: Combined Weight | E14: Vidushi Malhotra | F14: Dr Umesh Choudhry | G14: Gautam | H14: DA | I14: Held in (# a/cs)
A15: 1 | B15: =INDEX('Side by Side'!$B$7:$B$73,MATCH(C15,'Side by Side'!$I$7:$I$73,0)) -> Bajaj Finance Ltd | C15: =LARGE('Side by Side'!$I$7:$I$73,A15) -> 4886816.4 | D15: =INDEX('Side by Side'!$L$7:$L$73,MATCH(C15,'Side by Side'!$I$7:$I$73,0)) -> 0.34406681 | E15: =INDEX('Side by Side'!$S$7:$S$73,MATCH(C15,'Side by Side'!$I$7:$I$73,0)) -> 0.51408355 | F15: =INDEX('Side by Side'!$Z$7:$Z$73,MATCH(C15,'Side by Side'!$I$7:$I$73,0)) -> 0.42482855 | G15: =INDEX('Side by Side'!$AG$7:$AG$73,MATCH(C15,'Side by Side'!$I$7:$I$73,0)) -> 0.34042593 | H15: =INDEX('Side by Side'!$AN$7:$AN$73,MATCH(C15,'Side by Side'!$I$7:$I$73,0)) -> 0.22555667 | I15: =INDEX('Side by Side'!$E$7:$E$73,MATCH(C15,'Side by Side'!$I$7:$I$73,0)) -> 4
A16: 2 | B16: =INDEX('Side by Side'!$B$7:$B$73,MATCH(C16,'Side by Side'!$I$7:$I$73,0)) -> Titan Company Ltd | C16: =LARGE('Side by Side'!$I$7:$I$73,A16) -> 1225019.5 | D16: =INDEX('Side by Side'!$L$7:$L$73,MATCH(C16,'Side by Side'!$I$7:$I$73,0)) -> 0.086250132 | E16: =INDEX('Side by Side'!$S$7:$S$73,MATCH(C16,'Side by Side'!$I$7:$I$73,0)) -> 0.17437826 | F16: =INDEX('Side by Side'!$Z$7:$Z$73,MATCH(C16,'Side by Side'!$I$7:$I$73,0)) -> 0.13815491 | G16: =INDEX('Side by Side'!$AG$7:$AG$73,MATCH(C16,'Side by Side'!$I$7:$I$73,0)) -> 0.038252046 | H16: =INDEX('Side by Side'!$AN$7:$AN$73,MATCH(C16,'Side by Side'!$I$7:$I$73,0)) -> 0.066326655 | I16: =INDEX('Side by Side'!$E$7:$E$73,MATCH(C16,'Side by Side'!$I$7:$I$73,0)) -> 4
A17: 3 | B17: =INDEX('Side by Side'!$B$7:$B$73,MATCH(C17,'Side by Side'!$I$7:$I$73,0)) -> Poonawalla Fincorp Ltd | C17: =LARGE('Side by Side'!$I$7:$I$73,A17) -> 1138540 | D17: =INDEX('Side by Side'!$L$7:$L$73,MATCH(C17,'Side by Side'!$I$7:$I$73,0)) -> 0.080161356 | E17: =INDEX('Side by Side'!$S$7:$S$73,MATCH(C17,'Side by Side'!$I$7:$I$73,0)) -> 0.073955708 | F17: =INDEX('Side by Side'!$Z$7:$Z$73,MATCH(C17,'Side by Side'!$I$7:$I$73,0)) -> 0.062044387 | G17: =INDEX('Side by Side'!$AG$7:$AG$73,MATCH(C17,'Side by Side'!$I$7:$I$73,0)) -> 0.093808709 | H17: =INDEX('Side by Side'!$AN$7:$AN$73,MATCH(C17,'Side by Side'!$I$7:$I$73,0)) -> 0.089433356 | I17: =INDEX('Side by Side'!$E$7:$E$73,MATCH(C17,'Side by Side'!$I$7:$I$73,0)) -> 4
A18: 4 | B18: =INDEX('Side by Side'!$B$7:$B$73,MATCH(C18,'Side by Side'!$I$7:$I$73,0)) -> HDFC Bank Ltd | C18: =LARGE('Side by Side'!$I$7:$I$73,A18) -> 983687.25 | D18: =INDEX('Side by Side'!$L$7:$L$73,MATCH(C18,'Side by Side'!$I$7:$I$73,0)) -> 0.069258616 | E18: =INDEX('Side by Side'!$S$7:$S$73,MATCH(C18,'Side by Side'!$I$7:$I$73,0)) -> 0.064609357 | F18: =INDEX('Side by Side'!$Z$7:$Z$73,MATCH(C18,'Side by Side'!$I$7:$I$73,0)) -> 0.085837931 | G18: =INDEX('Side by Side'!$AG$7:$AG$73,MATCH(C18,'Side by Side'!$I$7:$I$73,0)) -> 0.057777894 | H18: =INDEX('Side by Side'!$AN$7:$AN$73,MATCH(C18,'Side by Side'!$I$7:$I$73,0)) -> 0.060157845 | I18: =INDEX('Side by Side'!$E$7:$E$73,MATCH(C18,'Side by Side'!$I$7:$I$73,0)) -> 4
A19: 5 | B19: =INDEX('Side by Side'!$B$7:$B$73,MATCH(C19,'Side by Side'!$I$7:$I$73,0)) -> AFCOM Holdings Ltd | C19: =LARGE('Side by Side'!$I$7:$I$73,A19) -> 687384 | D19: =INDEX('Side by Side'!$L$7:$L$73,MATCH(C19,'Side by Side'!$I$7:$I$73,0)) -> 0.048396748 | E19: =INDEX('Side by Side'!$S$7:$S$73,MATCH(C19,'Side by Side'!$I$7:$I$73,0)) -> 0 | F19: =INDEX('Side by Side'!$Z$7:$Z$73,MATCH(C19,'Side by Side'!$I$7:$I$73,0)) -> 0.063324334 | G19: =INDEX('Side by Side'!$AG$7:$AG$73,MATCH(C19,'Side by Side'!$I$7:$I$73,0)) -> 0.036776768 | H19: =INDEX('Side by Side'!$AN$7:$AN$73,MATCH(C19,'Side by Side'!$I$7:$I$73,0)) -> 0.044313783 | I19: =INDEX('Side by Side'!$E$7:$E$73,MATCH(C19,'Side by Side'!$I$7:$I$73,0)) -> 3
A20: 6 | B20: =INDEX('Side by Side'!$B$7:$B$73,MATCH(C20,'Side by Side'!$I$7:$I$73,0)) -> Connplex Cinemas Ltd | C20: =LARGE('Side by Side'!$I$7:$I$73,A20) -> 588000 | D20: =INDEX('Side by Side'!$L$7:$L$73,MATCH(C20,'Side by Side'!$I$7:$I$73,0)) -> 0.041399404 | E20: =INDEX('Side by Side'!$S$7:$S$73,MATCH(C20,'Side by Side'!$I$7:$I$73,0)) -> 0 | F20: =INDEX('Side by Side'!$Z$7:$Z$73,MATCH(C20,'Side by Side'!$I$7:$I$73,0)) -> 0.036112477 | G20: =INDEX('Side by Side'!$AG$7:$AG$73,MATCH(C20,'Side by Side'!$I$7:$I$73,0)) -> 0.041945967 | H20: =INDEX('Side by Side'!$AN$7:$AN$73,MATCH(C20,'Side by Side'!$I$7:$I$73,0)) -> 0.050542355 | I20: =INDEX('Side by Side'!$E$7:$E$73,MATCH(C20,'Side by Side'!$I$7:$I$73,0)) -> 3
A21: 7 | B21: =INDEX('Side by Side'!$B$7:$B$73,MATCH(C21,'Side by Side'!$I$7:$I$73,0)) -> Bajaj Housing Finance Ltd | C21: =LARGE('Side by Side'!$I$7:$I$73,A21) -> 441666.78 | D21: =INDEX('Side by Side'!$L$7:$L$73,MATCH(C21,'Side by Side'!$I$7:$I$73,0)) -> 0.031096499 | E21: =INDEX('Side by Side'!$S$7:$S$73,MATCH(C21,'Side by Side'!$I$7:$I$73,0)) -> 0.044172627 | F21: =INDEX('Side by Side'!$Z$7:$Z$73,MATCH(C21,'Side by Side'!$I$7:$I$73,0)) -> 0.033264699 | G21: =INDEX('Side by Side'!$AG$7:$AG$73,MATCH(C21,'Side by Side'!$I$7:$I$73,0)) -> 0.023309468 | H21: =INDEX('Side by Side'!$AN$7:$AN$73,MATCH(C21,'Side by Side'!$I$7:$I$73,0)) -> 0.036686137 | I21: =INDEX('Side by Side'!$E$7:$E$73,MATCH(C21,'Side by Side'!$I$7:$I$73,0)) -> 4
A22: 8 | B22: =INDEX('Side by Side'!$B$7:$B$73,MATCH(C22,'Side by Side'!$I$7:$I$73,0)) -> LTM Ltd (formerly LTIMindtree) | C22: =LARGE('Side by Side'!$I$7:$I$73,A22) -> 407160 | D22: =INDEX('Side by Side'!$L$7:$L$73,MATCH(C22,'Side by Side'!$I$7:$I$73,0)) -> 0.028666975 | E22: =INDEX('Side by Side'!$S$7:$S$73,MATCH(C22,'Side by Side'!$I$7:$I$73,0)) -> 0.034799654 | F22: =INDEX('Side by Side'!$Z$7:$Z$73,MATCH(C22,'Side by Side'!$I$7:$I$73,0)) -> 0.026689147 | G22: =INDEX('Side by Side'!$AG$7:$AG$73,MATCH(C22,'Side by Side'!$I$7:$I$73,0)) -> 0.050270957 | H22: =INDEX('Side by Side'!$AN$7:$AN$73,MATCH(C22,'Side by Side'!$I$7:$I$73,0)) -> 0.0050477888 | I22: =INDEX('Side by Side'!$E$7:$E$73,MATCH(C22,'Side by Side'!$I$7:$I$73,0)) -> 4
A23: 9 | B23: =INDEX('Side by Side'!$B$7:$B$73,MATCH(C23,'Side by Side'!$I$7:$I$73,0)) -> Nippon India ETF Nifty 1D Rate Liquid BeES | C23: =LARGE('Side by Side'!$I$7:$I$73,A23) -> 300000 | D23: =INDEX('Side by Side'!$L$7:$L$73,MATCH(C23,'Side by Side'!$I$7:$I$73,0)) -> 0.021122145 | E23: =INDEX('Side by Side'!$S$7:$S$73,MATCH(C23,'Side by Side'!$I$7:$I$73,0)) -> 0 | F23: =INDEX('Side by Side'!$Z$7:$Z$73,MATCH(C23,'Side by Side'!$I$7:$I$73,0)) -> 0 | G23: =INDEX('Side by Side'!$AG$7:$AG$73,MATCH(C23,'Side by Side'!$I$7:$I$73,0)) -> 0.06420301 | H23: =INDEX('Side by Side'!$AN$7:$AN$73,MATCH(C23,'Side by Side'!$I$7:$I$73,0)) -> 0 | I23: =INDEX('Side by Side'!$E$7:$E$73,MATCH(C23,'Side by Side'!$I$7:$I$73,0)) -> 1
A24: 10 | B24: =INDEX('Side by Side'!$B$7:$B$73,MATCH(C24,'Side by Side'!$I$7:$I$73,0)) -> Fineotex Chemical Ltd | C24: =LARGE('Side by Side'!$I$7:$I$73,A24) -> 287900.58 | D24: =INDEX('Side by Side'!$L$7:$L$73,MATCH(C24,'Side by Side'!$I$7:$I$73,0)) -> 0.020270259 | E24: =INDEX('Side by Side'!$S$7:$S$73,MATCH(C24,'Side by Side'!$I$7:$I$73,0)) -> 0.012442098 | F24: =INDEX('Side by Side'!$Z$7:$Z$73,MATCH(C24,'Side by Side'!$I$7:$I$73,0)) -> 0.024448939 | G24: =INDEX('Side by Side'!$AG$7:$AG$73,MATCH(C24,'Side by Side'!$I$7:$I$73,0)) -> 0.0082918359 | H24: =INDEX('Side by Side'!$AN$7:$AN$73,MATCH(C24,'Side by Side'!$I$7:$I$73,0)) -> 0.029309331 | I24: =INDEX('Side by Side'!$E$7:$E$73,MATCH(C24,'Side by Side'!$I$7:$I$73,0)) -> 4
A27: NOTES & FLAGS
A28: • Pricing: every holding is valued at the NSE/BSE close of 08.10.2026 (Screener.in daily price series), one price per security across all accounts. 'Repricing Impact' = workbook value minus each statement's own market value.
A29: ="• Securities on an exchange close: "&COUNTIF(Prices!$I$6:$I$300,"Close*")&" | on a statement price: "&COUNTIF(Prices!$I$6:$I$300,"No exchange*")&" | held in all 4 accounts: "&COUNTIF('Side by Side'!$E$7:$E$73,4) -> • Securities on an exchange close: 59 | on a statement price: 7 | held in all 4 accounts: 9
A30: • No exchange close for the 4 ETFs (Nifty 50 BeES, Gold BeES, Liquid BeES, HDFC Gold ETF), the Utkarsh SFB rights entitlement, NEPC Agro and PSL Ltd – these stay at statement price (Liquid BeES holds near ₹1,000).
A31: • Gautam: NEPC Agro Foods (144 sh) and PSL Ltd (1,000 sh) have no cost or price on the statement – shown with quantity, carried at nil value.
A32: • Names aligned across statements: LTM Ltd = LTIMindtree (DA); Connplex Cinemas = Connplex Smart Theatres (DA); AFCOM = Afcom Holdings.
A33: • Trades blended into holdings and listed on each tab: Vidushi 05.10.2026 (3 buys, ₹9,889); Dr Umesh 09.10.2026 (13 buys, ₹5.01 L, incl. new Eicher Motors and Rategain).
A34: • Dr Umesh holds ₹36,000 uninvested cash at ICICI Direct – row 'Cash – ICICI Direct' at ₹1 per unit, counted in totals but not as a holding.
A35: • Statement invested/market totals reconcile to transcribed rows within ₹2 (rupee rounding on the statements).

Sheet Side by Side
A1: SIDE-BY-SIDE HOLDINGS – COMBINED AND BY PORTFOLIO
A2: All values at the common Ref Price (Prices sheet). Sorted by combined market value at build; '-' = not held. Amber price = only a stale statement price available.
F4: COMBINED (ALL 4) | M4: VIDUSHI MALHOTRA – Zerodha | T4: DR UMESH CHOUDHRY – ICICI Direct | AA4: GAUTAM – HDFC Securities | AH4: DA – HDFC Securities + Kotak Securities
A5: # | B5: Security | C5: Ref Price (₹) | D5: Price Basis | E5: Held in (# a/cs) | F5: Qty | G5: Wtd Avg Cost (₹) | H5: Invested (₹) | I5: Mkt Value (₹) | J5: P&L (₹) | K5: P&L % | L5: Weight % | M5: Qty | N5: Wtd Avg Cost (₹) | O5: Invested (₹) | P5: Mkt Value (₹) | Q5: P&L (₹) | R5: P&L % | S5: Weight % | T5: Qty | U5: Wtd Avg Cost (₹) | V5: Invested (₹) | W5: Mkt Value (₹) | X5: P&L (₹) | Y5: P&L % | Z5: Weight % | AA5: Qty | AB5: Wtd Avg Cost (₹) | AC5: Invested (₹) | AD5: Mkt Value (₹) | AE5: P&L (₹) | AF5: P&L % | AG5: Weight % | AH5: Qty | AI5: Wtd Avg Cost (₹) | AJ5: Invested (₹) | AK5: Mkt Value (₹) | AL5: P&L (₹) | AM5: P&L % | AN5: Weight %
B6: TOTAL | E6: =COUNTIFS(E7:E73,">0",B7:B73,"<>Cash*") -> 66 | F6: =COUNTIFS(F7:F73,">0",$B7:$B73,"<>Cash*") -> 66 | H6: =SUM(H7:H73) -> 14789072 | I6: =SUM(I7:I73) -> 14203103 | J6: =I6-H6 -> -585969.03 | K6: =IF(H6>0,J6/H6,"") -> -0.039621758 | L6: =SUM(L7:L73) -> 1 | M6: =COUNTIFS(M7:M73,">0",$B7:$B73,"<>Cash*") -> 12 | O6: =SUM(O7:O73) -> 201361 | P6: =SUM(P7:P73) -> 225002.24 | Q6: =P6-O6 -> 23641.24 | R6: =IF(O6>0,Q6/O6,"") -> 0.11740724 | S6: =SUM(S7:S73) -> 1 | T6: =COUNTIFS(T7:T73,">0",$B7:$B73,"<>Cash*") -> 20 | V6: =SUM(V7:V73) -> 5222229 | W6: =SUM(W7:W73) -> 5427487 | X6: =W6-V6 -> 205257.97 | Y6: =IF(V6>0,X6/V6,"") -> 0.039304667 | Z6: =SUM(Z7:Z73) -> 1 | AA6: =COUNTIFS(AA7:AA73,">0",$B7:$B73,"<>Cash*") -> 32 | AC6: =SUM(AC7:AC73) -> 5000486 | AD6: =SUM(AD7:AD73) -> 4672678.1 | AE6: =AD6-AC6 -> -327807.88 | AF6: =IF(AC6>0,AE6/AC6,"") -> -0.065555204 | AG6: =SUM(AG7:AG73) -> 1 | AH6: =COUNTIFS(AH7:AH73,">0",$B7:$B73,"<>Cash*") -> 53 | AJ6: =SUM(AJ7:AJ73) -> 4364996 | AK6: =SUM(AK7:AK73) -> 3877935.6 | AL6: =AK6-AJ6 -> -487060.36 | AM6: =IF(AJ6>0,AL6/AJ6,"") -> -0.11158323 | AN6: =SUM(AN7:AN73) -> 1
A7: 1 | B7: Bajaj Finance Ltd | C7: =IFERROR(INDEX(Prices!$C$6:$C$300,MATCH($B7,Prices!$A$6:$A$300,0)),"") -> 955.95 | D7: =IFERROR(INDEX(Prices!$D$6:$D$300,MATCH($B7,Prices!$A$6:$A$300,0)),"") -> Close 08.10.2026 (Screener.in) | E7: =(M7>0)+(T7>0)+(AA7>0)+(AH7>0) -> 4 | F7: =M7+T7+AA7+AH7 -> 5112 | G7: =IF(AND(F7>0,H7>0),H7/F7,"") -> 915.22966 | H7: =O7+V7+AC7+AJ7 -> 4678654 | I7: =P7+W7+AD7+AK7 -> 4886816.4 | J7: =I7-H7 -> 208162.4 | K7: =IF(H7>0,J7/H7,"") -> 0.044491941 | L7: =IF(I$6=0,"",I7/I$6) -> 0.34406681 | M7: =SUMIFS('Vidushi Malhotra'!$D$7:$D$300,'Vidushi Malhotra'!$B$7:$B$300,$B7) -> 121 | N7: =IF(AND(M7>0,O7>0),O7/M7,"") -> 768 | O7: =SUMIFS('Vidushi Malhotra'!$E$7:$E$300,'Vidushi Malhotra'!$B$7:$B$300,$B7) -> 92928 | P7: =SUMIFS('Vidushi Malhotra'!$H$7:$H$300,'Vidushi Malhotra'!$B$7:$B$300,$B7) -> 115669.95 | Q7: =P7-O7 -> 22741.95 | R7: =IF(O7>0,Q7/O7,"") -> 0.24472656 | S7: =IF(P$6=0,"",P7/P$6) -> 0.51408355 | T7: =SUMIFS('Dr Umesh Choudhry'!$D$7:$D$300,'Dr Umesh Choudhry'!$B$7:$B$300,$B7) -> 2412 | U7: =IF(AND(T7>0,V7>0),V7/T7,"") -> 800.28441 | V7: =SUMIFS('Dr Umesh Choudhry'!$E$7:$E$300,'Dr Umesh Choudhry'!$B$7:$B$300,$B7) -> 1930286 | W7: =SUMIFS('Dr Umesh Choudhry'!$H$7:$H$300,'Dr Umesh Choudhry'!$B$7:$B$300,$B7) -> 2305751.4 | X7: =W7-V7 -> 375465.4 | Y7: =IF(V7>0,X7/V7,"") -> 0.19451283 | Z7: =IF(W$6=0,"",W7/W$6) -> 0.42482855 | AA7: =SUMIFS(Gautam!$D$7:$D$300,Gautam!$B$7:$B$300,$B7) -> 1664 | AB7: =IF(AND(AA7>0,AC7>0),AC7/AA7,"") -> 1016.4201 | AC7: =SUMIFS(Gautam!$E$7:$E$300,Gautam!$B$7:$B$300,$B7) -> 1691323 | AD7: =SUMIFS(Gautam!$H$7:$H$300,Gautam!$B$7:$B$300,$B7) -> 1590700.8 | AE7: =AD7-AC7 -> -100622.2 | AF7: =IF(AC7>0,AE7/AC7,"") -> -0.05949319 | AG7: =IF(AD$6=0,"",AD7/AD$6) -> 0.34042593 | AH7: =SUMIFS(DA!$D$7:$D$300,DA!$B$7:$B$300,$B7) -> 915 | AI7: =IF(AND(AH7>0,AJ7>0),AJ7/AH7,"") -> 1053.6798 | AJ7: =SUMIFS(DA!$E$7:$E$300,DA!$B$7:$B$300,$B7) -> 964117 | AK7: =SUMIFS(DA!$H$7:$H$300,DA!$B$7:$B$300,$B7) -> 874694.25 | AL7: =AK7-AJ7 -> -89422.75 | AM7: =IF(AJ7>0,AL7/AJ7,"") -> -0.092750932 | AN7: =IF(AK$6=0,"",AK7/AK$6) -> 0.22555667
A8: 2 | B8: Titan Company Ltd | C8: =IFERROR(INDEX(Prices!$C$6:$C$300,MATCH($B8,Prices!$A$6:$A$300,0)),"") -> 4359.5 | D8: =IFERROR(INDEX(Prices!$D$6:$D$300,MATCH($B8,Prices!$A$6:$A$300,0)),"") -> Close 08.10.2026 (Screener.in) | E8: =(M8>0)+(T8>0)+(AA8>0)+(AH8>0) -> 4 | F8: =M8+T8+AA8+AH8 -> 281 | G8: =IF(AND(F8>0,H8>0),H8/F8,"") -> 3928.2028 | H8: =O8+V8+AC8+AJ8 -> 1103825 | I8: =P8+W8+AD8+AK8 -> 1225019.5 | J8: =I8-H8 -> 121194.5 | K8: =IF(H8>0,J8/H8,"") -> 0.10979503 | L8: =IF(I$6=0,"",I8/I$6) -> 0.086250132 | M8: =SUMIFS('Vidushi Malhotra'!$D$7:$D$300,'Vidushi Malhotra'!$B$7:$B$300,$B8) -> 9 | N8: =IF(AND(M8>0,O8>0),O8/M8,"") -> 3160.1111 | O8: =SUMIFS('Vidushi Malhotra'!$E$7:$E$300,'Vidushi Malhotra'!$B$7:$B$300,$B8) -> 28441 | P8: =SUMIFS('Vidushi Malhotra'!$H$7:$H$300,'Vidushi Malhotra'!$B$7:$B$300,$B8) -> 39235.5 | Q8: =P8-O8 -> 10794.5 | R8: =IF(O8>0,Q8/O8,"") -> 0.3795401 | S8: =IF(P$6=0,"",P8/P$6) -> 0.17437826 | T8: =SUMIFS('Dr Umesh Choudhry'!$D$7:$D$300,'Dr Umesh Choudhry'!$B$7:$B$300,$B8) -> 172 | U8: =IF(AND(T8>0,V8>0),V8/T8,"") -> 3589.9244 | V8: =SUMIFS('Dr Umesh Choudhry'!$E$7:$E$300,'Dr Umesh Choudhry'!$B$7:$B$300,$B8) -> 617467 | W8: =SUMIFS('Dr Umesh Choudhry'!$H$7:$H$300,'Dr Umesh Choudhry'!$B$7:$B$300,$B8) -> 749834 | X8: =W8-V8 -> 132367 | Y8: =IF(V8>0,X8/V8,"") -> 0.21437097 | Z8: =IF(W$6=0,"",W8/W$6) -> 0.13815491 | AA8: =SUMIFS(Gautam!$D$7:$D$300,Gautam!$B$7:$B$300,$B8) -> 41 | AB8: =IF(AND(AA8>0,AC8>0),AC8/AA8,"") -> 4824.4878 | AC8: =SUMIFS(Gautam!$E$7:$E$300,Gautam!$B$7:$B$300,$B8) -> 197804 | AD8: =SUMIFS(Gautam!$H$7:$H$300,Gautam!$B$7:$B$300,$B8) -> 178739.5 | AE8: =AD8-AC8 -> -19064.5 | AF8: =IF(AC8>0,AE8/AC8,"") -> -0.096380761 | AG8: =IF(AD$6=0,"",AD8/AD$6) -> 0.038252046 | AH8: =SUMIFS(DA!$D$7:$D$300,DA!$B$7:$B$300,$B8) -> 59 | AI8: =IF(AND(AH8>0,AJ8>0),AJ8/AH8,"") -> 4408.6949 | AJ8: =SUMIFS(DA!$E$7:$E$300,DA!$B$7:$B$300,$B8) -> 260113 | AK8: =SUMIFS(DA!$H$7:$H$300,DA!$B$7:$B$300,$B8) -> 257210.5 | AL8: =AK8-AJ8 -> -2902.5 | AM8: =IF(AJ8>0,AL8/AJ8,"") -> -0.011158612 | AN8: =IF(AK$6=0,"",AK8/AK$6) -> 0.066326655
A9: 3 | B9: Poonawalla Fincorp Ltd | C9: =IFERROR(INDEX(Prices!$C$6:$C$300,MATCH($B9,Prices!$A$6:$A$300,0)),"") -> 437.9 | D9: =IFERROR(INDEX(Prices!$D$6:$D$300,MATCH($B9,Prices!$A$6:$A$300,0)),"") -> Close 08.10.2026 (Screener.in) | E9: =(M9>0)+(T9>0)+(AA9>0)+(AH9>0) -> 4 | F9: =M9+T9+AA9+AH9 -> 2600 | G9: =IF(AND(F9>0,H9>0),H9/F9,"") -> 465.84038 | H9: =O9+V9+AC9+AJ9 -> 1211185 | I9: =P9+W9+AD9+AK9 -> 1138540 | J9: =I9-H9 -> -72645 | K9: =IF(H9>0,J9/H9,"") -> -0.059978451 | L9: =IF(I$6=0,"",I9/I$6) -> 0.080161356 | M9: =SUMIFS('Vidushi Malhotra'!$D$7:$D$300,'Vidushi Malhotra'!$B$7:$B$300,$B9) -> 38 | N9: =IF(AND(M9>0,O9>0),O9/M9,"") -> 452.42105 | O9: =SUMIFS('Vidushi Malhotra'!$E$7:$E$300,'Vidushi Malhotra'!$B$7:$B$300,$B9) -> 17192 | P9: =SUMIFS('Vidushi Malhotra'!$H$7:$H$300,'Vidushi Malhotra'!$B$7:$B$300,$B9) -> 16640.2 | Q9: =P9-O9 -> -551.8 | R9: =IF(O9>0,Q9/O9,"") -> -0.032096324 | S9: =IF(P$6=0,"",P9/P$6) -> 0.073955708 | T9: =SUMIFS('Dr Umesh Choudhry'!$D$7:$D$300,'Dr Umesh Choudhry'!$B$7:$B$300,$B9) -> 769 | U9: =IF(AND(T9>0,V9>0),V9/T9,"") -> 451.22237 | V9: =SUMIFS('Dr Umesh Choudhry'!$E$7:$E$300,'Dr Umesh Choudhry'!$B$7:$B$300,$B9) -> 346990 | W9: =SUMIFS('Dr Umesh Choudhry'!$H$7:$H$300,'Dr Umesh Choudhry'!$B$7:$B$300,$B9) -> 336745.1 | X9: =W9-V9 -> -10244.9 | Y9: =IF(V9>0,X9/V9,"") -> -0.029525058 | Z9: =IF(W$6=0,"",W9/W$6) -> 0.062044387 | AA9: =SUMIFS(Gautam!$D$7:$D$300,Gautam!$B$7:$B$300,$B9) -> 1001 | AB9: =IF(AND(AA9>0,AC9>0),AC9/AA9,"") -> 470 | AC9: =SUMIFS(Gautam!$E$7:$E$300,Gautam!$B$7:$B$300,$B9) -> 470470 | AD9: =SUMIFS(Gautam!$H$7:$H$300,Gautam!$B$7:$B$300,$B9) -> 438337.9 | AE9: =AD9-AC9 -> -32132.1 | AF9: =IF(AC9>0,AE9/AC9,"") -> -0.068297872 | AG9: =IF(AD$6=0,"",AD9/AD$6) -> 0.093808709 | AH9: =SUMIFS(DA!$D$7:$D$300,DA!$B$7:$B$300,$B9) -> 792 | AI9: =IF(AND(AH9>0,AJ9>0),AJ9/AH9,"") -> 475.42045 | AJ9: =SUMIFS(DA!$E$7:$E$300,DA!$B$7:$B$300,$B9) -> 376533 | AK9: =SUMIFS(DA!$H$7:$H$300,DA!$B$7:$B$300,$B9) -> 346816.8 | AL9: =AK9-AJ9 -> -29716.2 | AM9: =IF(AJ9>0,AL9/AJ9,"") -> -0.078920573 | AN9: =IF(AK$6=0,"",AK9/AK$6) -> 0.089433356
A10: 4 | B10: HDFC Bank Ltd | C10: =IFERROR(INDEX(Prices!$C$6:$C$300,MATCH($B10,Prices!$A$6:$A$300,0)),"") -> 692.25 | D10: =IFERROR(INDEX(Prices!$D$6:$D$300,MATCH($B10,Prices!$A$6:$A$300,0)),"") -> Close 08.10.2026 (Screener.in) | E10: =(M10>0)+(T10>0)+(AA10>0)+(AH10>0) -> 4 | F10: =M10+T10+AA10+AH10 -> 1421 | G10: =IF(AND(F10>0,H10>0),H10/F10,"") -> 807.55735 | H10: =O10+V10+AC10+AJ10 -> 1147539 | I10: =P10+W10+AD10+AK10 -> 983687.25 | J10: =I10-H10 -> -163851.75 | K10: =IF(H10>0,J10/H10,"") -> -0.14278534 | L10: =IF(I$6=0,"",I10/I$6) -> 0.069258616 | M10: =SUMIFS('Vidushi Malhotra'!$D$7:$D$300,'Vidushi Malhotra'!$B$7:$B$300,$B10) -> 21 | N10: =IF(AND(M10>0,O10>0),O10/M10,"") -> 790.38095 | O10: =SUMIFS('Vidushi Malhotra'!$E$7:$E$300,'Vidushi Malhotra'!$B$7:$B$300,$B10) -> 16598 | P10: =SUMIFS('Vidushi Malhotra'!$H$7:$H$300,'Vidushi Malhotra'!$B$7:$B$300,$B10) -> 14537.25 | Q10: =P10-O10 -> -2060.75 | R10: =IF(O10>0,Q10/O10,"") -> -0.12415652 | S10: =IF(P$6=0,"",P10/P$6) -> 0.064609357 | T10: =SUMIFS('Dr Umesh Choudhry'!$D$7:$D$300,'Dr Umesh Choudhry'!$B$7:$B$300,$B10) -> 673 | U10: =IF(AND(T10>0,V10>0),V10/T10,"") -> 890.65973 | V10: =SUMIFS('Dr Umesh Choudhry'!$E$7:$E$300,'Dr Umesh Choudhry'!$B$7:$B$300,$B10) -> 599414 | W10: =SUMIFS('Dr Umesh Choudhry'!$H$7:$H$300,'Dr Umesh Choudhry'!$B$7:$B$300,$B10) -> 465884.25 | X10: =W10-V10 -> -133529.75 | Y10: =IF(V10>0,X10/V10,"") -> -0.22276715 | Z10: =IF(W$6=0,"",W10/W$6) -> 0.085837931 | AA10: =SUMIFS(Gautam!$D$7:$D$300,Gautam!$B$7:$B$300,$B10) -> 390 | AB10: =IF(AND(AA10>0,AC10>0),AC10/AA10,"") -> 719.4 | AC10: =SUMIFS(Gautam!$E$7:$E$300,Gautam!$B$7:$B$300,$B10) -> 280566 | AD10: =SUMIFS(Gautam!$H$7:$H$300,Gautam!$B$7:$B$300,$B10) -> 269977.5 | AE10: =AD10-AC10 -> -10588.5 | AF10: =IF(AC10>0,AE10/AC10,"") -> -0.037739783 | AG10: =IF(AD$6=0,"",AD10/AD$6) -> 0.057777894 | AH10: =SUMIFS(DA!$D$7:$D$300,DA!$B$7:$B$300,$B10) -> 337 | AI10: =IF(AND(AH10>0,AJ10>0),AJ10/AH10,"") -> 744.69139 | AJ10: =SUMIFS(DA!$E$7:$E$300,DA!$B$7:$B$300,$B10) -> 250961 | AK10: =SUMIFS(DA!$H$7:$H$300,DA!$B$7:$B$300,$B10) -> 233288.25 | AL10: =AK10-AJ10 -> -17672.75 | AM10: =IF(AJ10>0,AL10/AJ10,"") -> -0.070420304 | AN10: =IF(AK$6=0,"",AK10/AK$6) -> 0.060157845
A11: 5 | B11: AFCOM Holdings Ltd | C11: =IFERROR(INDEX(Prices!$C$6:$C$300,MATCH($B11,Prices!$A$6:$A$300,0)),"") -> 1432.05 | D11: =IFERROR(INDEX(Prices!$D$6:$D$300,MATCH($B11,Prices!$A$6:$A$300,0)),"") -> Close 08.10.2026 (Screener.in) | E11: =(M11>0)+(T11>0)+(AA11>0)+(AH11>0) -> 3 | F11: =M11+T11+AA11+AH11 -> 480 | G11: =IF(AND(F11>0,H11>0),H11/F11,"") -> 1192.0396 | H11: =O11+V11+AC11+AJ11 -> 572179 | I11: =P11+W11+AD11+AK11 -> 687384 | J11: =I11-H11 -> 115205 | K11: =IF(H11>0,J11/H11,"") -> 0.20134433 | L11: =IF(I$6=0,"",I11/I$6) -> 0.048396748 | M11: =SUMIFS('Vidushi Malhotra'!$D$7:$D$300,'Vidushi Malhotra'!$B$7:$B$300,$B11) -> 0 | N11: =IF(AND(M11>0,O11>0),O11/M11,"") | O11: =SUMIFS('Vidushi Malhotra'!$E$7:$E$300,'Vidushi Malhotra'!$B$7:$B$300,$B11) -> 0 | P11: =SUMIFS('Vidushi Malhotra'!$H$7:$H$300,'Vidushi Malhotra'!$B$7:$B$300,$B11) -> 0 | Q11: =P11-O11 -> 0 | R11: =IF(O11>0,Q11/O11,"") | S11: =IF(P$6=0,"",P11/P$6) -> 0 | T11: =SUMIFS('Dr Umesh Choudhry'!$D$7:$D$300,'Dr Umesh Choudhry'!$B$7:$B$300,$B11) -> 240 | U11: =IF(AND(T11>0,V11>0),V11/T11,"") -> 846.57917 | V11: =SUMIFS('Dr Umesh Choudhry'!$E$7:$E$300,'Dr Umesh Choudhry'!$B$7:$B$300,$B11) -> 203179 | W11: =SUMIFS('Dr Umesh Choudhry'!$H$7:$H$300,'Dr Umesh Choudhry'!$B$7:$B$300,$B11) -> 343692 | X11: =W11-V11 -> 140513 | Y11: =IF(V11>0,X11/V11,"") -> 0.69157246 | Z11: =IF(W$6=0,"",W11/W$6) -> 0.063324334 | AA11: =SUMIFS(Gautam!$D$7:$D$300,Gautam!$B$7:$B$300,$B11) -> 120 | AB11: =IF(AND(AA11>0,AC11>0),AC11/AA11,"") -> 1666 | AC11: =SUMIFS(Gautam!$E$7:$E$300,Gautam!$B$7:$B$300,$B11) -> 199920 | AD11: =SUMIFS(Gautam!$H$7:$H$300,Gautam!$B$7:$B$300,$B11) -> 171846 | AE11: =AD11-AC11 -> -28074 | AF11: =IF(AC11>0,AE11/AC11,"") -> -0.14042617 | AG11: =IF(AD$6=0,"",AD11/AD$6) -> 0.036776768 | AH11: =SUMIFS(DA!$D$7:$D$300,DA!$B$7:$B$300,$B11) -> 120 | AI11: =IF(AND(AH11>0,AJ11>0),AJ11/AH11,"") -> 1409 | AJ11: =SUMIFS(DA!$E$7:$E$300,DA!$B$7:$B$300,$B11) -> 169080 | AK11: =SUMIFS(DA!$H$7:$H$300,DA!$B$7:$B$300,$B11) -> 171846 | AL11: =AK11-AJ11 -> 2766 | AM11: =IF(AJ11>0,AL11/AJ11,"") -> 0.01635912 | AN11: =IF(AK$6=0,"",AK11/AK$6) -> 0.044313783
A12: 6 | B12: Connplex Cinemas Ltd | C12: =IFERROR(INDEX(Prices!$C$6:$C$300,MATCH($B12,Prices!$A$6:$A$300,0)),"") -> 245 | D12: =IFERROR(INDEX(Prices!$D$6:$D$300,MATCH($B12,Prices!$A$6:$A$300,0)),"") -> Close 08.10.2026 (Screener.in) | E12: =(M12>0)+(T12>0)+(AA12>0)+(AH12>0) -> 3 | F12: =M12+T12+AA12+AH12 -> 2400 | G12: =IF(AND(F12>0,H12>0),H12/F12,"") -> 239.66333 | H12: =O12+V12+AC12+AJ12 -> 575192 | I12: =P12+W12+AD12+AK12 -> 588000 | J12: =I12-H12 -> 12808 | K12: =IF(H12>0,J12/H12,"") -> 0.022267347 | L12: =IF(I$6=0,"",I12/I$6) -> 0.041399404 | M12: =SUMIFS('Vidushi Malhotra'!$D$7:$D$300,'Vidushi Malhotra'!$B$7:$B$300,$B12) -> 0 | N12: =IF(AND(M12>0,O12>0),O12/M12,"") | O12: =SUMIFS('Vidushi Malhotra'!$E$7:$E$300,'Vidushi Malhotra'!$B$7:$B$300,$B12) -> 0 | P12: =SUMIFS('Vidushi Malhotra'!$H$7:$H$300,'Vidushi Malhotra'!$B$7:$B$300,$B12) -> 0 | Q12: =P12-O12 -> 0 | R12: =IF(O12>0,Q12/O12,"") | S12: =IF(P$6=0,"",P12/P$6) -> 0 | T12: =SUMIFS('Dr Umesh Choudhry'!$D$7:$D$300,'Dr Umesh Choudhry'!$B$7:$B$300,$B12) -> 800 | U12: =IF(AND(T12>0,V12>0),V12/T12,"") -> 229.99 | V12: =SUMIFS('Dr Umesh Choudhry'!$E$7:$E$300,'Dr Umesh Choudhry'!$B$7:$B$300,$B12) -> 183992 | W12: =SUMIFS('Dr Umesh Choudhry'!$H$7:$H$300,'Dr Umesh Choudhry'!$B$7:$B$300,$B12) -> 196000 | X12: =W12-V12 -> 12008 | Y12: =IF(V12>0,X12/V12,"") -> 0.065263707 | Z12: =IF(W$6=0,"",W12/W$6) -> 0.036112477 | AA12: =SUMIFS(Gautam!$D$7:$D$300,Gautam!$B$7:$B$300,$B12) -> 800 | AB12: =IF(AND(AA12>0,AC12>0),AC12/AA12,"") -> 264 | AC12: =SUMIFS(Gautam!$E$7:$E$300,Gautam!$B$7:$B$300,$B12) -> 211200 | AD12: =SUMIFS(Gautam!$H$7:$H$300,Gautam!$B$7:$B$300,$B12) -> 196000 | AE12: =AD12-AC12 -> -15200 | AF12: =IF(AC12>0,AE12/AC12,"") -> -0.071969697 | AG12: =IF(AD$6=0,"",AD12/AD$6) -> 0.041945967 | AH12: =SUMIFS(DA!$D$7:$D$300,DA!$B$7:$B$300,$B12) -> 800 | AI12: =IF(AND(AH12>0,AJ12>0),AJ12/AH12,"") -> 225 | AJ12: =SUMIFS(DA!$E$7:$E$300,DA!$B$7:$B$300,$B12) -> 180000 | AK12: =SUMIFS(DA!$H$7:$H$300,DA!$B$7:$B$300,$B12) -> 196000 | AL12: =AK12-AJ12 -> 16000 | AM12: =IF(AJ12>0,AL12/AJ12,"") -> 0.088888889 | AN12: =IF(AK$6=0,"",AK12/AK$6) -> 0.050542355
A13: 7 | B13: Bajaj Housing Finance Ltd | C13: =IFERROR(INDEX(Prices!$C$6:$C$300,MATCH($B13,Prices!$A$6:$A$300,0)),"") -> 82.14 | D13: =IFERROR(INDEX(Prices!$D$6:$D$300,MATCH($B13,Prices!$A$6:$A$300,0)),"") -> Close 08.10.2026 (Screener.in) | E13: =(M13>0)+(T13>0)+(AA13>0)+(AH13>0) -> 4 | F13: =M13+T13+AA13+AH13 -> 5377 | G13: =IF(AND(F13>0,H13>0),H13/F13,"") -> 102.88414 | H13: =O13+V13+AC13+AJ13 -> 553208 | I13: =P13+W13+AD13+AK13 -> 441666.78 | J13: =I13-H13 -> -111541.22 | K13: =IF(H13>0,J13/H13,"") -> -0.20162619 | L13: =IF(I$6=0,"",I13/I$6) -> 0.031096499 | M13: =SUMIFS('Vidushi Malhotra'!$D$7:$D$300,'Vidushi Malhotra'!$B$7:$B$300,$B13) -> 121 | N13: =IF(AND(M13>0,O13>0),O13/M13,"") -> 115.43802 | O13: =SUMIFS('Vidushi Malhotra'!$E$7:$E$300,'Vidushi Malhotra'!$B$7:$B$300,$B13) -> 13968 | P13: =SUMIFS('Vidushi Malhotra'!$H$7:$H$300,'Vidushi Malhotra'!$B$7:$B$300,$B13) -> 9938.94 | Q13: =P13-O13 -> -4029.06 | R13: =IF(O13>0,Q13/O13,"") -> -0.28844931 | S13: =IF(P$6=0,"",P13/P$6) -> 0.044172627 | T13: =SUMIFS('Dr Umesh Choudhry'!$D$7:$D$300,'Dr Umesh Choudhry'!$B$7:$B$300,$B13) -> 2198 | U13: =IF(AND(T13>0,V13>0),V13/T13,"") -> 116.37853 | V13: =SUMIFS('Dr Umesh Choudhry'!$E$7:$E$300,'Dr Umesh Choudhry'!$B$7:$B$300,$B13) -> 255800 | W13: =SUMIFS('Dr Umesh Choudhry'!$H$7:$H$300,'Dr Umesh Choudhry'!$B$7:$B$300,$B13) -> 180543.72 | X13: =W13-V13 -> -75256.28 | Y13: =IF(V13>0,X13/V13,"") -> -0.29419969 | Z13: =IF(W$6=0,"",W13/W$6) -> 0.033264699 | AA13: =SUMIFS(Gautam!$D$7:$D$300,Gautam!$B$7:$B$300,$B13) -> 1326 | AB13: =IF(AND(AA13>0,AC13>0),AC13/AA13,"") -> 83.490196 | AC13: =SUMIFS(Gautam!$E$7:$E$300,Gautam!$B$7:$B$300,$B13) -> 110708 | AD13: =SUMIFS(Gautam!$H$7:$H$300,Gautam!$B$7:$B$300,$B13) -> 108917.64 | AE13: =AD13-AC13 -> -1790.36 | AF13: =IF(AC13>0,AE13/AC13,"") -> -0.016171912 | AG13: =IF(AD$6=0,"",AD13/AD$6) -> 0.023309468 | AH13: =SUMIFS(DA!$D$7:$D$300,DA!$B$7:$B$300,$B13) -> 1732 | AI13: =IF(AND(AH13>0,AJ13>0),AJ13/AH13,"") -> 99.729792 | AJ13: =SUMIFS(DA!$E$7:$E$300,DA!$B$7:$B$300,$B13) -> 172732 | AK13: =SUMIFS(DA!$H$7:$H$300,DA!$B$7:$B$300,$B13) -> 142266.48 | AL13: =AK13-AJ13 -> -30465.52 | AM13: =IF(AJ13>0,AL13/AJ13,"") -> -0.1763745 | AN13: =IF(AK$6=0,"",AK13/AK$6) -> 0.036686137
A14: 8 | B14: LTM Ltd (formerly LTIMindtree) | C14: =IFERROR(INDEX(Prices!$C$6:$C$300,MATCH($B14,Prices!$A$6:$A$300,0)),"") -> 3915 | D14: =IFERROR(INDEX(Prices!$D$6:$D$300,MATCH($B14,Prices!$A$6:$A$300,0)),"") -> Close 08.10.2026 (Screener.in) | E14: =(M14>0)+(T14>0)+(AA14>0)+(AH14>0) -> 4 | F14: =M14+T14+AA14+AH14 -> 104 | G14: =IF(AND(F14>0,H14>0),H14/F14,"") -> 5041.3462 | H14: =O14+V14+AC14+AJ14 -> 524300 | I14: =P14+W14+AD14+AK14 -> 407160 | J14: =I14-H14 -> -117140 | K14: =IF(H14>0,J14/H14,"") -> -0.22342171 | L14: =IF(I$6=0,"",I14/I$6) -> 0.028666975 | M14: =SUMIFS('Vidushi Malhotra'!$D$7:$D$300,'Vidushi Malhotra'!$B$7:$B$300,$B14) -> 2 | N14: =IF(AND(M14>0,O14>0),O14/M14,"") -> 5099 | O14: =SUMIFS('Vidushi Malhotra'!$E$7:$E$300,'Vidushi Malhotra'!$B$7:$B$300,$B14) -> 10198 | P14: =SUMIFS('Vidushi Malhotra'!$H$7:$H$300,'Vidushi Malhotra'!$B$7:$B$300,$B14) -> 7830 | Q14: =P14-O14 -> -2368 | R14: =IF(O14>0,Q14/O14,"") -> -0.23220239 | S14: =IF(P$6=0,"",P14/P$6) -> 0.034799654 | T14: =SUMIFS('Dr Umesh Choudhry'!$D$7:$D$300,'Dr Umesh Choudhry'!$B$7:$B$300,$B14) -> 37 | U14: =IF(AND(T14>0,V14>0),V14/T14,"") -> 5854.1081 | V14: =SUMIFS('Dr Umesh Choudhry'!$E$7:$E$300,'Dr Umesh Choudhry'!$B$7:$B$300,$B14) -> 216602 | W14: =SUMIFS('Dr Umesh Choudhry'!$H$7:$H$300,'Dr Umesh Choudhry'!$B$7:$B$300,$B14) -> 144855 | X14: =W14-V14 -> -71747 | Y14: =IF(V14>0,X14/V14,"") -> -0.33123886 | Z14: =IF(W$6=0,"",W14/W$6) -> 0.026689147 | AA14: =SUMIFS(Gautam!$D$7:$D$300,Gautam!$B$7:$B$300,$B14) -> 60 | AB14: =IF(AND(AA14>0,AC14>0),AC14/AA14,"") -> 4564 | AC14: =SUMIFS(Gautam!$E$7:$E$300,Gautam!$B$7:$B$300,$B14) -> 273840 | AD14: =SUMIFS(Gautam!$H$7:$H$300,Gautam!$B$7:$B$300,$B14) -> 234900 | AE14: =AD14-AC14 -> -38940 | AF14: =IF(AC14>0,AE14/AC14,"") -> -0.14219982 | AG14: =IF(AD$6=0,"",AD14/AD$6) -> 0.050270957 | AH14: =SUMIFS(DA!$D$7:$D$300,DA!$B$7:$B$300,$B14) -> 5 | AI14: =IF(AND(AH14>0,AJ14>0),AJ14/AH14,"") -> 4732 | AJ14: =SUMIFS(DA!$E$7:$E$300,DA!$B$7:$B$300,$B14) -> 23660 | AK14: =SUMIFS(DA!$H$7:$H$300,DA!$B$7:$B$300,$B14) -> 19575 | AL14: =AK14-AJ14 -> -4085 | AM14: =IF(AJ14>0,AL14/AJ14,"") -> -0.17265427 | AN14: =IF(AK$6=0,"",AK14/AK$6) -> 0.0050477888
A15: 9 | B15: Nippon India ETF Nifty 1D Rate Liquid BeES | C15: =IFERROR(INDEX(Prices!$C$6:$C$300,MATCH($B15,Prices!$A$6:$A$300,0)),"") -> 1000 | D15: =IFERROR(INDEX(Prices!$D$6:$D$300,MATCH($B15,Prices!$A$6:$A$300,0)),"") -> Gautam stmt – 05.10 | E15: =(M15>0)+(T15>0)+(AA15>0)+(AH15>0) -> 1 | F15: =M15+T15+AA15+AH15 -> 300 | G15: =IF(AND(F15>0,H15>0),H15/F15,"") -> 1000 | H15: =O15+V15+AC15+AJ15 -> 300000 | I15: =P15+W15+AD15+AK15 -> 300000 | J15: =I15-H15 -> 0 | K15: =IF(H15>0,J15/H15,"") -> 0 | L15: =IF(I$6=0,"",I15/I$6) -> 0.021122145 | M15: =SUMIFS('Vidushi Malhotra'!$D$7:$D$300,'Vidushi Malhotra'!$B$7:$B$300,$B15) -> 0 | N15: =IF(AND(M15>0,O15>0),O15/M15,"") | O15: =SUMIFS('Vidushi Malhotra'!$E$7:$E$300,'Vidushi Malhotra'!$B$7:$B$300,$B15) -> 0 | P15: =SUMIFS('Vidushi Malhotra'!$H$7:$H$300,'Vidushi Malhotra'!$B$7:$B$300,$B15) -> 0 | Q15: =P15-O15 -> 0 | R15: =IF(O15>0,Q15/O15,"") | S15: =IF(P$6=0,"",P15/P$6) -> 0 | T15: =SUMIFS('Dr Umesh Choudhry'!$D$7:$D$300,'Dr Umesh Choudhry'!$B$7:$B$300,$B15) -> 0 | U15: =IF(AND(T15>0,V15>0),V15/T15,"") | V15: =SUMIFS('Dr Umesh Choudhry'!$E$7:$E$300,'Dr Umesh Choudhry'!$B$7:$B$300,$B15) -> 0 | W15: =SUMIFS('Dr Umesh Choudhry'!$H$7:$H$300,'Dr Umesh Choudhry'!$B$7:$B$300,$B15) -> 0 | X15: =W15-V15 -> 0 | Y15: =IF(V15>0,X15/V15,"") | Z15: =IF(W$6=0,"",W15/W$6) -> 0 | AA15: =SUMIFS(Gautam!$D$7:$D$300,Gautam!$B$7:$B$300,$B15) -> 300 | AB15: =IF(AND(AA15>0,AC15>0),AC15/AA15,"") -> 1000 | AC15: =SUMIFS(Gautam!$E$7:$E$300,Gautam!$B$7:$B$300,$B15) -> 300000 | AD15: =SUMIFS(Gautam!$H$7:$H$300,Gautam!$B$7:$B$300,$B15) -> 300000 | AE15: =AD15-AC15 -> 0 | AF15: =IF(AC15>0,AE15/AC15,"") -> 0 | AG15: =IF(AD$6=0,"",AD15/AD$6) -> 0.06420301 | AH15: =SUMIFS(DA!$D$7:$D$300,DA!$B$7:$B$300,$B15) -> 0 | AI15: =IF(AND(AH15>0,AJ15>0),AJ15/AH15,"") | AJ15: =SUMIFS(DA!$E$7:$E$300,DA!$B$7:$B$300,$B15) -> 0 | AK15: =SUMIFS(DA!$H$7:$H$300,DA!$B$7:$B$300,$B15) -> 0 | AL15: =AK15-AJ15 -> 0 | AM15: =IF(AJ15>0,AL15/AJ15,"") | AN15: =IF(AK$6=0,"",AK15/AK$6) -> 0
A16: 10 | B16: Fineotex Chemical Ltd | C16: =IFERROR(INDEX(Prices!$C$6:$C$300,MATCH($B16,Prices!$A$6:$A$300,0)),"") -> 55.99 | D16: =IFERROR(INDEX(Prices!$D$6:$D$300,MATCH($B16,Prices!$A$6:$A$300,0)),"") -> Close 08.10.2026 (Screener.in) | E16: =(M16>0)+(T16>0)+(AA16>0)+(AH16>0) -> 4 | F16: =M16+T16+AA16+AH16 -> 5142 | G16: =IF(AND(F16>0,H16>0),H16/F16,"") -> 39.824971 | H16: =O16+V16+AC16+AJ16 -> 204780 | I16: =P16+W16+AD16+AK16 -> 287900.58 | J16: =I16-H16 -> 83120.58 | K16: =IF(H16>0,J16/H16,"") -> 0.40590185 | L16: =IF(I$6=0,"",I16/I$6) -> 0.020270259 | M16: =SUMIFS('Vidushi Malhotra'!$D$7:$D$300,'Vidushi Malhotra'!$B$7:$B$300,$B16) -> 50 | N16: =IF(AND(M16>0,O16>0),O16/M16,"") -> 37.54 | O16: =SUMIFS('Vidushi Malhotra'!$E$7:$E$300,'Vidushi Malhotra'!$B$7:$B$300,$B16) -> 1877 | P16: =SUMIFS('Vidushi Malhotra'!$H$7:$H$300,'Vidushi Malhotra'!$B$7:$B$300,$B16) -> 2799.5 | Q16: =P16-O16 -> 922.5 | R16: =IF(O16>0,Q16/O16,"") -> 0.49147576 | S16: =IF(P$6=0,"",P16/P$6) -> 0.012442098 | T16: =SUMIFS('Dr Umesh Choudhry'!$D$7:$D$300,'Dr Umesh Choudhry'!$B$7:$B$300,$B16) -> 2370 | U16: =IF(AND(T16>0,V16>0),V16/T16,"") -> 39.829958 | V16: =SUMIFS('Dr Umesh Choudhry'!$E$7:$E$300,'Dr Umesh Choudhry'!$B$7:$B$300,$B16) -> 94397 | W16: =SUMIFS('Dr Umesh Choudhry'!$H$7:$H$300,'Dr Umesh Choudhry'!$B$7:$B$300,$B16) -> 132696.3 | X16: =W16-V16 -> 38299.3 | Y16: =IF(V16>0,X16/V16,"") -> 0.40572582 | Z16: =IF(W$6=0,"",W16/W$6) -> 0.024448939 | AA16: =SUMIFS(Gautam!$D$7:$D$300,Gautam!$B$7:$B$300,$B16) -> 692 | AB16: =IF(AND(AA16>0,AC16>0),AC16/AA16,"") -> 57.060694 | AC16: =SUMIFS(Gautam!$E$7:$E$300,Gautam!$B$7:$B$300,$B16) -> 39486 | AD16: =SUMIFS(Gautam!$H$7:$H$300,Gautam!$B$7:$B$300,$B16) -> 38745.08 | AE16: =AD16-AC16 -> -740.92 | AF16: =IF(AC16>0,AE16/AC16,"") -> -0.018764119 | AG16: =IF(AD$6=0,"",AD16/AD$6) -> 0.0082918359 | AH16: =SUMIFS(DA!$D$7:$D$300,DA!$B$7:$B$300,$B16) -> 2030 | AI16: =IF(AND(AH16>0,AJ16>0),AJ16/AH16,"") -> 34 | AJ16: =SUMIFS(DA!$E$7:$E$300,DA!$B$7:$B$300,$B16) -> 69020 | AK16: =SUMIFS(DA!$H$7:$H$300,DA!$B$7:$B$300,$B16) -> 113659.7 | AL16: =AK16-AJ16 -> 44639.7 | AM16: =IF(AJ16>0,AL16/AJ16,"") -> 0.64676471 | AN16: =IF(AK$6=0,"",AK16/AK$6) -> 0.029309331
A17: 11 | B17: Persistent Systems Ltd | C17: =IFERROR(INDEX(Prices!$C$6:$C$300,MATCH($B17,Prices!$A$6:$A$300,0)),"") -> 5468 | D17: =IFERROR(INDEX(Prices!$D$6:$D$300,MATCH($B17,Prices!$A$6:$A$300,0)),"") -> Close 08.10.2026 (Screener.in) | E17: =(M17>0)+(T17>0)+(AA17>0)+(AH17>0) -> 3 | F17: =M17+T17+AA17+AH17 -> 51 | G17: =IF(AND(F17>0,H17>0),H17/F17,"") -> 5227.9216 | H17: =O17+V17+AC17+AJ17 -> 266624 | I17: =P17+W17+AD17+AK17 -> 278868 | J17: =I17-H17 -> 12244 | K17: =IF(H17>0,J17/H17,"") -> 0.045922348 | L17: =IF(I$6=0,"",I17/I$6) -> 0.019634301 | M17: =SUMIFS('Vidushi Malhotra'!$D$7:$D$300,'Vidushi Malhotra'!$B$7:$B$300,$B17) -> 0 | N17: =IF(AND(M17>0,O17>0),O17/M17,"") | O17: =SUMIFS('Vidushi Malhotra'!$E$7:$E$300,'Vidushi Malhotra'!$B$7:$B$300,$B17) -> 0 | P17: =SUMIFS('Vidushi Malhotra'!$H$7:$H$300,'Vidushi Malhotra'!$B$7:$B$300,$B17) -> 0 | Q17: =P17-O17 -> 0 | R17: =IF(O17>0,Q17/O17,"") | S17: =IF(P$6=0,"",P17/P$6) -> 0 | T17: =SUMIFS('Dr Umesh Choudhry'!$D$7:$D$300,'Dr Umesh Choudhry'!$B$7:$B$300,$B17) -> 17 | U17: =IF(AND(T17>0,V17>0),V17/T17,"") -> 5101.9412 | V17: =SUMIFS('Dr Umesh Choudhry'!$E$7:$E$300,'Dr Umesh Choudhry'!$B$7:$B$300,$B17) -> 86733 | W17: =SUMIFS('Dr Umesh Choudhry'!$H$7:$H$300,'Dr Umesh Choudhry'!$B$7:$B$300,$B17) -> 92956 | X17: =W17-V17 -> 6223 | Y17: =IF(V17>0,X17/V17,"") -> 0.071748931 | Z17: =IF(W$6=0,"",W17/W$6) -> 0.017126895 | AA17: =SUMIFS(Gautam!$D$7:$D$300,Gautam!$B$7:$B$300,$B17) -> 16 | AB17: =IF(AND(AA17>0,AC17>0),AC17/AA17,"") -> 5501.125 | AC17: =SUMIFS(Gautam!$E$7:$E$300,Gautam!$B$7:$B$300,$B17) -> 88018 | AD17: =SUMIFS(Gautam!$H$7:$H$300,Gautam!$B$7:$B$300,$B17) -> 87488 | AE17: =AD17-AC17 -> -530 | AF17: =IF(AC17>0,AE17/AC17,"") -> -0.0060214956 | AG17: =IF(AD$6=0,"",AD17/AD$6) -> 0.01872331 | AH17: =SUMIFS(DA!$D$7:$D$300,DA!$B$7:$B$300,$B17) -> 18 | AI17: =IF(AND(AH17>0,AJ17>0),AJ17/AH17,"") -> 5104.0556 | AJ17: =SUMIFS(DA!$E$7:$E$300,DA!$B$7:$B$300,$B17) -> 91873 | AK17: =SUMIFS(DA!$H$7:$H$300,DA!$B$7:$B$300,$B17) -> 98424 | AL17: =AK17-AJ17 -> 6551 | AM17: =IF(AJ17>0,AL17/AJ17,"") -> 0.071304954 | AN17: =IF(AK$6=0,"",AK17/AK$6) -> 0.025380514
A18: 12 | B18: Tata Consultancy Services Ltd | C18: =IFERROR(INDEX(Prices!$C$6:$C$300,MATCH($B18,Prices!$A$6:$A$300,0)),"") -> 2076 | D18: =IFERROR(INDEX(Prices!$D$6:$D$300,MATCH($B18,Prices!$A$6:$A$300,0)),"") -> Close 08.10.2026 (Screener.in) | E18: =(M18>0)+(T18>0)+(AA18>0)+(AH18>0) -> 3 | F18: =M18+T18+AA18+AH18 -> 134 | G18: =IF(AND(F18>0,H18>0),H18/F18,"") -> 2718.9478 | H18: =O18+V18+AC18+AJ18 -> 364339 | I18: =P18+W18+AD18+AK18 -> 278184 | J18: =I18-H18 -> -86155 | K18: =IF(H18>0,J18/H18,"") -> -0.23646933 | L18: =IF(I$6=0,"",I18/I$6) -> 0.019586143 | M18: =SUMIFS('Vidushi Malhotra'!$D$7:$D$300,'Vidushi Malhotra'!$B$7:$B$300,$B18) -> 0 | N18: =IF(AND(M18>0,O18>0),O18/M18,"") | O18: =SUMIFS('Vidushi Malhotra'!$E$7:$E$300,'Vidushi Malhotra'!$B$7:$B$300,$B18) -> 0 | P18: =SUMIFS('Vidushi Malhotra'!$H$7:$H$300,'Vidushi Malhotra'!$B$7:$B$300,$B18) -> 0 | Q18: =P18-O18 -> 0 | R18: =IF(O18>0,Q18/O18,"") | S18: =IF(P$6=0,"",P18/P$6) -> 0 | T18: =SUMIFS('Dr Umesh Choudhry'!$D$7:$D$300,'Dr Umesh Choudhry'!$B$7:$B$300,$B18) -> 29 | U18: =IF(AND(T18>0,V18>0),V18/T18,"") -> 4227.6897 | V18: =SUMIFS('Dr Umesh Choudhry'!$E$7:$E$300,'Dr Umesh Choudhry'!$B$7:$B$300,$B18) -> 122603 | W18: =SUMIFS('Dr Umesh Choudhry'!$H$7:$H$300,'Dr Umesh Choudhry'!$B$7:$B$300,$B18) -> 60204 | X18: =W18-V18 -> -62399 | Y18: =IF(V18>0,X18/V18,"") -> -0.50895166 | Z18: =IF(W$6=0,"",W18/W$6) -> 0.011092426 | AA18: =SUMIFS(Gautam!$D$7:$D$300,Gautam!$B$7:$B$300,$B18) -> 92 | AB18: =IF(AND(AA18>0,AC18>0),AC18/AA18,"") -> 2289 | AC18: =SUMIFS(Gautam!$E$7:$E$300,Gautam!$B$7:$B$300,$B18) -> 210588 | AD18: =SUMIFS(Gautam!$H$7:$H$300,Gautam!$B$7:$B$300,$B18) -> 190992 | AE18: =AD18-AC18 -> -19596 | AF18: =IF(AC18>0,AE18/AC18,"") -> -0.093053735 | AG18: =IF(AD$6=0,"",AD18/AD$6) -> 0.040874204 | AH18: =SUMIFS(DA!$D$7:$D$300,DA!$B$7:$B$300,$B18) -> 13 | AI18: =IF(AND(AH18>0,AJ18>0),AJ18/AH18,"") -> 2396 | AJ18: =SUMIFS(DA!$E$7:$E$300,DA!$B$7:$B$300,$B18) -> 31148 | AK18: =SUMIFS(DA!$H$7:$H$300,DA!$B$7:$B$300,$B18) -> 26988 | AL18: =AK18-AJ18 -> -4160 | AM18: =IF(AJ18>0,AL18/AJ18,"") -> -0.13355593 | AN18: =IF(AK$6=0,"",AK18/AK$6) -> 0.0069593728
... A73: 67 | B73: PSL Ltd (formerly PSL Holdings Ltd) | C73: =IFERROR(INDEX(Prices!$C$6:$C$300,MATCH($B73,Prices!$A$6:$A$300,0)),"") | D73: =IFERROR(INDEX(Prices!$D$6:$D$300,MATCH($B73,Prices!$A$6:$A$300,0)),"") -> No price on any statement | E73: =(M73>0)+(T73>0)+(AA73>0)+(AH73>0) -> 1 | F73: =M73+T73+AA73+AH73 -> 1000 | G73: =IF(AND(F73>0,H73>0),H73/F73,"") | H73: =O73+V73+AC73+AJ73 -> 0 | I73: =P73+W73+AD73+AK73 -> 0 | J73: =I73-H73 -> 0 | K73: =IF(H73>0,J73/H73,"") | L73: =IF(I$6=0,"",I73/I$6) -> 0 | M73: =SUMIFS('Vidushi Malhotra'!$D$7:$D$300,'Vidushi Malhotra'!$B$7:$B$300,$B73) -> 0 | N73: =IF(AND(M73>0,O73>0),O73/M73,"") | O73: =SUMIFS('Vidushi Malhotra'!$E$7:$E$300,'Vidushi Malhotra'!$B$7:$B$300,$B73) -> 0 | P73: =SUMIFS('Vidushi Malhotra'!$H$7:$H$300,'Vidushi Malhotra'!$B$7:$B$300,$B73) -> 0 | Q73: =P73-O73 -> 0 | R73: =IF(O73>0,Q73/O73,"") | S73: =IF(P$6=0,"",P73/P$6) -> 0 | T73: =SUMIFS('Dr Umesh Choudhry'!$D$7:$D$300,'Dr Umesh Choudhry'!$B$7:$B$300,$B73) -> 0 | U73: =IF(AND(T73>0,V73>0),V73/T73,"") | V73: =SUMIFS('Dr Umesh Choudhry'!$E$7:$E$300,'Dr Umesh Choudhry'!$B$7:$B$300,$B73) -> 0 | W73: =SUMIFS('Dr Umesh Choudhry'!$H$7:$H$300,'Dr Umesh Choudhry'!$B$7:$B$300,$B73) -> 0 | X73: =W73-V73 -> 0 | Y73: =IF(V73>0,X73/V73,"") | Z73: =IF(W$6=0,"",W73/W$6) -> 0 | AA73: =SUMIFS(Gautam!$D$7:$D$300,Gautam!$B$7:$B$300,$B73) -> 1000 | AB73: =IF(AND(AA73>0,AC73>0),AC73/AA73,"") | AC73: =SUMIFS(Gautam!$E$7:$E$300,Gautam!$B$7:$B$300,$B73) -> 0 | AD73: =SUMIFS(Gautam!$H$7:$H$300,Gautam!$B$7:$B$300,$B73) -> 0 | AE73: =AD73-AC73 -> 0 | AF73: =IF(AC73>0,AE73/AC73,"") | AG73: =IF(AD$6=0,"",AD73/AD$6) -> 0 | AH73: =SUMIFS(DA!$D$7:$D$300,DA!$B$7:$B$300,$B73) -> 0 | AI73: =IF(AND(AH73>0,AJ73>0),AJ73/AH73,"") | AJ73: =SUMIFS(DA!$E$7:$E$300,DA!$B$7:$B$300,$B73) -> 0 | AK73: =SUMIFS(DA!$H$7:$H$300,DA!$B$7:$B$300,$B73) -> 0 | AL73: =AK73-AJ73 -> 0 | AM73: =IF(AJ73>0,AL73/AJ73,"") | AN73: =IF(AK$6=0,"",AK73/AK$6) -> 0

Sheet Prices
A1: COMMON PRICE SHEET
A2: One price per security, used to value every portfolio. Without an exchange close, the statement price is used, freshest statement first: Vidushi stmt – LTP 05.10 → Umesh stmt – NSE live 09.10 → Gautam stmt – 05.10 → DA stmt – older (stale).
A3: Column B holds NSE/BSE closes for 08.10.2026 (Screener.in). TO UPDATE: overwrite the yellow column B and the source text beside it — every portfolio and the combined view revalue. Blank B = statement price.
A5: Security | B5: Override Price (₹) ← type here | C5: Ref Price (₹) (used everywhere) | D5: Price Basis | E5: Vidushi Malhotra stmt (₹) | F5: Dr Umesh Choudhry stmt (₹) | G5: Gautam stmt (₹) | H5: DA stmt (₹) | I5: Override source | J5: Prev close 07.10 (₹) | K5: 1-day chg %
A6: AFCOM Holdings Ltd | B6: 1432.05 | C6: =IF(ISNUMBER(B6),B6,IF(ISNUMBER(E6),E6,IF(ISNUMBER(F6),F6,IF(ISNUMBER(G6),G6,IF(ISNUMBER(H6),H6,""))))) -> 1432.05 | D6: =IF(ISNUMBER(B6),IF(I6<>"",I6,"Manual override"),IF(ISNUMBER(E6),"Vidushi stmt – LTP 05.10",IF(ISNUMBER(F6),"Umesh stmt – NSE live 09.10",IF(ISNUMBER(G6),"Gautam stmt – 05.10",IF(ISNUMBER(H6),"DA stmt – older (stale)","No price on any statement"))))) -> Close 08.10.2026 (Screener.in) | E6: =IFERROR(INDEX('Vidushi Malhotra'!$M$7:$M$300,MATCH($A6,'Vidushi Malhotra'!$B$7:$B$300,0)),"") | F6: =IFERROR(INDEX('Dr Umesh Choudhry'!$M$7:$M$300,MATCH($A6,'Dr Umesh Choudhry'!$B$7:$B$300,0)),"") -> 1425 | G6: =IFERROR(INDEX(Gautam!$M$7:$M$300,MATCH($A6,Gautam!$B$7:$B$300,0)),"") -> 1481 | H6: =IFERROR(INDEX(DA!$M$7:$M$300,MATCH($A6,DA!$B$7:$B$300,0)),"") -> 1540 | I6: Close 08.10.2026 (Screener.in) | J6: 1499.4 | K6: =IF(AND(ISNUMBER(B6),ISNUMBER(J6),N(J6)>0),B6/J6-1,"") -> -0.044917967
A7: Affle 3i Ltd | B7: 1401.4 | C7: =IF(ISNUMBER(B7),B7,IF(ISNUMBER(E7),E7,IF(ISNUMBER(F7),F7,IF(ISNUMBER(G7),G7,IF(ISNUMBER(H7),H7,""))))) -> 1401.4 | D7: =IF(ISNUMBER(B7),IF(I7<>"",I7,"Manual override"),IF(ISNUMBER(E7),"Vidushi stmt – LTP 05.10",IF(ISNUMBER(F7),"Umesh stmt – NSE live 09.10",IF(ISNUMBER(G7),"Gautam stmt – 05.10",IF(ISNUMBER(H7),"DA stmt – older (stale)","No price on any statement"))))) -> Close 08.10.2026 (Screener.in) | E7: =IFERROR(INDEX('Vidushi Malhotra'!$M$7:$M$300,MATCH($A7,'Vidushi Malhotra'!$B$7:$B$300,0)),"") -> 1456.6667 | F7: =IFERROR(INDEX('Dr Umesh Choudhry'!$M$7:$M$300,MATCH($A7,'Dr Umesh Choudhry'!$B$7:$B$300,0)),"") -> 1422.8936 | G7: =IFERROR(INDEX(Gautam!$M$7:$M$300,MATCH($A7,Gautam!$B$7:$B$300,0)),"") -> 1450 | H7: =IFERROR(INDEX(DA!$M$7:$M$300,MATCH($A7,DA!$B$7:$B$300,0)),"") -> 1568 | I7: Close 08.10.2026 (Screener.in) | J7: 1436 | K7: =IF(AND(ISNUMBER(B7),ISNUMBER(J7),N(J7)>0),B7/J7-1,"") -> -0.024094708
A8: Ambuja Cements Ltd | B8: 341 | C8: =IF(ISNUMBER(B8),B8,IF(ISNUMBER(E8),E8,IF(ISNUMBER(F8),F8,IF(ISNUMBER(G8),G8,IF(ISNUMBER(H8),H8,""))))) -> 341 | D8: =IF(ISNUMBER(B8),IF(I8<>"",I8,"Manual override"),IF(ISNUMBER(E8),"Vidushi stmt – LTP 05.10",IF(ISNUMBER(F8),"Umesh stmt – NSE live 09.10",IF(ISNUMBER(G8),"Gautam stmt – 05.10",IF(ISNUMBER(H8),"DA stmt – older (stale)","No price on any statement"))))) -> Close 08.10.2026 (Screener.in) | E8: =IFERROR(INDEX('Vidushi Malhotra'!$M$7:$M$300,MATCH($A8,'Vidushi Malhotra'!$B$7:$B$300,0)),"") | F8: =IFERROR(INDEX('Dr Umesh Choudhry'!$M$7:$M$300,MATCH($A8,'Dr Umesh Choudhry'!$B$7:$B$300,0)),"") | G8: =IFERROR(INDEX(Gautam!$M$7:$M$300,MATCH($A8,Gautam!$B$7:$B$300,0)),"") | H8: =IFERROR(INDEX(DA!$M$7:$M$300,MATCH($A8,DA!$B$7:$B$300,0)),"") -> 392 | I8: Close 08.10.2026 (Screener.in) | J8: 356.9 | K8: =IF(AND(ISNUMBER(B8),ISNUMBER(J8),N(J8)>0),B8/J8-1,"") -> -0.044550294
A9: Ashoka Buildcon Ltd | B9: 101.4 | C9: =IF(ISNUMBER(B9),B9,IF(ISNUMBER(E9),E9,IF(ISNUMBER(F9),F9,IF(ISNUMBER(G9),G9,IF(ISNUMBER(H9),H9,""))))) -> 101.4 | D9: =IF(ISNUMBER(B9),IF(I9<>"",I9,"Manual override"),IF(ISNUMBER(E9),"Vidushi stmt – LTP 05.10",IF(ISNUMBER(F9),"Umesh stmt – NSE live 09.10",IF(ISNUMBER(G9),"Gautam stmt – 05.10",IF(ISNUMBER(H9),"DA stmt – older (stale)","No price on any statement"))))) -> Close 08.10.2026 (Screener.in) | E9: =IFERROR(INDEX('Vidushi Malhotra'!$M$7:$M$300,MATCH($A9,'Vidushi Malhotra'!$B$7:$B$300,0)),"") | F9: =IFERROR(INDEX('Dr Umesh Choudhry'!$M$7:$M$300,MATCH($A9,'Dr Umesh Choudhry'!$B$7:$B$300,0)),"") | G9: =IFERROR(INDEX(Gautam!$M$7:$M$300,MATCH($A9,Gautam!$B$7:$B$300,0)),"") | H9: =IFERROR(INDEX(DA!$M$7:$M$300,MATCH($A9,DA!$B$7:$B$300,0)),"") -> 114 | I9: Close 08.10.2026 (Screener.in) | J9: 104.03 | K9: =IF(AND(ISNUMBER(B9),ISNUMBER(J9),N(J9)>0),B9/J9-1,"") -> -0.025281169
A10: Astec LifeSciences Ltd | B10: 714.75 | C10: =IF(ISNUMBER(B10),B10,IF(ISNUMBER(E10),E10,IF(ISNUMBER(F10),F10,IF(ISNUMBER(G10),G10,IF(ISNUMBER(H10),H10,""))))) -> 714.75 | D10: =IF(ISNUMBER(B10),IF(I10<>"",I10,"Manual override"),IF(ISNUMBER(E10),"Vidushi stmt – LTP 05.10",IF(ISNUMBER(F10),"Umesh stmt – NSE live 09.10",IF(ISNUMBER(G10),"Gautam stmt – 05.10",IF(ISNUMBER(H10),"DA stmt – older (stale)","No price on any statement"))))) -> Close 08.10.2026 (Screener.in) | E10: =IFERROR(INDEX('Vidushi Malhotra'!$M$7:$M$300,MATCH($A10,'Vidushi Malhotra'!$B$7:$B$300,0)),"") | F10: =IFERROR(INDEX('Dr Umesh Choudhry'!$M$7:$M$300,MATCH($A10,'Dr Umesh Choudhry'!$B$7:$B$300,0)),"") | G10: =IFERROR(INDEX(Gautam!$M$7:$M$300,MATCH($A10,Gautam!$B$7:$B$300,0)),"") | H10: =IFERROR(INDEX(DA!$M$7:$M$300,MATCH($A10,DA!$B$7:$B$300,0)),"") -> 700 | I10: Close 08.10.2026 (Screener.in) | J10: 748.2 | K10: =IF(AND(ISNUMBER(B10),ISNUMBER(J10),N(J10)>0),B10/J10-1,"") -> -0.044707298
A11: Avenue Supermarts (DMart) Ltd | B11: 3585 | C11: =IF(ISNUMBER(B11),B11,IF(ISNUMBER(E11),E11,IF(ISNUMBER(F11),F11,IF(ISNUMBER(G11),G11,IF(ISNUMBER(H11),H11,""))))) -> 3585 | D11: =IF(ISNUMBER(B11),IF(I11<>"",I11,"Manual override"),IF(ISNUMBER(E11),"Vidushi stmt – LTP 05.10",IF(ISNUMBER(F11),"Umesh stmt – NSE live 09.10",IF(ISNUMBER(G11),"Gautam stmt – 05.10",IF(ISNUMBER(H11),"DA stmt – older (stale)","No price on any statement"))))) -> Close 08.10.2026 (Screener.in) | E11: =IFERROR(INDEX('Vidushi Malhotra'!$M$7:$M$300,MATCH($A11,'Vidushi Malhotra'!$B$7:$B$300,0)),"") | F11: =IFERROR(INDEX('Dr Umesh Choudhry'!$M$7:$M$300,MATCH($A11,'Dr Umesh Choudhry'!$B$7:$B$300,0)),"") -> 3567.5 | G11: =IFERROR(INDEX(Gautam!$M$7:$M$300,MATCH($A11,Gautam!$B$7:$B$300,0)),"") -> 3813 | H11: =IFERROR(INDEX(DA!$M$7:$M$300,MATCH($A11,DA!$B$7:$B$300,0)),"") -> 3688 | I11: Close 08.10.2026 (Screener.in) | J11: 3636 | K11: =IF(AND(ISNUMBER(B11),ISNUMBER(J11),N(J11)>0),B11/J11-1,"") -> -0.014026403
A12: Bagmane Prime Office REIT | B12: 106.52 | C12: =IF(ISNUMBER(B12),B12,IF(ISNUMBER(E12),E12,IF(ISNUMBER(F12),F12,IF(ISNUMBER(G12),G12,IF(ISNUMBER(H12),H12,""))))) -> 106.52 | D12: =IF(ISNUMBER(B12),IF(I12<>"",I12,"Manual override"),IF(ISNUMBER(E12),"Vidushi stmt – LTP 05.10",IF(ISNUMBER(F12),"Umesh stmt – NSE live 09.10",IF(ISNUMBER(G12),"Gautam stmt – 05.10",IF(ISNUMBER(H12),"DA stmt – older (stale)","No price on any statement"))))) -> Close 08.10.2026 (Screener.in) | E12: =IFERROR(INDEX('Vidushi Malhotra'!$M$7:$M$300,MATCH($A12,'Vidushi Malhotra'!$B$7:$B$300,0)),"") | F12: =IFERROR(INDEX('Dr Umesh Choudhry'!$M$7:$M$300,MATCH($A12,'Dr Umesh Choudhry'!$B$7:$B$300,0)),"") | G12: =IFERROR(INDEX(Gautam!$M$7:$M$300,MATCH($A12,Gautam!$B$7:$B$300,0)),"") -> 107 | H12: =IFERROR(INDEX(DA!$M$7:$M$300,MATCH($A12,DA!$B$7:$B$300,0)),"") | I12: Close 08.10.2026 (Screener.in) | J12: 106.62 | K12: =IF(AND(ISNUMBER(B12),ISNUMBER(J12),N(J12)>0),B12/J12-1,"") -> -0.00093791034
A13: Bajaj Finance Ltd | B13: 955.95 | C13: =IF(ISNUMBER(B13),B13,IF(ISNUMBER(E13),E13,IF(ISNUMBER(F13),F13,IF(ISNUMBER(G13),G13,IF(ISNUMBER(H13),H13,""))))) -> 955.95 | D13: =IF(ISNUMBER(B13),IF(I13<>"",I13,"Manual override"),IF(ISNUMBER(E13),"Vidushi stmt – LTP 05.10",IF(ISNUMBER(F13),"Umesh stmt – NSE live 09.10",IF(ISNUMBER(G13),"Gautam stmt – 05.10",IF(ISNUMBER(H13),"DA stmt – older (stale)","No price on any statement"))))) -> Close 08.10.2026 (Screener.in) | E13: =IFERROR(INDEX('Vidushi Malhotra'!$M$7:$M$300,MATCH($A13,'Vidushi Malhotra'!$B$7:$B$300,0)),"") -> 973.90083 | F13: =IFERROR(INDEX('Dr Umesh Choudhry'!$M$7:$M$300,MATCH($A13,'Dr Umesh Choudhry'!$B$7:$B$300,0)),"") -> 961.34992 | G13: =IFERROR(INDEX(Gautam!$M$7:$M$300,MATCH($A13,Gautam!$B$7:$B$300,0)),"") -> 981 | H13: =IFERROR(INDEX(DA!$M$7:$M$300,MATCH($A13,DA!$B$7:$B$300,0)),"") -> 1034 | I13: Close 08.10.2026 (Screener.in) | J13: 963.85 | K13: =IF(AND(ISNUMBER(B13),ISNUMBER(J13),N(J13)>0),B13/J13-1,"") -> -0.0081962961
A14: Bajaj Housing Finance Ltd | B14: 82.14 | C14: =IF(ISNUMBER(B14),B14,IF(ISNUMBER(E14),E14,IF(ISNUMBER(F14),F14,IF(ISNUMBER(G14),G14,IF(ISNUMBER(H14),H14,""))))) -> 82.14 | D14: =IF(ISNUMBER(B14),IF(I14<>"",I14,"Manual override"),IF(ISNUMBER(E14),"Vidushi stmt – LTP 05.10",IF(ISNUMBER(F14),"Umesh stmt – NSE live 09.10",IF(ISNUMBER(G14),"Gautam stmt – 05.10",IF(ISNUMBER(H14),"DA stmt – older (stale)","No price on any statement"))))) -> Close 08.10.2026 (Screener.in) | E14: =IFERROR(INDEX('Vidushi Malhotra'!$M$7:$M$300,MATCH($A14,'Vidushi Malhotra'!$B$7:$B$300,0)),"") -> 81.801653 | F14: =IFERROR(INDEX('Dr Umesh Choudhry'!$M$7:$M$300,MATCH($A14,'Dr Umesh Choudhry'!$B$7:$B$300,0)),"") -> 82.210191 | G14: =IFERROR(INDEX(Gautam!$M$7:$M$300,MATCH($A14,Gautam!$B$7:$B$300,0)),"") -> 82.600302 | H14: =IFERROR(INDEX(DA!$M$7:$M$300,MATCH($A14,DA!$B$7:$B$300,0)),"") -> 84 | I14: Close 08.10.2026 (Screener.in) | J14: 84.08 | K14: =IF(AND(ISNUMBER(B14),ISNUMBER(J14),N(J14)>0),B14/J14-1,"") -> -0.023073264
A15: Bharti Airtel Ltd | B15: 1804.6 | C15: =IF(ISNUMBER(B15),B15,IF(ISNUMBER(E15),E15,IF(ISNUMBER(F15),F15,IF(ISNUMBER(G15),G15,IF(ISNUMBER(H15),H15,""))))) -> 1804.6 | D15: =IF(ISNUMBER(B15),IF(I15<>"",I15,"Manual override"),IF(ISNUMBER(E15),"Vidushi stmt – LTP 05.10",IF(ISNUMBER(F15),"Umesh stmt – NSE live 09.10",IF(ISNUMBER(G15),"Gautam stmt – 05.10",IF(ISNUMBER(H15),"DA stmt – older (stale)","No price on any statement"))))) -> Close 08.10.2026 (Screener.in) | E15: =IFERROR(INDEX('Vidushi Malhotra'!$M$7:$M$300,MATCH($A15,'Vidushi Malhotra'!$B$7:$B$300,0)),"") | F15: =IFERROR(INDEX('Dr Umesh Choudhry'!$M$7:$M$300,MATCH($A15,'Dr Umesh Choudhry'!$B$7:$B$300,0)),"") | G15: =IFERROR(INDEX(Gautam!$M$7:$M$300,MATCH($A15,Gautam!$B$7:$B$300,0)),"") -> 1741 | H15: =IFERROR(INDEX(DA!$M$7:$M$300,MATCH($A15,DA!$B$7:$B$300,0)),"") | I15: Close 08.10.2026 (Screener.in) | J15: 1833.9 | K15: =IF(AND(ISNUMBER(B15),ISNUMBER(J15),N(J15)>0),B15/J15-1,"") -> -0.01597688
A16: Brigade Enterprises Ltd | B16: 547.2 | C16: =IF(ISNUMBER(B16),B16,IF(ISNUMBER(E16),E16,IF(ISNUMBER(F16),F16,IF(ISNUMBER(G16),G16,IF(ISNUMBER(H16),H16,""))))) -> 547.2 | D16: =IF(ISNUMBER(B16),IF(I16<>"",I16,"Manual override"),IF(ISNUMBER(E16),"Vidushi stmt – LTP 05.10",IF(ISNUMBER(F16),"Umesh stmt – NSE live 09.10",IF(ISNUMBER(G16),"Gautam stmt – 05.10",IF(ISNUMBER(H16),"DA stmt – older (stale)","No price on any statement"))))) -> Close 08.10.2026 (Screener.in) | E16: =IFERROR(INDEX('Vidushi Malhotra'!$M$7:$M$300,MATCH($A16,'Vidushi Malhotra'!$B$7:$B$300,0)),"") | F16: =IFERROR(INDEX('Dr Umesh Choudhry'!$M$7:$M$300,MATCH($A16,'Dr Umesh Choudhry'!$B$7:$B$300,0)),"") | G16: =IFERROR(INDEX(Gautam!$M$7:$M$300,MATCH($A16,Gautam!$B$7:$B$300,0)),"") | H16: =IFERROR(INDEX(DA!$M$7:$M$300,MATCH($A16,DA!$B$7:$B$300,0)),"") -> 639 | I16: Close 08.10.2026 (Screener.in) | J16: 554.2 | K16: =IF(AND(ISNUMBER(B16),ISNUMBER(J16),N(J16)>0),B16/J16-1,"") -> -0.012630819
A17: Capacite Infraprojects Ltd | B17: 177.19 | C17: =IF(ISNUMBER(B17),B17,IF(ISNUMBER(E17),E17,IF(ISNUMBER(F17),F17,IF(ISNUMBER(G17),G17,IF(ISNUMBER(H17),H17,""))))) -> 177.19 | D17: =IF(ISNUMBER(B17),IF(I17<>"",I17,"Manual override"),IF(ISNUMBER(E17),"Vidushi stmt – LTP 05.10",IF(ISNUMBER(F17),"Umesh stmt – NSE live 09.10",IF(ISNUMBER(G17),"Gautam stmt – 05.10",IF(ISNUMBER(H17),"DA stmt – older (stale)","No price on any statement"))))) -> Close 08.10.2026 (Screener.in) | E17: =IFERROR(INDEX('Vidushi Malhotra'!$M$7:$M$300,MATCH($A17,'Vidushi Malhotra'!$B$7:$B$300,0)),"") | F17: =IFERROR(INDEX('Dr Umesh Choudhry'!$M$7:$M$300,MATCH($A17,'Dr Umesh Choudhry'!$B$7:$B$300,0)),"") | G17: =IFERROR(INDEX(Gautam!$M$7:$M$300,MATCH($A17,Gautam!$B$7:$B$300,0)),"") | H17: =IFERROR(INDEX(DA!$M$7:$M$300,MATCH($A17,DA!$B$7:$B$300,0)),"") -> 192 | I17: Close 08.10.2026 (Screener.in) | J17: 181.72 | K17: =IF(AND(ISNUMBER(B17),ISNUMBER(J17),N(J17)>0),B17/J17-1,"") -> -0.024928461
A18: Cash – ICICI Direct | B18: 1 | C18: =IF(ISNUMBER(B18),B18,IF(ISNUMBER(E18),E18,IF(ISNUMBER(F18),F18,IF(ISNUMBER(G18),G18,IF(ISNUMBER(H18),H18,""))))) -> 1 | D18: =IF(ISNUMBER(B18),IF(I18<>"",I18,"Manual override"),IF(ISNUMBER(E18),"Vidushi stmt – LTP 05.10",IF(ISNUMBER(F18),"Umesh stmt – NSE live 09.10",IF(ISNUMBER(G18),"Gautam stmt – 05.10",IF(ISNUMBER(H18),"DA stmt – older (stale)","No price on any statement"))))) -> Cash at par (₹1) | E18: =IFERROR(INDEX('Vidushi Malhotra'!$M$7:$M$300,MATCH($A18,'Vidushi Malhotra'!$B$7:$B$300,0)),"") | F18: =IFERROR(INDEX('Dr Umesh Choudhry'!$M$7:$M$300,MATCH($A18,'Dr Umesh Choudhry'!$B$7:$B$300,0)),"") -> 1 | G18: =IFERROR(INDEX(Gautam!$M$7:$M$300,MATCH($A18,Gautam!$B$7:$B$300,0)),"") | H18: =IFERROR(INDEX(DA!$M$7:$M$300,MATCH($A18,DA!$B$7:$B$300,0)),"") | I18: Cash at par (₹1) | K18: =IF(AND(ISNUMBER(B18),ISNUMBER(J18),N(J18)>0),B18/J18-1,"")
A19: Connplex Cinemas Ltd | B19: 245 | C19: =IF(ISNUMBER(B19),B19,IF(ISNUMBER(E19),E19,IF(ISNUMBER(F19),F19,IF(ISNUMBER(G19),G19,IF(ISNUMBER(H19),H19,""))))) -> 245 | D19: =IF(ISNUMBER(B19),IF(I19<>"",I19,"Manual override"),IF(ISNUMBER(E19),"Vidushi stmt – LTP 05.10",IF(ISNUMBER(F19),"Umesh stmt – NSE live 09.10",IF(ISNUMBER(G19),"Gautam stmt – 05.10",IF(ISNUMBER(H19),"DA stmt – older (stale)","No price on any statement"))))) -> Close 08.10.2026 (Screener.in) | E19: =IFERROR(INDEX('Vidushi Malhotra'!$M$7:$M$300,MATCH($A19,'Vidushi Malhotra'!$B$7:$B$300,0)),"") | F19: =IFERROR(INDEX('Dr Umesh Choudhry'!$M$7:$M$300,MATCH($A19,'Dr Umesh Choudhry'!$B$7:$B$300,0)),"") -> 245 | G19: =IFERROR(INDEX(Gautam!$M$7:$M$300,MATCH($A19,Gautam!$B$7:$B$300,0)),"") -> 246 | H19: =IFERROR(INDEX(DA!$M$7:$M$300,MATCH($A19,DA!$B$7:$B$300,0)),"") -> 265 | I19: Close 08.10.2026 (Screener.in) | J19: 256.65 | K19: =IF(AND(ISNUMBER(B19),ISNUMBER(J19),N(J19)>0),B19/J19-1,"") -> -0.045392558
A20: Cyient Ltd | B20: 1084.7 | C20: =IF(ISNUMBER(B20),B20,IF(ISNUMBER(E20),E20,IF(ISNUMBER(F20),F20,IF(ISNUMBER(G20),G20,IF(ISNUMBER(H20),H20,""))))) -> 1084.7 | D20: =IF(ISNUMBER(B20),IF(I20<>"",I20,"Manual override"),IF(ISNUMBER(E20),"Vidushi stmt – LTP 05.10",IF(ISNUMBER(F20),"Umesh stmt – NSE live 09.10",IF(ISNUMBER(G20),"Gautam stmt – 05.10",IF(ISNUMBER(H20),"DA stmt – older (stale)","No price on any statement"))))) -> Close 08.10.2026 (Screener.in) | E20: =IFERROR(INDEX('Vidushi Malhotra'!$M$7:$M$300,MATCH($A20,'Vidushi Malhotra'!$B$7:$B$300,0)),"") | F20: =IFERROR(INDEX('Dr Umesh Choudhry'!$M$7:$M$300,MATCH($A20,'Dr Umesh Choudhry'!$B$7:$B$300,0)),"") | G20: =IFERROR(INDEX(Gautam!$M$7:$M$300,MATCH($A20,Gautam!$B$7:$B$300,0)),"") | H20: =IFERROR(INDEX(DA!$M$7:$M$300,MATCH($A20,DA!$B$7:$B$300,0)),"") -> 1059 | I20: Close 08.10.2026 (Screener.in) | J20: 1115 | K20: =IF(AND(ISNUMBER(B20),ISNUMBER(J20),N(J20)>0),B20/J20-1,"") -> -0.027174888
A21: Eicher Motors Ltd | B21: 6767.5 | C21: =IF(ISNUMBER(B21),B21,IF(ISNUMBER(E21),E21,IF(ISNUMBER(F21),F21,IF(ISNUMBER(G21),G21,IF(ISNUMBER(H21),H21,""))))) -> 6767.5 | D21: =IF(ISNUMBER(B21),IF(I21<>"",I21,"Manual override"),IF(ISNUMBER(E21),"Vidushi stmt – LTP 05.10",IF(ISNUMBER(F21),"Umesh stmt – NSE live 09.10",IF(ISNUMBER(G21),"Gautam stmt – 05.10",IF(ISNUMBER(H21),"DA stmt – older (stale)","No price on any statement"))))) -> Close 08.10.2026 (Screener.in) | E21: =IFERROR(INDEX('Vidushi Malhotra'!$M$7:$M$300,MATCH($A21,'Vidushi Malhotra'!$B$7:$B$300,0)),"") | F21: =IFERROR(INDEX('Dr Umesh Choudhry'!$M$7:$M$300,MATCH($A21,'Dr Umesh Choudhry'!$B$7:$B$300,0)),"") -> 6935 | G21: =IFERROR(INDEX(Gautam!$M$7:$M$300,MATCH($A21,Gautam!$B$7:$B$300,0)),"") -> 6920 | H21: =IFERROR(INDEX(DA!$M$7:$M$300,MATCH($A21,DA!$B$7:$B$300,0)),"") -> 7530 | I21: Close 08.10.2026 (Screener.in) | J21: 6960 | K21: =IF(AND(ISNUMBER(B21),ISNUMBER(J21),N(J21)>0),B21/J21-1,"") -> -0.027658046
A22: Fineotex Chemical Ltd | B22: 55.99 | C22: =IF(ISNUMBER(B22),B22,IF(ISNUMBER(E22),E22,IF(ISNUMBER(F22),F22,IF(ISNUMBER(G22),G22,IF(ISNUMBER(H22),H22,""))))) -> 55.99 | D22: =IF(ISNUMBER(B22),IF(I22<>"",I22,"Manual override"),IF(ISNUMBER(E22),"Vidushi stmt – LTP 05.10",IF(ISNUMBER(F22),"Umesh stmt – NSE live 09.10",IF(ISNUMBER(G22),"Gautam stmt – 05.10",IF(ISNUMBER(H22),"DA stmt – older (stale)","No price on any statement"))))) -> Close 08.10.2026 (Screener.in) | E22: =IFERROR(INDEX('Vidushi Malhotra'!$M$7:$M$300,MATCH($A22,'Vidushi Malhotra'!$B$7:$B$300,0)),"") -> 54.22 | F22: =IFERROR(INDEX('Dr Umesh Choudhry'!$M$7:$M$300,MATCH($A22,'Dr Umesh Choudhry'!$B$7:$B$300,0)),"") -> 56.329958 | G22: =IFERROR(INDEX(Gautam!$M$7:$M$300,MATCH($A22,Gautam!$B$7:$B$300,0)),"") -> 55.699422 | H22: =IFERROR(INDEX(DA!$M$7:$M$300,MATCH($A22,DA!$B$7:$B$300,0)),"") -> 57.7 | I22: Close 08.10.2026 (Screener.in) | J22: 57.8 | K22: =IF(AND(ISNUMBER(B22),ISNUMBER(J22),N(J22)>0),B22/J22-1,"") -> -0.031314879
A23: GFL Ltd | B23: 54.91 | C23: =IF(ISNUMBER(B23),B23,IF(ISNUMBER(E23),E23,IF(ISNUMBER(F23),F23,IF(ISNUMBER(G23),G23,IF(ISNUMBER(H23),H23,""))))) -> 54.91 | D23: =IF(ISNUMBER(B23),IF(I23<>"",I23,"Manual override"),IF(ISNUMBER(E23),"Vidushi stmt – LTP 05.10",IF(ISNUMBER(F23),"Umesh stmt – NSE live 09.10",IF(ISNUMBER(G23),"Gautam stmt – 05.10",IF(ISNUMBER(H23),"DA stmt – older (stale)","No price on any statement"))))) -> Close 08.10.2026 (Screener.in) | E23: =IFERROR(INDEX('Vidushi Malhotra'!$M$7:$M$300,MATCH($A23,'Vidushi Malhotra'!$B$7:$B$300,0)),"") | F23: =IFERROR(INDEX('Dr Umesh Choudhry'!$M$7:$M$300,MATCH($A23,'Dr Umesh Choudhry'!$B$7:$B$300,0)),"") | G23: =IFERROR(INDEX(Gautam!$M$7:$M$300,MATCH($A23,Gautam!$B$7:$B$300,0)),"") | H23: =IFERROR(INDEX(DA!$M$7:$M$300,MATCH($A23,DA!$B$7:$B$300,0)),"") -> 58 | I23: Close 08.10.2026 (Screener.in) | J23: 57.83 | K23: =IF(AND(ISNUMBER(B23),ISNUMBER(J23),N(J23)>0),B23/J23-1,"") -> -0.050492824
